ðŸ“Š Total pertandingan: 2
ðŸŽ¯ Yang memenuhi syarat: 2
ðŸ“Š Total pertandingan: 2
ðŸŽ¯ Yang memenuhi syarat: 2
ðŸ“Š Total pertandingan: 2
ðŸŽ¯ Yang memenuhi syarat: 2
ðŸ“Š Total pertandingan: 2
ðŸŽ¯ Yang memenuhi syarat: 2
ðŸ“Š Total pertandingan: 2
ðŸŽ¯ Yang memenuhi syarat: 2
Traceback (most recent call last):
  File "/home/arifin/envbot/lib/python3.12/site-packages/httpx/_transports/default.py", line 101, in map_httpcore_exceptions
    yield
  File "/home/arifin/envbot/lib/python3.12/site-packages/httpx/_transports/default.py", line 250, in handle_request
    resp = self._pool.handle_request(req)
           ^^^^^^^^^^^^^^^^^^^^^^^^^^^^^^
  File "/home/arifin/envbot/lib/python3.12/site-packages/httpcore/_sync/connection_pool.py", line 256, in handle_request
    raise exc from None
  File "/home/arifin/envbot/lib/python3.12/site-packages/httpcore/_sync/connection_pool.py", line 236, in handle_request
    response = connection.handle_request(
               ^^^^^^^^^^^^^^^^^^^^^^^^^^
  File "/home/arifin/envbot/lib/python3.12/site-packages/httpcore/_sync/connection.py", line 101, in handle_request
    raise exc
  File "/home/arifin/envbot/lib/python3.12/site-packages/httpcore/_sync/connection.py", line 78, in handle_request
    stream = self._connect(request)
             ^^^^^^^^^^^^^^^^^^^^^^
  File "/home/arifin/envbot/lib/python3.12/site-packages/httpcore/_sync/connection.py", line 156, in _connect
    stream = stream.start_tls(**kwargs)
             ^^^^^^^^^^^^^^^^^^^^^^^^^^
  File "/home/arifin/envbot/lib/python3.12/site-packages/httpcore/_backends/sync.py", line 154, in start_tls
    with map_exceptions(exc_map):
  File "/usr/lib/python3.12/contextlib.py", line 158, in __exit__
    self.gen.throw(value)
  File "/home/arifin/envbot/lib/python3.12/site-packages/httpcore/_exceptions.py", line 14, in map_exceptions
    raise to_exc(exc) from exc
httpcore.ConnectError: [Errno 104] Connection reset by peer

The above exception was the direct cause of the following exception:

Traceback (most recent call last):
  File "/home/arifin/project/live_score/main.py", line 30, in <module>
    notify(match, reason)
  File "/home/arifin/project/live_score/notifier.py", line 68, in notify
    httpx.post(f"{API_URL}/sendMessage", json={
  File "/home/arifin/envbot/lib/python3.12/site-packages/httpx/_api.py", line 304, in post
    return request(
           ^^^^^^^^
  File "/home/arifin/envbot/lib/python3.12/site-packages/httpx/_api.py", line 109, in request
    return client.request(
           ^^^^^^^^^^^^^^^
  File "/home/arifin/envbot/lib/python3.12/site-packages/httpx/_client.py", line 825, in request
    return self.send(request, auth=auth, follow_redirects=follow_redirects)
           ^^^^^^^^^^^^^^^^^^^^^^^^^^^^^^^^^^^^^^^^^^^^^^^^^^^^^^^^^^^^^^^^
  File "/home/arifin/envbot/lib/python3.12/site-packages/httpx/_client.py", line 914, in send
    response = self._send_handling_auth(
               ^^^^^^^^^^^^^^^^^^^^^^^^^
  File "/home/arifin/envbot/lib/python3.12/site-packages/httpx/_client.py", line 942, in _send_handling_auth
    response = self._send_handling_redirects(
               ^^^^^^^^^^^^^^^^^^^^^^^^^^^^^^
  File "/home/arifin/envbot/lib/python3.12/site-packages/httpx/_client.py", line 979, in _send_handling_redirects
    response = self._send_single_request(request)
               ^^^^^^^^^^^^^^^^^^^^^^^^^^^^^^^^^^
  File "/home/arifin/envbot/lib/python3.12/site-packages/httpx/_client.py", line 1014, in _send_single_request
    response = transport.handle_request(request)
               ^^^^^^^^^^^^^^^^^^^^^^^^^^^^^^^^^
  File "/home/arifin/envbot/lib/python3.12/site-packages/httpx/_transports/default.py", line 249, in handle_request
    with map_httpcore_exceptions():
  File "/usr/lib/python3.12/contextlib.py", line 158, in __exit__
    self.gen.throw(value)
  File "/home/arifin/envbot/lib/python3.12/site-packages/httpx/_transports/default.py", line 118, in map_httpcore_exceptions
    raise mapped_exc(message) from exc
httpx.ConnectError: [Errno 104] Connection reset by peer
ðŸ“Š Total pertandingan: 2
ðŸŽ¯ Yang memenuhi syarat: 2
ðŸ“Š Total pertandingan: 291
ðŸŽ¯ Yang memenuhi syarat: 5
ðŸ“Š Total pertandingan: 291
ðŸŽ¯ Yang memenuhi syarat: 5
ðŸ“Š Total pertandingan: 291
ðŸŽ¯ Yang memenuhi syarat: 5
Traceback (most recent call last):
  File "/home/arifin/envbot/lib/python3.12/site-packages/httpx/_transports/default.py", line 101, in map_httpcore_exceptions
    yield
  File "/home/arifin/envbot/lib/python3.12/site-packages/httpx/_transports/default.py", line 250, in handle_request
    resp = self._pool.handle_request(req)
           ^^^^^^^^^^^^^^^^^^^^^^^^^^^^^^
  File "/home/arifin/envbot/lib/python3.12/site-packages/httpcore/_sync/connection_pool.py", line 256, in handle_request
    raise exc from None
  File "/home/arifin/envbot/lib/python3.12/site-packages/httpcore/_sync/connection_pool.py", line 236, in handle_request
    response = connection.handle_request(
               ^^^^^^^^^^^^^^^^^^^^^^^^^^
  File "/home/arifin/envbot/lib/python3.12/site-packages/httpcore/_sync/connection.py", line 101, in handle_request
    raise exc
  File "/home/arifin/envbot/lib/python3.12/site-packages/httpcore/_sync/connection.py", line 78, in handle_request
    stream = self._connect(request)
             ^^^^^^^^^^^^^^^^^^^^^^
  File "/home/arifin/envbot/lib/python3.12/site-packages/httpcore/_sync/connection.py", line 156, in _connect
    stream = stream.start_tls(**kwargs)
             ^^^^^^^^^^^^^^^^^^^^^^^^^^
  File "/home/arifin/envbot/lib/python3.12/site-packages/httpcore/_backends/sync.py", line 154, in start_tls
    with map_exceptions(exc_map):
  File "/usr/lib/python3.12/contextlib.py", line 158, in __exit__
    self.gen.throw(value)
  File "/home/arifin/envbot/lib/python3.12/site-packages/httpcore/_exceptions.py", line 14, in map_exceptions
    raise to_exc(exc) from exc
httpcore.ConnectTimeout: _ssl.c:983: The handshake operation timed out

The above exception was the direct cause of the following exception:

Traceback (most recent call last):
  File "/home/arifin/project/live_score/main.py", line 30, in <module>
    notify(match, reason)
  File "/home/arifin/project/live_score/notifier.py", line 68, in notify
    httpx.post(f"{API_URL}/sendMessage", json={
  File "/home/arifin/envbot/lib/python3.12/site-packages/httpx/_api.py", line 304, in post
    return request(
           ^^^^^^^^
  File "/home/arifin/envbot/lib/python3.12/site-packages/httpx/_api.py", line 109, in request
    return client.request(
           ^^^^^^^^^^^^^^^
  File "/home/arifin/envbot/lib/python3.12/site-packages/httpx/_client.py", line 825, in request
    return self.send(request, auth=auth, follow_redirects=follow_redirects)
           ^^^^^^^^^^^^^^^^^^^^^^^^^^^^^^^^^^^^^^^^^^^^^^^^^^^^^^^^^^^^^^^^
  File "/home/arifin/envbot/lib/python3.12/site-packages/httpx/_client.py", line 914, in send
    response = self._send_handling_auth(
               ^^^^^^^^^^^^^^^^^^^^^^^^^
  File "/home/arifin/envbot/lib/python3.12/site-packages/httpx/_client.py", line 942, in _send_handling_auth
    response = self._send_handling_redirects(
               ^^^^^^^^^^^^^^^^^^^^^^^^^^^^^^
  File "/home/arifin/envbot/lib/python3.12/site-packages/httpx/_client.py", line 979, in _send_handling_redirects
    response = self._send_single_request(request)
               ^^^^^^^^^^^^^^^^^^^^^^^^^^^^^^^^^^
  File "/home/arifin/envbot/lib/python3.12/site-packages/httpx/_client.py", line 1014, in _send_single_request
    response = transport.handle_request(request)
               ^^^^^^^^^^^^^^^^^^^^^^^^^^^^^^^^^
  File "/home/arifin/envbot/lib/python3.12/site-packages/httpx/_transports/default.py", line 249, in handle_request
    with map_httpcore_exceptions():
  File "/usr/lib/python3.12/contextlib.py", line 158, in __exit__
    self.gen.throw(value)
  File "/home/arifin/envbot/lib/python3.12/site-packages/httpx/_transports/default.py", line 118, in map_httpcore_exceptions
    raise mapped_exc(message) from exc
httpx.ConnectTimeout: _ssl.c:983: The handshake operation timed out
ðŸ“Š Total pertandingan: 291
ðŸŽ¯ Yang memenuhi syarat: 5
ðŸ“Š Total pertandingan: 291
ðŸŽ¯ Yang memenuhi syarat: 5
Traceback (most recent call last):
  File "/home/arifin/envbot/lib/python3.12/site-packages/httpx/_transports/default.py", line 101, in map_httpcore_exceptions
    yield
  File "/home/arifin/envbot/lib/python3.12/site-packages/httpx/_transports/default.py", line 250, in handle_request
    resp = self._pool.handle_request(req)
           ^^^^^^^^^^^^^^^^^^^^^^^^^^^^^^
  File "/home/arifin/envbot/lib/python3.12/site-packages/httpcore/_sync/connection_pool.py", line 256, in handle_request
    raise exc from None
  File "/home/arifin/envbot/lib/python3.12/site-packages/httpcore/_sync/connection_pool.py", line 236, in handle_request
    response = connection.handle_request(
               ^^^^^^^^^^^^^^^^^^^^^^^^^^
  File "/home/arifin/envbot/lib/python3.12/site-packages/httpcore/_sync/connection.py", line 101, in handle_request
    raise exc
  File "/home/arifin/envbot/lib/python3.12/site-packages/httpcore/_sync/connection.py", line 78, in handle_request
    stream = self._connect(request)
             ^^^^^^^^^^^^^^^^^^^^^^
  File "/home/arifin/envbot/lib/python3.12/site-packages/httpcore/_sync/connection.py", line 156, in _connect
    stream = stream.start_tls(**kwargs)
             ^^^^^^^^^^^^^^^^^^^^^^^^^^
  File "/home/arifin/envbot/lib/python3.12/site-packages/httpcore/_backends/sync.py", line 154, in start_tls
    with map_exceptions(exc_map):
  File "/usr/lib/python3.12/contextlib.py", line 158, in __exit__
    self.gen.throw(value)
  File "/home/arifin/envbot/lib/python3.12/site-packages/httpcore/_exceptions.py", line 14, in map_exceptions
    raise to_exc(exc) from exc
httpcore.ConnectTimeout: _ssl.c:983: The handshake operation timed out

The above exception was the direct cause of the following exception:

Traceback (most recent call last):
  File "/home/arifin/project/live_score/main.py", line 30, in <module>
    notify(match, reason)
  File "/home/arifin/project/live_score/notifier.py", line 68, in notify
    httpx.post(f"{API_URL}/sendMessage", json={
  File "/home/arifin/envbot/lib/python3.12/site-packages/httpx/_api.py", line 304, in post
    return request(
           ^^^^^^^^
  File "/home/arifin/envbot/lib/python3.12/site-packages/httpx/_api.py", line 109, in request
    return client.request(
           ^^^^^^^^^^^^^^^
  File "/home/arifin/envbot/lib/python3.12/site-packages/httpx/_client.py", line 825, in request
    return self.send(request, auth=auth, follow_redirects=follow_redirects)
           ^^^^^^^^^^^^^^^^^^^^^^^^^^^^^^^^^^^^^^^^^^^^^^^^^^^^^^^^^^^^^^^^
  File "/home/arifin/envbot/lib/python3.12/site-packages/httpx/_client.py", line 914, in send
    response = self._send_handling_auth(
               ^^^^^^^^^^^^^^^^^^^^^^^^^
  File "/home/arifin/envbot/lib/python3.12/site-packages/httpx/_client.py", line 942, in _send_handling_auth
    response = self._send_handling_redirects(
               ^^^^^^^^^^^^^^^^^^^^^^^^^^^^^^
  File "/home/arifin/envbot/lib/python3.12/site-packages/httpx/_client.py", line 979, in _send_handling_redirects
    response = self._send_single_request(request)
               ^^^^^^^^^^^^^^^^^^^^^^^^^^^^^^^^^^
  File "/home/arifin/envbot/lib/python3.12/site-packages/httpx/_client.py", line 1014, in _send_single_request
    response = transport.handle_request(request)
               ^^^^^^^^^^^^^^^^^^^^^^^^^^^^^^^^^
  File "/home/arifin/envbot/lib/python3.12/site-packages/httpx/_transports/default.py", line 249, in handle_request
    with map_httpcore_exceptions():
  File "/usr/lib/python3.12/contextlib.py", line 158, in __exit__
    self.gen.throw(value)
  File "/home/arifin/envbot/lib/python3.12/site-packages/httpx/_transports/default.py", line 118, in map_httpcore_exceptions
    raise mapped_exc(message) from exc
httpx.ConnectTimeout: _ssl.c:983: The handshake operation timed out
ðŸ“Š Total pertandingan: 291
ðŸŽ¯ Yang memenuhi syarat: 5
ðŸ“Š Total pertandingan: 291
ðŸŽ¯ Yang memenuhi syarat: 5
ðŸ“Š Total pertandingan: 291
ðŸŽ¯ Yang memenuhi syarat: 5
ðŸ“Š Total pertandingan: 291
ðŸŽ¯ Yang memenuhi syarat: 5
ðŸ“Š Total pertandingan: 291
ðŸŽ¯ Yang memenuhi syarat: 5
ðŸ“Š Total pertandingan: 291
ðŸŽ¯ Yang memenuhi syarat: 5
ðŸ“Š Total pertandingan: 291
ðŸŽ¯ Yang memenuhi syarat: 5
ðŸ“Š Total pertandingan: 292
ðŸŽ¯ Yang memenuhi syarat: 5
Traceback (most recent call last):
  File "/home/arifin/envbot/lib/python3.12/site-packages/httpx/_transports/default.py", line 101, in map_httpcore_exceptions
    yield
  File "/home/arifin/envbot/lib/python3.12/site-packages/httpx/_transports/default.py", line 250, in handle_request
    resp = self._pool.handle_request(req)
           ^^^^^^^^^^^^^^^^^^^^^^^^^^^^^^
  File "/home/arifin/envbot/lib/python3.12/site-packages/httpcore/_sync/connection_pool.py", line 256, in handle_request
    raise exc from None
  File "/home/arifin/envbot/lib/python3.12/site-packages/httpcore/_sync/connection_pool.py", line 236, in handle_request
    response = connection.handle_request(
               ^^^^^^^^^^^^^^^^^^^^^^^^^^
  File "/home/arifin/envbot/lib/python3.12/site-packages/httpcore/_sync/connection.py", line 101, in handle_request
    raise exc
  File "/home/arifin/envbot/lib/python3.12/site-packages/httpcore/_sync/connection.py", line 78, in handle_request
    stream = self._connect(request)
             ^^^^^^^^^^^^^^^^^^^^^^
  File "/home/arifin/envbot/lib/python3.12/site-packages/httpcore/_sync/connection.py", line 156, in _connect
    stream = stream.start_tls(**kwargs)
             ^^^^^^^^^^^^^^^^^^^^^^^^^^
  File "/home/arifin/envbot/lib/python3.12/site-packages/httpcore/_backends/sync.py", line 154, in start_tls
    with map_exceptions(exc_map):
  File "/usr/lib/python3.12/contextlib.py", line 158, in __exit__
    self.gen.throw(value)
  File "/home/arifin/envbot/lib/python3.12/site-packages/httpcore/_exceptions.py", line 14, in map_exceptions
    raise to_exc(exc) from exc
httpcore.ConnectTimeout: _ssl.c:983: The handshake operation timed out

The above exception was the direct cause of the following exception:

Traceback (most recent call last):
  File "/home/arifin/project/live_score/main.py", line 30, in <module>
    notify(match, reason)
  File "/home/arifin/project/live_score/notifier.py", line 68, in notify
    httpx.post(f"{API_URL}/sendMessage", json={
  File "/home/arifin/envbot/lib/python3.12/site-packages/httpx/_api.py", line 304, in post
    return request(
           ^^^^^^^^
  File "/home/arifin/envbot/lib/python3.12/site-packages/httpx/_api.py", line 109, in request
    return client.request(
           ^^^^^^^^^^^^^^^
  File "/home/arifin/envbot/lib/python3.12/site-packages/httpx/_client.py", line 825, in request
    return self.send(request, auth=auth, follow_redirects=follow_redirects)
           ^^^^^^^^^^^^^^^^^^^^^^^^^^^^^^^^^^^^^^^^^^^^^^^^^^^^^^^^^^^^^^^^
  File "/home/arifin/envbot/lib/python3.12/site-packages/httpx/_client.py", line 914, in send
    response = self._send_handling_auth(
               ^^^^^^^^^^^^^^^^^^^^^^^^^
  File "/home/arifin/envbot/lib/python3.12/site-packages/httpx/_client.py", line 942, in _send_handling_auth
    response = self._send_handling_redirects(
               ^^^^^^^^^^^^^^^^^^^^^^^^^^^^^^
  File "/home/arifin/envbot/lib/python3.12/site-packages/httpx/_client.py", line 979, in _send_handling_redirects
    response = self._send_single_request(request)
               ^^^^^^^^^^^^^^^^^^^^^^^^^^^^^^^^^^
  File "/home/arifin/envbot/lib/python3.12/site-packages/httpx/_client.py", line 1014, in _send_single_request
    response = transport.handle_request(request)
               ^^^^^^^^^^^^^^^^^^^^^^^^^^^^^^^^^
  File "/home/arifin/envbot/lib/python3.12/site-packages/httpx/_transports/default.py", line 249, in handle_request
    with map_httpcore_exceptions():
  File "/usr/lib/python3.12/contextlib.py", line 158, in __exit__
    self.gen.throw(value)
  File "/home/arifin/envbot/lib/python3.12/site-packages/httpx/_transports/default.py", line 118, in map_httpcore_exceptions
    raise mapped_exc(message) from exc
httpx.ConnectTimeout: _ssl.c:983: The handshake operation timed out
ðŸ“Š Total pertandingan: 292
ðŸŽ¯ Yang memenuhi syarat: 5
ðŸ“Š Total pertandingan: 292
ðŸŽ¯ Yang memenuhi syarat: 5
ðŸ“Š Total pertandingan: 292
ðŸŽ¯ Yang memenuhi syarat: 5
Traceback (most recent call last):
  File "/home/arifin/envbot/lib/python3.12/site-packages/httpx/_transports/default.py", line 101, in map_httpcore_exceptions
    yield
  File "/home/arifin/envbot/lib/python3.12/site-packages/httpx/_transports/default.py", line 250, in handle_request
    resp = self._pool.handle_request(req)
           ^^^^^^^^^^^^^^^^^^^^^^^^^^^^^^
  File "/home/arifin/envbot/lib/python3.12/site-packages/httpcore/_sync/connection_pool.py", line 256, in handle_request
    raise exc from None
  File "/home/arifin/envbot/lib/python3.12/site-packages/httpcore/_sync/connection_pool.py", line 236, in handle_request
    response = connection.handle_request(
               ^^^^^^^^^^^^^^^^^^^^^^^^^^
  File "/home/arifin/envbot/lib/python3.12/site-packages/httpcore/_sync/connection.py", line 101, in handle_request
    raise exc
  File "/home/arifin/envbot/lib/python3.12/site-packages/httpcore/_sync/connection.py", line 78, in handle_request
    stream = self._connect(request)
             ^^^^^^^^^^^^^^^^^^^^^^
  File "/home/arifin/envbot/lib/python3.12/site-packages/httpcore/_sync/connection.py", line 156, in _connect
    stream = stream.start_tls(**kwargs)
             ^^^^^^^^^^^^^^^^^^^^^^^^^^
  File "/home/arifin/envbot/lib/python3.12/site-packages/httpcore/_backends/sync.py", line 154, in start_tls
    with map_exceptions(exc_map):
  File "/usr/lib/python3.12/contextlib.py", line 158, in __exit__
    self.gen.throw(value)
  File "/home/arifin/envbot/lib/python3.12/site-packages/httpcore/_exceptions.py", line 14, in map_exceptions
    raise to_exc(exc) from exc
httpcore.ConnectTimeout: _ssl.c:983: The handshake operation timed out

The above exception was the direct cause of the following exception:

Traceback (most recent call last):
  File "/home/arifin/project/live_score/main.py", line 30, in <module>
    notify(match, reason)
  File "/home/arifin/project/live_score/notifier.py", line 68, in notify
    httpx.post(f"{API_URL}/sendMessage", json={
  File "/home/arifin/envbot/lib/python3.12/site-packages/httpx/_api.py", line 304, in post
    return request(
           ^^^^^^^^
  File "/home/arifin/envbot/lib/python3.12/site-packages/httpx/_api.py", line 109, in request
    return client.request(
           ^^^^^^^^^^^^^^^
  File "/home/arifin/envbot/lib/python3.12/site-packages/httpx/_client.py", line 825, in request
    return self.send(request, auth=auth, follow_redirects=follow_redirects)
           ^^^^^^^^^^^^^^^^^^^^^^^^^^^^^^^^^^^^^^^^^^^^^^^^^^^^^^^^^^^^^^^^
  File "/home/arifin/envbot/lib/python3.12/site-packages/httpx/_client.py", line 914, in send
    response = self._send_handling_auth(
               ^^^^^^^^^^^^^^^^^^^^^^^^^
  File "/home/arifin/envbot/lib/python3.12/site-packages/httpx/_client.py", line 942, in _send_handling_auth
    response = self._send_handling_redirects(
               ^^^^^^^^^^^^^^^^^^^^^^^^^^^^^^
  File "/home/arifin/envbot/lib/python3.12/site-packages/httpx/_client.py", line 979, in _send_handling_redirects
    response = self._send_single_request(request)
               ^^^^^^^^^^^^^^^^^^^^^^^^^^^^^^^^^^
  File "/home/arifin/envbot/lib/python3.12/site-packages/httpx/_client.py", line 1014, in _send_single_request
    response = transport.handle_request(request)
               ^^^^^^^^^^^^^^^^^^^^^^^^^^^^^^^^^
  File "/home/arifin/envbot/lib/python3.12/site-packages/httpx/_transports/default.py", line 249, in handle_request
    with map_httpcore_exceptions():
  File "/usr/lib/python3.12/contextlib.py", line 158, in __exit__
    self.gen.throw(value)
  File "/home/arifin/envbot/lib/python3.12/site-packages/httpx/_transports/default.py", line 118, in map_httpcore_exceptions
    raise mapped_exc(message) from exc
httpx.ConnectTimeout: _ssl.c:983: The handshake operation timed out
ðŸ“Š Total pertandingan: 292
ðŸŽ¯ Yang memenuhi syarat: 5
Traceback (most recent call last):
  File "/home/arifin/envbot/lib/python3.12/site-packages/httpx/_transports/default.py", line 101, in map_httpcore_exceptions
    yield
  File "/home/arifin/envbot/lib/python3.12/site-packages/httpx/_transports/default.py", line 250, in handle_request
    resp = self._pool.handle_request(req)
           ^^^^^^^^^^^^^^^^^^^^^^^^^^^^^^
  File "/home/arifin/envbot/lib/python3.12/site-packages/httpcore/_sync/connection_pool.py", line 256, in handle_request
    raise exc from None
  File "/home/arifin/envbot/lib/python3.12/site-packages/httpcore/_sync/connection_pool.py", line 236, in handle_request
    response = connection.handle_request(
               ^^^^^^^^^^^^^^^^^^^^^^^^^^
  File "/home/arifin/envbot/lib/python3.12/site-packages/httpcore/_sync/connection.py", line 101, in handle_request
    raise exc
  File "/home/arifin/envbot/lib/python3.12/site-packages/httpcore/_sync/connection.py", line 78, in handle_request
    stream = self._connect(request)
             ^^^^^^^^^^^^^^^^^^^^^^
  File "/home/arifin/envbot/lib/python3.12/site-packages/httpcore/_sync/connection.py", line 156, in _connect
    stream = stream.start_tls(**kwargs)
             ^^^^^^^^^^^^^^^^^^^^^^^^^^
  File "/home/arifin/envbot/lib/python3.12/site-packages/httpcore/_backends/sync.py", line 154, in start_tls
    with map_exceptions(exc_map):
  File "/usr/lib/python3.12/contextlib.py", line 158, in __exit__
    self.gen.throw(value)
  File "/home/arifin/envbot/lib/python3.12/site-packages/httpcore/_exceptions.py", line 14, in map_exceptions
    raise to_exc(exc) from exc
httpcore.ConnectTimeout: _ssl.c:983: The handshake operation timed out

The above exception was the direct cause of the following exception:

Traceback (most recent call last):
  File "/home/arifin/project/live_score/main.py", line 30, in <module>
    notify(match, reason)
  File "/home/arifin/project/live_score/notifier.py", line 68, in notify
    httpx.post(f"{API_URL}/sendMessage", json={
  File "/home/arifin/envbot/lib/python3.12/site-packages/httpx/_api.py", line 304, in post
    return request(
           ^^^^^^^^
  File "/home/arifin/envbot/lib/python3.12/site-packages/httpx/_api.py", line 109, in request
    return client.request(
           ^^^^^^^^^^^^^^^
  File "/home/arifin/envbot/lib/python3.12/site-packages/httpx/_client.py", line 825, in request
    return self.send(request, auth=auth, follow_redirects=follow_redirects)
           ^^^^^^^^^^^^^^^^^^^^^^^^^^^^^^^^^^^^^^^^^^^^^^^^^^^^^^^^^^^^^^^^
  File "/home/arifin/envbot/lib/python3.12/site-packages/httpx/_client.py", line 914, in send
    response = self._send_handling_auth(
               ^^^^^^^^^^^^^^^^^^^^^^^^^
  File "/home/arifin/envbot/lib/python3.12/site-packages/httpx/_client.py", line 942, in _send_handling_auth
    response = self._send_handling_redirects(
               ^^^^^^^^^^^^^^^^^^^^^^^^^^^^^^
  File "/home/arifin/envbot/lib/python3.12/site-packages/httpx/_client.py", line 979, in _send_handling_redirects
    response = self._send_single_request(request)
               ^^^^^^^^^^^^^^^^^^^^^^^^^^^^^^^^^^
  File "/home/arifin/envbot/lib/python3.12/site-packages/httpx/_client.py", line 1014, in _send_single_request
    response = transport.handle_request(request)
               ^^^^^^^^^^^^^^^^^^^^^^^^^^^^^^^^^
  File "/home/arifin/envbot/lib/python3.12/site-packages/httpx/_transports/default.py", line 249, in handle_request
    with map_httpcore_exceptions():
  File "/usr/lib/python3.12/contextlib.py", line 158, in __exit__
    self.gen.throw(value)
  File "/home/arifin/envbot/lib/python3.12/site-packages/httpx/_transports/default.py", line 118, in map_httpcore_exceptions
    raise mapped_exc(message) from exc
httpx.ConnectTimeout: _ssl.c:983: The handshake operation timed out
ðŸ“Š Total pertandingan: 292
ðŸŽ¯ Yang memenuhi syarat: 5
ðŸ“Š Total pertandingan: 292
ðŸŽ¯ Yang memenuhi syarat: 5
Traceback (most recent call last):
  File "/home/arifin/envbot/lib/python3.12/site-packages/httpx/_transports/default.py", line 101, in map_httpcore_exceptions
    yield
  File "/home/arifin/envbot/lib/python3.12/site-packages/httpx/_transports/default.py", line 250, in handle_request
    resp = self._pool.handle_request(req)
           ^^^^^^^^^^^^^^^^^^^^^^^^^^^^^^
  File "/home/arifin/envbot/lib/python3.12/site-packages/httpcore/_sync/connection_pool.py", line 256, in handle_request
    raise exc from None
  File "/home/arifin/envbot/lib/python3.12/site-packages/httpcore/_sync/connection_pool.py", line 236, in handle_request
    response = connection.handle_request(
               ^^^^^^^^^^^^^^^^^^^^^^^^^^
  File "/home/arifin/envbot/lib/python3.12/site-packages/httpcore/_sync/connection.py", line 101, in handle_request
    raise exc
  File "/home/arifin/envbot/lib/python3.12/site-packages/httpcore/_sync/connection.py", line 78, in handle_request
    stream = self._connect(request)
             ^^^^^^^^^^^^^^^^^^^^^^
  File "/home/arifin/envbot/lib/python3.12/site-packages/httpcore/_sync/connection.py", line 156, in _connect
    stream = stream.start_tls(**kwargs)
             ^^^^^^^^^^^^^^^^^^^^^^^^^^
  File "/home/arifin/envbot/lib/python3.12/site-packages/httpcore/_backends/sync.py", line 154, in start_tls
    with map_exceptions(exc_map):
  File "/usr/lib/python3.12/contextlib.py", line 158, in __exit__
    self.gen.throw(value)
  File "/home/arifin/envbot/lib/python3.12/site-packages/httpcore/_exceptions.py", line 14, in map_exceptions
    raise to_exc(exc) from exc
httpcore.ConnectTimeout: _ssl.c:983: The handshake operation timed out

The above exception was the direct cause of the following exception:

Traceback (most recent call last):
  File "/home/arifin/project/live_score/main.py", line 30, in <module>
    notify(match, reason)
  File "/home/arifin/project/live_score/notifier.py", line 68, in notify
    httpx.post(f"{API_URL}/sendMessage", json={
  File "/home/arifin/envbot/lib/python3.12/site-packages/httpx/_api.py", line 304, in post
    return request(
           ^^^^^^^^
  File "/home/arifin/envbot/lib/python3.12/site-packages/httpx/_api.py", line 109, in request
    return client.request(
           ^^^^^^^^^^^^^^^
  File "/home/arifin/envbot/lib/python3.12/site-packages/httpx/_client.py", line 825, in request
    return self.send(request, auth=auth, follow_redirects=follow_redirects)
           ^^^^^^^^^^^^^^^^^^^^^^^^^^^^^^^^^^^^^^^^^^^^^^^^^^^^^^^^^^^^^^^^
  File "/home/arifin/envbot/lib/python3.12/site-packages/httpx/_client.py", line 914, in send
    response = self._send_handling_auth(
               ^^^^^^^^^^^^^^^^^^^^^^^^^
  File "/home/arifin/envbot/lib/python3.12/site-packages/httpx/_client.py", line 942, in _send_handling_auth
    response = self._send_handling_redirects(
               ^^^^^^^^^^^^^^^^^^^^^^^^^^^^^^
  File "/home/arifin/envbot/lib/python3.12/site-packages/httpx/_client.py", line 979, in _send_handling_redirects
    response = self._send_single_request(request)
               ^^^^^^^^^^^^^^^^^^^^^^^^^^^^^^^^^^
  File "/home/arifin/envbot/lib/python3.12/site-packages/httpx/_client.py", line 1014, in _send_single_request
    response = transport.handle_request(request)
               ^^^^^^^^^^^^^^^^^^^^^^^^^^^^^^^^^
  File "/home/arifin/envbot/lib/python3.12/site-packages/httpx/_transports/default.py", line 249, in handle_request
    with map_httpcore_exceptions():
  File "/usr/lib/python3.12/contextlib.py", line 158, in __exit__
    self.gen.throw(value)
  File "/home/arifin/envbot/lib/python3.12/site-packages/httpx/_transports/default.py", line 118, in map_httpcore_exceptions
    raise mapped_exc(message) from exc
httpx.ConnectTimeout: _ssl.c:983: The handshake operation timed out
ðŸ“Š Total pertandingan: 292
ðŸŽ¯ Yang memenuhi syarat: 5
ðŸ“Š Total pertandingan: 292
ðŸŽ¯ Yang memenuhi syarat: 5
Traceback (most recent call last):
  File "/home/arifin/envbot/lib/python3.12/site-packages/httpx/_transports/default.py", line 101, in map_httpcore_exceptions
    yield
  File "/home/arifin/envbot/lib/python3.12/site-packages/httpx/_transports/default.py", line 250, in handle_request
    resp = self._pool.handle_request(req)
           ^^^^^^^^^^^^^^^^^^^^^^^^^^^^^^
  File "/home/arifin/envbot/lib/python3.12/site-packages/httpcore/_sync/connection_pool.py", line 256, in handle_request
    raise exc from None
  File "/home/arifin/envbot/lib/python3.12/site-packages/httpcore/_sync/connection_pool.py", line 236, in handle_request
    response = connection.handle_request(
               ^^^^^^^^^^^^^^^^^^^^^^^^^^
  File "/home/arifin/envbot/lib/python3.12/site-packages/httpcore/_sync/connection.py", line 101, in handle_request
    raise exc
  File "/home/arifin/envbot/lib/python3.12/site-packages/httpcore/_sync/connection.py", line 78, in handle_request
    stream = self._connect(request)
             ^^^^^^^^^^^^^^^^^^^^^^
  File "/home/arifin/envbot/lib/python3.12/site-packages/httpcore/_sync/connection.py", line 156, in _connect
    stream = stream.start_tls(**kwargs)
             ^^^^^^^^^^^^^^^^^^^^^^^^^^
  File "/home/arifin/envbot/lib/python3.12/site-packages/httpcore/_backends/sync.py", line 154, in start_tls
    with map_exceptions(exc_map):
  File "/usr/lib/python3.12/contextlib.py", line 158, in __exit__
    self.gen.throw(value)
  File "/home/arifin/envbot/lib/python3.12/site-packages/httpcore/_exceptions.py", line 14, in map_exceptions
    raise to_exc(exc) from exc
httpcore.ConnectTimeout: _ssl.c:983: The handshake operation timed out

The above exception was the direct cause of the following exception:

Traceback (most recent call last):
  File "/home/arifin/project/live_score/main.py", line 30, in <module>
    notify(match, reason)
  File "/home/arifin/project/live_score/notifier.py", line 68, in notify
    httpx.post(f"{API_URL}/sendMessage", json={
  File "/home/arifin/envbot/lib/python3.12/site-packages/httpx/_api.py", line 304, in post
    return request(
           ^^^^^^^^
  File "/home/arifin/envbot/lib/python3.12/site-packages/httpx/_api.py", line 109, in request
    return client.request(
           ^^^^^^^^^^^^^^^
  File "/home/arifin/envbot/lib/python3.12/site-packages/httpx/_client.py", line 825, in request
    return self.send(request, auth=auth, follow_redirects=follow_redirects)
           ^^^^^^^^^^^^^^^^^^^^^^^^^^^^^^^^^^^^^^^^^^^^^^^^^^^^^^^^^^^^^^^^
  File "/home/arifin/envbot/lib/python3.12/site-packages/httpx/_client.py", line 914, in send
    response = self._send_handling_auth(
               ^^^^^^^^^^^^^^^^^^^^^^^^^
  File "/home/arifin/envbot/lib/python3.12/site-packages/httpx/_client.py", line 942, in _send_handling_auth
    response = self._send_handling_redirects(
               ^^^^^^^^^^^^^^^^^^^^^^^^^^^^^^
  File "/home/arifin/envbot/lib/python3.12/site-packages/httpx/_client.py", line 979, in _send_handling_redirects
    response = self._send_single_request(request)
               ^^^^^^^^^^^^^^^^^^^^^^^^^^^^^^^^^^
  File "/home/arifin/envbot/lib/python3.12/site-packages/httpx/_client.py", line 1014, in _send_single_request
    response = transport.handle_request(request)
               ^^^^^^^^^^^^^^^^^^^^^^^^^^^^^^^^^
  File "/home/arifin/envbot/lib/python3.12/site-packages/httpx/_transports/default.py", line 249, in handle_request
    with map_httpcore_exceptions():
  File "/usr/lib/python3.12/contextlib.py", line 158, in __exit__
    self.gen.throw(value)
  File "/home/arifin/envbot/lib/python3.12/site-packages/httpx/_transports/default.py", line 118, in map_httpcore_exceptions
    raise mapped_exc(message) from exc
httpx.ConnectTimeout: _ssl.c:983: The handshake operation timed out
ðŸ“Š Total pertandingan: 292
ðŸŽ¯ Yang memenuhi syarat: 5
ðŸ“Š Total pertandingan: 292
ðŸŽ¯ Yang memenuhi syarat: 5
ðŸ“Š Total pertandingan: 292
ðŸŽ¯ Yang memenuhi syarat: 5
ðŸ“Š Total pertandingan: 292
ðŸŽ¯ Yang memenuhi syarat: 5
Traceback (most recent call last):
  File "/home/arifin/envbot/lib/python3.12/site-packages/urllib3/connection.py", line 198, in _new_conn
    sock = connection.create_connection(
           ^^^^^^^^^^^^^^^^^^^^^^^^^^^^^
  File "/home/arifin/envbot/lib/python3.12/site-packages/urllib3/util/connection.py", line 85, in create_connection
    raise err
  File "/home/arifin/envbot/lib/python3.12/site-packages/urllib3/util/connection.py", line 73, in create_connection
    sock.connect(sa)
TimeoutError: [Errno 110] Connection timed out

The above exception was the direct cause of the following exception:

Traceback (most recent call last):
  File "/home/arifin/envbot/lib/python3.12/site-packages/urllib3/connectionpool.py", line 787, in urlopen
    response = self._make_request(
               ^^^^^^^^^^^^^^^^^^^
  File "/home/arifin/envbot/lib/python3.12/site-packages/urllib3/connectionpool.py", line 493, in _make_request
    conn.request(
  File "/home/arifin/envbot/lib/python3.12/site-packages/urllib3/connection.py", line 494, in request
    self.endheaders()
  File "/usr/lib/python3.12/http/client.py", line 1331, in endheaders
    self._send_output(message_body, encode_chunked=encode_chunked)
  File "/usr/lib/python3.12/http/client.py", line 1091, in _send_output
    self.send(msg)
  File "/usr/lib/python3.12/http/client.py", line 1035, in send
    self.connect()
  File "/home/arifin/envbot/lib/python3.12/site-packages/urllib3/connection.py", line 325, in connect
    self.sock = self._new_conn()
                ^^^^^^^^^^^^^^^^
  File "/home/arifin/envbot/lib/python3.12/site-packages/urllib3/connection.py", line 207, in _new_conn
    raise ConnectTimeoutError(
urllib3.exceptions.ConnectTimeoutError: (<urllib3.connection.HTTPConnection object at 0x7b302395e630>, 'Connection to api.isportsapi.com timed out. (connect timeout=None)')

The above exception was the direct cause of the following exception:

Traceback (most recent call last):
  File "/home/arifin/envbot/lib/python3.12/site-packages/requests/adapters.py", line 667, in send
    resp = conn.urlopen(
           ^^^^^^^^^^^^^
  File "/home/arifin/envbot/lib/python3.12/site-packages/urllib3/connectionpool.py", line 841, in urlopen
    retries = retries.increment(
              ^^^^^^^^^^^^^^^^^^
  File "/home/arifin/envbot/lib/python3.12/site-packages/urllib3/util/retry.py", line 519, in increment
    raise MaxRetryError(_pool, url, reason) from reason  # type: ignore[arg-type]
    ^^^^^^^^^^^^^^^^^^^^^^^^^^^^^^^^^^^^^^^^^^^^^^^^^^^
urllib3.exceptions.MaxRetryError: HTTPConnectionPool(host='api.isportsapi.com', port=80): Max retries exceeded with url: /sport/football/livescores?api_key=VEM3L91m7eguSCla (Caused by ConnectTimeoutError(<urllib3.connection.HTTPConnection object at 0x7b302395e630>, 'Connection to api.isportsapi.com timed out. (connect timeout=None)'))

During handling of the above exception, another exception occurred:

Traceback (most recent call last):
  File "/home/arifin/project/live_score/main.py", line 23, in <module>
    matches = fetch_matches()
              ^^^^^^^^^^^^^^^
  File "/home/arifin/project/live_score/main.py", line 17, in fetch_matches
    resp = requests.get(settings.NOWGOAL_API_URL, params=params)
           ^^^^^^^^^^^^^^^^^^^^^^^^^^^^^^^^^^^^^^^^^^^^^^^^^^^^^
  File "/home/arifin/envbot/lib/python3.12/site-packages/requests/api.py", line 73, in get
    return request("get", url, params=params, **kwargs)
           ^^^^^^^^^^^^^^^^^^^^^^^^^^^^^^^^^^^^^^^^^^^^
  File "/home/arifin/envbot/lib/python3.12/site-packages/requests/api.py", line 59, in request
    return session.request(method=method, url=url, **kwargs)
           ^^^^^^^^^^^^^^^^^^^^^^^^^^^^^^^^^^^^^^^^^^^^^^^^^
  File "/home/arifin/envbot/lib/python3.12/site-packages/requests/sessions.py", line 589, in request
    resp = self.send(prep, **send_kwargs)
           ^^^^^^^^^^^^^^^^^^^^^^^^^^^^^^
  File "/home/arifin/envbot/lib/python3.12/site-packages/requests/sessions.py", line 703, in send
    r = adapter.send(request, **kwargs)
        ^^^^^^^^^^^^^^^^^^^^^^^^^^^^^^^
  File "/home/arifin/envbot/lib/python3.12/site-packages/requests/adapters.py", line 688, in send
    raise ConnectTimeout(e, request=request)
requests.exceptions.ConnectTimeout: HTTPConnectionPool(host='api.isportsapi.com', port=80): Max retries exceeded with url: /sport/football/livescores?api_key=VEM3L91m7eguSCla (Caused by ConnectTimeoutError(<urllib3.connection.HTTPConnection object at 0x7b302395e630>, 'Connection to api.isportsapi.com timed out. (connect timeout=None)'))
ðŸ“Š Total pertandingan: 292
ðŸŽ¯ Yang memenuhi syarat: 5
Traceback (most recent call last):
  File "/home/arifin/envbot/lib/python3.12/site-packages/httpx/_transports/default.py", line 101, in map_httpcore_exceptions
    yield
  File "/home/arifin/envbot/lib/python3.12/site-packages/httpx/_transports/default.py", line 250, in handle_request
    resp = self._pool.handle_request(req)
           ^^^^^^^^^^^^^^^^^^^^^^^^^^^^^^
  File "/home/arifin/envbot/lib/python3.12/site-packages/httpcore/_sync/connection_pool.py", line 256, in handle_request
    raise exc from None
  File "/home/arifin/envbot/lib/python3.12/site-packages/httpcore/_sync/connection_pool.py", line 236, in handle_request
    response = connection.handle_request(
               ^^^^^^^^^^^^^^^^^^^^^^^^^^
  File "/home/arifin/envbot/lib/python3.12/site-packages/httpcore/_sync/connection.py", line 101, in handle_request
    raise exc
  File "/home/arifin/envbot/lib/python3.12/site-packages/httpcore/_sync/connection.py", line 78, in handle_request
    stream = self._connect(request)
             ^^^^^^^^^^^^^^^^^^^^^^
  File "/home/arifin/envbot/lib/python3.12/site-packages/httpcore/_sync/connection.py", line 124, in _connect
    stream = self._network_backend.connect_tcp(**kwargs)
             ^^^^^^^^^^^^^^^^^^^^^^^^^^^^^^^^^^^^^^^^^^^
  File "/home/arifin/envbot/lib/python3.12/site-packages/httpcore/_backends/sync.py", line 207, in connect_tcp
    with map_exceptions(exc_map):
  File "/usr/lib/python3.12/contextlib.py", line 158, in __exit__
    self.gen.throw(value)
  File "/home/arifin/envbot/lib/python3.12/site-packages/httpcore/_exceptions.py", line 14, in map_exceptions
    raise to_exc(exc) from exc
httpcore.ConnectError: [Errno 101] Network is unreachable

The above exception was the direct cause of the following exception:

Traceback (most recent call last):
  File "/home/arifin/project/live_score/main.py", line 30, in <module>
    notify(match, reason)
  File "/home/arifin/project/live_score/notifier.py", line 68, in notify
    httpx.post(f"{API_URL}/sendMessage", json={
  File "/home/arifin/envbot/lib/python3.12/site-packages/httpx/_api.py", line 304, in post
    return request(
           ^^^^^^^^
  File "/home/arifin/envbot/lib/python3.12/site-packages/httpx/_api.py", line 109, in request
    return client.request(
           ^^^^^^^^^^^^^^^
  File "/home/arifin/envbot/lib/python3.12/site-packages/httpx/_client.py", line 825, in request
    return self.send(request, auth=auth, follow_redirects=follow_redirects)
           ^^^^^^^^^^^^^^^^^^^^^^^^^^^^^^^^^^^^^^^^^^^^^^^^^^^^^^^^^^^^^^^^
  File "/home/arifin/envbot/lib/python3.12/site-packages/httpx/_client.py", line 914, in send
    response = self._send_handling_auth(
               ^^^^^^^^^^^^^^^^^^^^^^^^^
  File "/home/arifin/envbot/lib/python3.12/site-packages/httpx/_client.py", line 942, in _send_handling_auth
    response = self._send_handling_redirects(
               ^^^^^^^^^^^^^^^^^^^^^^^^^^^^^^
  File "/home/arifin/envbot/lib/python3.12/site-packages/httpx/_client.py", line 979, in _send_handling_redirects
    response = self._send_single_request(request)
               ^^^^^^^^^^^^^^^^^^^^^^^^^^^^^^^^^^
  File "/home/arifin/envbot/lib/python3.12/site-packages/httpx/_client.py", line 1014, in _send_single_request
    response = transport.handle_request(request)
               ^^^^^^^^^^^^^^^^^^^^^^^^^^^^^^^^^
  File "/home/arifin/envbot/lib/python3.12/site-packages/httpx/_transports/default.py", line 249, in handle_request
    with map_httpcore_exceptions():
  File "/usr/lib/python3.12/contextlib.py", line 158, in __exit__
    self.gen.throw(value)
  File "/home/arifin/envbot/lib/python3.12/site-packages/httpx/_transports/default.py", line 118, in map_httpcore_exceptions
    raise mapped_exc(message) from exc
httpx.ConnectError: [Errno 101] Network is unreachable
ðŸ“Š Total pertandingan: 292
ðŸŽ¯ Yang memenuhi syarat: 6
Traceback (most recent call last):
  File "/home/arifin/envbot/lib/python3.12/site-packages/urllib3/response.py", line 779, in _error_catcher
    yield
  File "/home/arifin/envbot/lib/python3.12/site-packages/urllib3/response.py", line 904, in _raw_read
    data = self._fp_read(amt, read1=read1) if not fp_closed else b""
           ^^^^^^^^^^^^^^^^^^^^^^^^^^^^^^^
  File "/home/arifin/envbot/lib/python3.12/site-packages/urllib3/response.py", line 887, in _fp_read
    return self._fp.read(amt) if amt is not None else self._fp.read()
           ^^^^^^^^^^^^^^^^^^
  File "/usr/lib/python3.12/http/client.py", line 479, in read
    s = self.fp.read(amt)
        ^^^^^^^^^^^^^^^^^
  File "/usr/lib/python3.12/socket.py", line 707, in readinto
    return self._sock.recv_into(b)
           ^^^^^^^^^^^^^^^^^^^^^^^
ConnectionResetError: [Errno 104] Connection reset by peer

The above exception was the direct cause of the following exception:

Traceback (most recent call last):
  File "/home/arifin/envbot/lib/python3.12/site-packages/requests/models.py", line 820, in generate
    yield from self.raw.stream(chunk_size, decode_content=True)
  File "/home/arifin/envbot/lib/python3.12/site-packages/urllib3/response.py", line 1091, in stream
    data = self.read(amt=amt, decode_content=decode_content)
           ^^^^^^^^^^^^^^^^^^^^^^^^^^^^^^^^^^^^^^^^^^^^^^^^^
  File "/home/arifin/envbot/lib/python3.12/site-packages/urllib3/response.py", line 980, in read
    data = self._raw_read(amt)
           ^^^^^^^^^^^^^^^^^^^
  File "/home/arifin/envbot/lib/python3.12/site-packages/urllib3/response.py", line 903, in _raw_read
    with self._error_catcher():
  File "/usr/lib/python3.12/contextlib.py", line 158, in __exit__
    self.gen.throw(value)
  File "/home/arifin/envbot/lib/python3.12/site-packages/urllib3/response.py", line 806, in _error_catcher
    raise ProtocolError(f"Connection broken: {e!r}", e) from e
urllib3.exceptions.ProtocolError: ("Connection broken: ConnectionResetError(104, 'Connection reset by peer')", ConnectionResetError(104, 'Connection reset by peer'))

During handling of the above exception, another exception occurred:

Traceback (most recent call last):
  File "/home/arifin/project/live_score/main.py", line 23, in <module>
    matches = fetch_matches()
              ^^^^^^^^^^^^^^^
  File "/home/arifin/project/live_score/main.py", line 17, in fetch_matches
    resp = requests.get(settings.NOWGOAL_API_URL, params=params)
           ^^^^^^^^^^^^^^^^^^^^^^^^^^^^^^^^^^^^^^^^^^^^^^^^^^^^^
  File "/home/arifin/envbot/lib/python3.12/site-packages/requests/api.py", line 73, in get
    return request("get", url, params=params, **kwargs)
           ^^^^^^^^^^^^^^^^^^^^^^^^^^^^^^^^^^^^^^^^^^^^
  File "/home/arifin/envbot/lib/python3.12/site-packages/requests/api.py", line 59, in request
    return session.request(method=method, url=url, **kwargs)
           ^^^^^^^^^^^^^^^^^^^^^^^^^^^^^^^^^^^^^^^^^^^^^^^^^
  File "/home/arifin/envbot/lib/python3.12/site-packages/requests/sessions.py", line 589, in request
    resp = self.send(prep, **send_kwargs)
           ^^^^^^^^^^^^^^^^^^^^^^^^^^^^^^
  File "/home/arifin/envbot/lib/python3.12/site-packages/requests/sessions.py", line 746, in send
    r.content
  File "/home/arifin/envbot/lib/python3.12/site-packages/requests/models.py", line 902, in content
    self._content = b"".join(self.iter_content(CONTENT_CHUNK_SIZE)) or b""
                    ^^^^^^^^^^^^^^^^^^^^^^^^^^^^^^^^^^^^^^^^^^^^^^^
  File "/home/arifin/envbot/lib/python3.12/site-packages/requests/models.py", line 822, in generate
    raise ChunkedEncodingError(e)
requests.exceptions.ChunkedEncodingError: ("Connection broken: ConnectionResetError(104, 'Connection reset by peer')", ConnectionResetError(104, 'Connection reset by peer'))
ðŸ“Š Total pertandingan: 292
ðŸŽ¯ Yang memenuhi syarat: 6
Traceback (most recent call last):
  File "/home/arifin/envbot/lib/python3.12/site-packages/httpx/_transports/default.py", line 101, in map_httpcore_exceptions
    yield
  File "/home/arifin/envbot/lib/python3.12/site-packages/httpx/_transports/default.py", line 250, in handle_request
    resp = self._pool.handle_request(req)
           ^^^^^^^^^^^^^^^^^^^^^^^^^^^^^^
  File "/home/arifin/envbot/lib/python3.12/site-packages/httpcore/_sync/connection_pool.py", line 256, in handle_request
    raise exc from None
  File "/home/arifin/envbot/lib/python3.12/site-packages/httpcore/_sync/connection_pool.py", line 236, in handle_request
    response = connection.handle_request(
               ^^^^^^^^^^^^^^^^^^^^^^^^^^
  File "/home/arifin/envbot/lib/python3.12/site-packages/httpcore/_sync/connection.py", line 103, in handle_request
    return self._connection.handle_request(request)
           ^^^^^^^^^^^^^^^^^^^^^^^^^^^^^^^^^^^^^^^^
  File "/home/arifin/envbot/lib/python3.12/site-packages/httpcore/_sync/http11.py", line 136, in handle_request
    raise exc
  File "/home/arifin/envbot/lib/python3.12/site-packages/httpcore/_sync/http11.py", line 106, in handle_request
    ) = self._receive_response_headers(**kwargs)
        ^^^^^^^^^^^^^^^^^^^^^^^^^^^^^^^^^^^^^^^^
  File "/home/arifin/envbot/lib/python3.12/site-packages/httpcore/_sync/http11.py", line 177, in _receive_response_headers
    event = self._receive_event(timeout=timeout)
            ^^^^^^^^^^^^^^^^^^^^^^^^^^^^^^^^^^^^
  File "/home/arifin/envbot/lib/python3.12/site-packages/httpcore/_sync/http11.py", line 217, in _receive_event
    data = self._network_stream.read(
           ^^^^^^^^^^^^^^^^^^^^^^^^^^
  File "/home/arifin/envbot/lib/python3.12/site-packages/httpcore/_backends/sync.py", line 126, in read
    with map_exceptions(exc_map):
  File "/usr/lib/python3.12/contextlib.py", line 158, in __exit__
    self.gen.throw(value)
  File "/home/arifin/envbot/lib/python3.12/site-packages/httpcore/_exceptions.py", line 14, in map_exceptions
    raise to_exc(exc) from exc
httpcore.ReadTimeout: The read operation timed out

The above exception was the direct cause of the following exception:

Traceback (most recent call last):
  File "/home/arifin/project/live_score/main.py", line 30, in <module>
    notify(match, reason)
  File "/home/arifin/project/live_score/notifier.py", line 68, in notify
    httpx.post(f"{API_URL}/sendMessage", json={
  File "/home/arifin/envbot/lib/python3.12/site-packages/httpx/_api.py", line 304, in post
    return request(
           ^^^^^^^^
  File "/home/arifin/envbot/lib/python3.12/site-packages/httpx/_api.py", line 109, in request
    return client.request(
           ^^^^^^^^^^^^^^^
  File "/home/arifin/envbot/lib/python3.12/site-packages/httpx/_client.py", line 825, in request
    return self.send(request, auth=auth, follow_redirects=follow_redirects)
           ^^^^^^^^^^^^^^^^^^^^^^^^^^^^^^^^^^^^^^^^^^^^^^^^^^^^^^^^^^^^^^^^
  File "/home/arifin/envbot/lib/python3.12/site-packages/httpx/_client.py", line 914, in send
    response = self._send_handling_auth(
               ^^^^^^^^^^^^^^^^^^^^^^^^^
  File "/home/arifin/envbot/lib/python3.12/site-packages/httpx/_client.py", line 942, in _send_handling_auth
    response = self._send_handling_redirects(
               ^^^^^^^^^^^^^^^^^^^^^^^^^^^^^^
  File "/home/arifin/envbot/lib/python3.12/site-packages/httpx/_client.py", line 979, in _send_handling_redirects
    response = self._send_single_request(request)
               ^^^^^^^^^^^^^^^^^^^^^^^^^^^^^^^^^^
  File "/home/arifin/envbot/lib/python3.12/site-packages/httpx/_client.py", line 1014, in _send_single_request
    response = transport.handle_request(request)
               ^^^^^^^^^^^^^^^^^^^^^^^^^^^^^^^^^
  File "/home/arifin/envbot/lib/python3.12/site-packages/httpx/_transports/default.py", line 249, in handle_request
    with map_httpcore_exceptions():
  File "/usr/lib/python3.12/contextlib.py", line 158, in __exit__
    self.gen.throw(value)
  File "/home/arifin/envbot/lib/python3.12/site-packages/httpx/_transports/default.py", line 118, in map_httpcore_exceptions
    raise mapped_exc(message) from exc
httpx.ReadTimeout: The read operation timed out
Traceback (most recent call last):
  File "/home/arifin/envbot/lib/python3.12/site-packages/urllib3/connection.py", line 198, in _new_conn
    sock = connection.create_connection(
           ^^^^^^^^^^^^^^^^^^^^^^^^^^^^^
  File "/home/arifin/envbot/lib/python3.12/site-packages/urllib3/util/connection.py", line 85, in create_connection
    raise err
  File "/home/arifin/envbot/lib/python3.12/site-packages/urllib3/util/connection.py", line 73, in create_connection
    sock.connect(sa)
TimeoutError: [Errno 110] Connection timed out

The above exception was the direct cause of the following exception:

Traceback (most recent call last):
  File "/home/arifin/envbot/lib/python3.12/site-packages/urllib3/connectionpool.py", line 787, in urlopen
    response = self._make_request(
               ^^^^^^^^^^^^^^^^^^^
  File "/home/arifin/envbot/lib/python3.12/site-packages/urllib3/connectionpool.py", line 493, in _make_request
    conn.request(
  File "/home/arifin/envbot/lib/python3.12/site-packages/urllib3/connection.py", line 494, in request
    self.endheaders()
  File "/usr/lib/python3.12/http/client.py", line 1331, in endheaders
    self._send_output(message_body, encode_chunked=encode_chunked)
  File "/usr/lib/python3.12/http/client.py", line 1091, in _send_output
    self.send(msg)
  File "/usr/lib/python3.12/http/client.py", line 1035, in send
    self.connect()
  File "/home/arifin/envbot/lib/python3.12/site-packages/urllib3/connection.py", line 325, in connect
    self.sock = self._new_conn()
                ^^^^^^^^^^^^^^^^
  File "/home/arifin/envbot/lib/python3.12/site-packages/urllib3/connection.py", line 207, in _new_conn
    raise ConnectTimeoutError(
urllib3.exceptions.ConnectTimeoutError: (<urllib3.connection.HTTPConnection object at 0x707e7693ca70>, 'Connection to api.isportsapi.com timed out. (connect timeout=None)')

The above exception was the direct cause of the following exception:

Traceback (most recent call last):
  File "/home/arifin/envbot/lib/python3.12/site-packages/requests/adapters.py", line 667, in send
    resp = conn.urlopen(
           ^^^^^^^^^^^^^
  File "/home/arifin/envbot/lib/python3.12/site-packages/urllib3/connectionpool.py", line 841, in urlopen
    retries = retries.increment(
              ^^^^^^^^^^^^^^^^^^
  File "/home/arifin/envbot/lib/python3.12/site-packages/urllib3/util/retry.py", line 519, in increment
    raise MaxRetryError(_pool, url, reason) from reason  # type: ignore[arg-type]
    ^^^^^^^^^^^^^^^^^^^^^^^^^^^^^^^^^^^^^^^^^^^^^^^^^^^
urllib3.exceptions.MaxRetryError: HTTPConnectionPool(host='api.isportsapi.com', port=80): Max retries exceeded with url: /sport/football/livescores?api_key=VEM3L91m7eguSCla (Caused by ConnectTimeoutError(<urllib3.connection.HTTPConnection object at 0x707e7693ca70>, 'Connection to api.isportsapi.com timed out. (connect timeout=None)'))

During handling of the above exception, another exception occurred:

Traceback (most recent call last):
  File "/home/arifin/project/live_score/main.py", line 23, in <module>
    matches = fetch_matches()
              ^^^^^^^^^^^^^^^
  File "/home/arifin/project/live_score/main.py", line 17, in fetch_matches
    resp = requests.get(settings.NOWGOAL_API_URL, params=params)
           ^^^^^^^^^^^^^^^^^^^^^^^^^^^^^^^^^^^^^^^^^^^^^^^^^^^^^
  File "/home/arifin/envbot/lib/python3.12/site-packages/requests/api.py", line 73, in get
    return request("get", url, params=params, **kwargs)
           ^^^^^^^^^^^^^^^^^^^^^^^^^^^^^^^^^^^^^^^^^^^^
  File "/home/arifin/envbot/lib/python3.12/site-packages/requests/api.py", line 59, in request
    return session.request(method=method, url=url, **kwargs)
           ^^^^^^^^^^^^^^^^^^^^^^^^^^^^^^^^^^^^^^^^^^^^^^^^^
  File "/home/arifin/envbot/lib/python3.12/site-packages/requests/sessions.py", line 589, in request
    resp = self.send(prep, **send_kwargs)
           ^^^^^^^^^^^^^^^^^^^^^^^^^^^^^^
  File "/home/arifin/envbot/lib/python3.12/site-packages/requests/sessions.py", line 703, in send
    r = adapter.send(request, **kwargs)
        ^^^^^^^^^^^^^^^^^^^^^^^^^^^^^^^
  File "/home/arifin/envbot/lib/python3.12/site-packages/requests/adapters.py", line 688, in send
    raise ConnectTimeout(e, request=request)
requests.exceptions.ConnectTimeout: HTTPConnectionPool(host='api.isportsapi.com', port=80): Max retries exceeded with url: /sport/football/livescores?api_key=VEM3L91m7eguSCla (Caused by ConnectTimeoutError(<urllib3.connection.HTTPConnection object at 0x707e7693ca70>, 'Connection to api.isportsapi.com timed out. (connect timeout=None)'))
Traceback (most recent call last):
  File "/home/arifin/envbot/lib/python3.12/site-packages/urllib3/connection.py", line 198, in _new_conn
    sock = connection.create_connection(
           ^^^^^^^^^^^^^^^^^^^^^^^^^^^^^
  File "/home/arifin/envbot/lib/python3.12/site-packages/urllib3/util/connection.py", line 85, in create_connection
    raise err
  File "/home/arifin/envbot/lib/python3.12/site-packages/urllib3/util/connection.py", line 73, in create_connection
    sock.connect(sa)
TimeoutError: [Errno 110] Connection timed out

The above exception was the direct cause of the following exception:

Traceback (most recent call last):
  File "/home/arifin/envbot/lib/python3.12/site-packages/urllib3/connectionpool.py", line 787, in urlopen
    response = self._make_request(
               ^^^^^^^^^^^^^^^^^^^
  File "/home/arifin/envbot/lib/python3.12/site-packages/urllib3/connectionpool.py", line 493, in _make_request
    conn.request(
  File "/home/arifin/envbot/lib/python3.12/site-packages/urllib3/connection.py", line 494, in request
    self.endheaders()
  File "/usr/lib/python3.12/http/client.py", line 1331, in endheaders
    self._send_output(message_body, encode_chunked=encode_chunked)
  File "/usr/lib/python3.12/http/client.py", line 1091, in _send_output
    self.send(msg)
  File "/usr/lib/python3.12/http/client.py", line 1035, in send
    self.connect()
  File "/home/arifin/envbot/lib/python3.12/site-packages/urllib3/connection.py", line 325, in connect
    self.sock = self._new_conn()
                ^^^^^^^^^^^^^^^^
  File "/home/arifin/envbot/lib/python3.12/site-packages/urllib3/connection.py", line 207, in _new_conn
    raise ConnectTimeoutError(
urllib3.exceptions.ConnectTimeoutError: (<urllib3.connection.HTTPConnection object at 0x7d8ee3c96e40>, 'Connection to api.isportsapi.com timed out. (connect timeout=None)')

The above exception was the direct cause of the following exception:

Traceback (most recent call last):
  File "/home/arifin/envbot/lib/python3.12/site-packages/requests/adapters.py", line 667, in send
    resp = conn.urlopen(
           ^^^^^^^^^^^^^
  File "/home/arifin/envbot/lib/python3.12/site-packages/urllib3/connectionpool.py", line 841, in urlopen
    retries = retries.increment(
              ^^^^^^^^^^^^^^^^^^
  File "/home/arifin/envbot/lib/python3.12/site-packages/urllib3/util/retry.py", line 519, in increment
    raise MaxRetryError(_pool, url, reason) from reason  # type: ignore[arg-type]
    ^^^^^^^^^^^^^^^^^^^^^^^^^^^^^^^^^^^^^^^^^^^^^^^^^^^
urllib3.exceptions.MaxRetryError: HTTPConnectionPool(host='api.isportsapi.com', port=80): Max retries exceeded with url: /sport/football/livescores?api_key=VEM3L91m7eguSCla (Caused by ConnectTimeoutError(<urllib3.connection.HTTPConnection object at 0x7d8ee3c96e40>, 'Connection to api.isportsapi.com timed out. (connect timeout=None)'))

During handling of the above exception, another exception occurred:

Traceback (most recent call last):
  File "/home/arifin/project/live_score/main.py", line 23, in <module>
    matches = fetch_matches()
              ^^^^^^^^^^^^^^^
  File "/home/arifin/project/live_score/main.py", line 17, in fetch_matches
    resp = requests.get(settings.NOWGOAL_API_URL, params=params)
           ^^^^^^^^^^^^^^^^^^^^^^^^^^^^^^^^^^^^^^^^^^^^^^^^^^^^^
  File "/home/arifin/envbot/lib/python3.12/site-packages/requests/api.py", line 73, in get
    return request("get", url, params=params, **kwargs)
           ^^^^^^^^^^^^^^^^^^^^^^^^^^^^^^^^^^^^^^^^^^^^
  File "/home/arifin/envbot/lib/python3.12/site-packages/requests/api.py", line 59, in request
    return session.request(method=method, url=url, **kwargs)
           ^^^^^^^^^^^^^^^^^^^^^^^^^^^^^^^^^^^^^^^^^^^^^^^^^
  File "/home/arifin/envbot/lib/python3.12/site-packages/requests/sessions.py", line 589, in request
    resp = self.send(prep, **send_kwargs)
           ^^^^^^^^^^^^^^^^^^^^^^^^^^^^^^
  File "/home/arifin/envbot/lib/python3.12/site-packages/requests/sessions.py", line 703, in send
    r = adapter.send(request, **kwargs)
        ^^^^^^^^^^^^^^^^^^^^^^^^^^^^^^^
  File "/home/arifin/envbot/lib/python3.12/site-packages/requests/adapters.py", line 688, in send
    raise ConnectTimeout(e, request=request)
requests.exceptions.ConnectTimeout: HTTPConnectionPool(host='api.isportsapi.com', port=80): Max retries exceeded with url: /sport/football/livescores?api_key=VEM3L91m7eguSCla (Caused by ConnectTimeoutError(<urllib3.connection.HTTPConnection object at 0x7d8ee3c96e40>, 'Connection to api.isportsapi.com timed out. (connect timeout=None)'))
Traceback (most recent call last):
  File "/home/arifin/envbot/lib/python3.12/site-packages/urllib3/connection.py", line 198, in _new_conn
    sock = connection.create_connection(
           ^^^^^^^^^^^^^^^^^^^^^^^^^^^^^
  File "/home/arifin/envbot/lib/python3.12/site-packages/urllib3/util/connection.py", line 85, in create_connection
    raise err
  File "/home/arifin/envbot/lib/python3.12/site-packages/urllib3/util/connection.py", line 73, in create_connection
    sock.connect(sa)
TimeoutError: [Errno 110] Connection timed out

The above exception was the direct cause of the following exception:

Traceback (most recent call last):
  File "/home/arifin/envbot/lib/python3.12/site-packages/urllib3/connectionpool.py", line 787, in urlopen
    response = self._make_request(
               ^^^^^^^^^^^^^^^^^^^
  File "/home/arifin/envbot/lib/python3.12/site-packages/urllib3/connectionpool.py", line 493, in _make_request
    conn.request(
  File "/home/arifin/envbot/lib/python3.12/site-packages/urllib3/connection.py", line 494, in request
    self.endheaders()
  File "/usr/lib/python3.12/http/client.py", line 1331, in endheaders
    self._send_output(message_body, encode_chunked=encode_chunked)
  File "/usr/lib/python3.12/http/client.py", line 1091, in _send_output
    self.send(msg)
  File "/usr/lib/python3.12/http/client.py", line 1035, in send
    self.connect()
  File "/home/arifin/envbot/lib/python3.12/site-packages/urllib3/connection.py", line 325, in connect
    self.sock = self._new_conn()
                ^^^^^^^^^^^^^^^^
  File "/home/arifin/envbot/lib/python3.12/site-packages/urllib3/connection.py", line 207, in _new_conn
    raise ConnectTimeoutError(
urllib3.exceptions.ConnectTimeoutError: (<urllib3.connection.HTTPConnection object at 0x7f5663ab4ec0>, 'Connection to api.isportsapi.com timed out. (connect timeout=None)')

The above exception was the direct cause of the following exception:

Traceback (most recent call last):
  File "/home/arifin/envbot/lib/python3.12/site-packages/requests/adapters.py", line 667, in send
    resp = conn.urlopen(
           ^^^^^^^^^^^^^
  File "/home/arifin/envbot/lib/python3.12/site-packages/urllib3/connectionpool.py", line 841, in urlopen
    retries = retries.increment(
              ^^^^^^^^^^^^^^^^^^
  File "/home/arifin/envbot/lib/python3.12/site-packages/urllib3/util/retry.py", line 519, in increment
    raise MaxRetryError(_pool, url, reason) from reason  # type: ignore[arg-type]
    ^^^^^^^^^^^^^^^^^^^^^^^^^^^^^^^^^^^^^^^^^^^^^^^^^^^
urllib3.exceptions.MaxRetryError: HTTPConnectionPool(host='api.isportsapi.com', port=80): Max retries exceeded with url: /sport/football/livescores?api_key=VEM3L91m7eguSCla (Caused by ConnectTimeoutError(<urllib3.connection.HTTPConnection object at 0x7f5663ab4ec0>, 'Connection to api.isportsapi.com timed out. (connect timeout=None)'))

During handling of the above exception, another exception occurred:

Traceback (most recent call last):
  File "/home/arifin/project/live_score/main.py", line 23, in <module>
    matches = fetch_matches()
              ^^^^^^^^^^^^^^^
  File "/home/arifin/project/live_score/main.py", line 17, in fetch_matches
    resp = requests.get(settings.NOWGOAL_API_URL, params=params)
           ^^^^^^^^^^^^^^^^^^^^^^^^^^^^^^^^^^^^^^^^^^^^^^^^^^^^^
  File "/home/arifin/envbot/lib/python3.12/site-packages/requests/api.py", line 73, in get
    return request("get", url, params=params, **kwargs)
           ^^^^^^^^^^^^^^^^^^^^^^^^^^^^^^^^^^^^^^^^^^^^
  File "/home/arifin/envbot/lib/python3.12/site-packages/requests/api.py", line 59, in request
    return session.request(method=method, url=url, **kwargs)
           ^^^^^^^^^^^^^^^^^^^^^^^^^^^^^^^^^^^^^^^^^^^^^^^^^
  File "/home/arifin/envbot/lib/python3.12/site-packages/requests/sessions.py", line 589, in request
    resp = self.send(prep, **send_kwargs)
           ^^^^^^^^^^^^^^^^^^^^^^^^^^^^^^
  File "/home/arifin/envbot/lib/python3.12/site-packages/requests/sessions.py", line 703, in send
    r = adapter.send(request, **kwargs)
        ^^^^^^^^^^^^^^^^^^^^^^^^^^^^^^^
  File "/home/arifin/envbot/lib/python3.12/site-packages/requests/adapters.py", line 688, in send
    raise ConnectTimeout(e, request=request)
requests.exceptions.ConnectTimeout: HTTPConnectionPool(host='api.isportsapi.com', port=80): Max retries exceeded with url: /sport/football/livescores?api_key=VEM3L91m7eguSCla (Caused by ConnectTimeoutError(<urllib3.connection.HTTPConnection object at 0x7f5663ab4ec0>, 'Connection to api.isportsapi.com timed out. (connect timeout=None)'))
Traceback (most recent call last):
  File "/home/arifin/envbot/lib/python3.12/site-packages/urllib3/connection.py", line 198, in _new_conn
    sock = connection.create_connection(
           ^^^^^^^^^^^^^^^^^^^^^^^^^^^^^
  File "/home/arifin/envbot/lib/python3.12/site-packages/urllib3/util/connection.py", line 85, in create_connection
    raise err
  File "/home/arifin/envbot/lib/python3.12/site-packages/urllib3/util/connection.py", line 73, in create_connection
    sock.connect(sa)
TimeoutError: [Errno 110] Connection timed out

The above exception was the direct cause of the following exception:

Traceback (most recent call last):
  File "/home/arifin/envbot/lib/python3.12/site-packages/urllib3/connectionpool.py", line 787, in urlopen
    response = self._make_request(
               ^^^^^^^^^^^^^^^^^^^
  File "/home/arifin/envbot/lib/python3.12/site-packages/urllib3/connectionpool.py", line 493, in _make_request
    conn.request(
  File "/home/arifin/envbot/lib/python3.12/site-packages/urllib3/connection.py", line 494, in request
    self.endheaders()
  File "/usr/lib/python3.12/http/client.py", line 1331, in endheaders
    self._send_output(message_body, encode_chunked=encode_chunked)
  File "/usr/lib/python3.12/http/client.py", line 1091, in _send_output
    self.send(msg)
  File "/usr/lib/python3.12/http/client.py", line 1035, in send
    self.connect()
  File "/home/arifin/envbot/lib/python3.12/site-packages/urllib3/connection.py", line 325, in connect
    self.sock = self._new_conn()
                ^^^^^^^^^^^^^^^^
  File "/home/arifin/envbot/lib/python3.12/site-packages/urllib3/connection.py", line 207, in _new_conn
    raise ConnectTimeoutError(
urllib3.exceptions.ConnectTimeoutError: (<urllib3.connection.HTTPConnection object at 0x71ceae13ab10>, 'Connection to api.isportsapi.com timed out. (connect timeout=None)')

The above exception was the direct cause of the following exception:

Traceback (most recent call last):
  File "/home/arifin/envbot/lib/python3.12/site-packages/requests/adapters.py", line 667, in send
    resp = conn.urlopen(
           ^^^^^^^^^^^^^
  File "/home/arifin/envbot/lib/python3.12/site-packages/urllib3/connectionpool.py", line 841, in urlopen
    retries = retries.increment(
              ^^^^^^^^^^^^^^^^^^
  File "/home/arifin/envbot/lib/python3.12/site-packages/urllib3/util/retry.py", line 519, in increment
    raise MaxRetryError(_pool, url, reason) from reason  # type: ignore[arg-type]
    ^^^^^^^^^^^^^^^^^^^^^^^^^^^^^^^^^^^^^^^^^^^^^^^^^^^
urllib3.exceptions.MaxRetryError: HTTPConnectionPool(host='api.isportsapi.com', port=80): Max retries exceeded with url: /sport/football/livescores?api_key=VEM3L91m7eguSCla (Caused by ConnectTimeoutError(<urllib3.connection.HTTPConnection object at 0x71ceae13ab10>, 'Connection to api.isportsapi.com timed out. (connect timeout=None)'))

During handling of the above exception, another exception occurred:

Traceback (most recent call last):
  File "/home/arifin/project/live_score/main.py", line 23, in <module>
    matches = fetch_matches()
              ^^^^^^^^^^^^^^^
  File "/home/arifin/project/live_score/main.py", line 17, in fetch_matches
    resp = requests.get(settings.NOWGOAL_API_URL, params=params)
           ^^^^^^^^^^^^^^^^^^^^^^^^^^^^^^^^^^^^^^^^^^^^^^^^^^^^^
  File "/home/arifin/envbot/lib/python3.12/site-packages/requests/api.py", line 73, in get
    return request("get", url, params=params, **kwargs)
           ^^^^^^^^^^^^^^^^^^^^^^^^^^^^^^^^^^^^^^^^^^^^
  File "/home/arifin/envbot/lib/python3.12/site-packages/requests/api.py", line 59, in request
    return session.request(method=method, url=url, **kwargs)
           ^^^^^^^^^^^^^^^^^^^^^^^^^^^^^^^^^^^^^^^^^^^^^^^^^
  File "/home/arifin/envbot/lib/python3.12/site-packages/requests/sessions.py", line 589, in request
    resp = self.send(prep, **send_kwargs)
           ^^^^^^^^^^^^^^^^^^^^^^^^^^^^^^
  File "/home/arifin/envbot/lib/python3.12/site-packages/requests/sessions.py", line 703, in send
    r = adapter.send(request, **kwargs)
        ^^^^^^^^^^^^^^^^^^^^^^^^^^^^^^^
  File "/home/arifin/envbot/lib/python3.12/site-packages/requests/adapters.py", line 688, in send
    raise ConnectTimeout(e, request=request)
requests.exceptions.ConnectTimeout: HTTPConnectionPool(host='api.isportsapi.com', port=80): Max retries exceeded with url: /sport/football/livescores?api_key=VEM3L91m7eguSCla (Caused by ConnectTimeoutError(<urllib3.connection.HTTPConnection object at 0x71ceae13ab10>, 'Connection to api.isportsapi.com timed out. (connect timeout=None)'))
Traceback (most recent call last):
  File "/home/arifin/envbot/lib/python3.12/site-packages/urllib3/connection.py", line 198, in _new_conn
    sock = connection.create_connection(
           ^^^^^^^^^^^^^^^^^^^^^^^^^^^^^
  File "/home/arifin/envbot/lib/python3.12/site-packages/urllib3/util/connection.py", line 85, in create_connection
    raise err
  File "/home/arifin/envbot/lib/python3.12/site-packages/urllib3/util/connection.py", line 73, in create_connection
    sock.connect(sa)
TimeoutError: [Errno 110] Connection timed out

The above exception was the direct cause of the following exception:

Traceback (most recent call last):
  File "/home/arifin/envbot/lib/python3.12/site-packages/urllib3/connectionpool.py", line 787, in urlopen
    response = self._make_request(
               ^^^^^^^^^^^^^^^^^^^
  File "/home/arifin/envbot/lib/python3.12/site-packages/urllib3/connectionpool.py", line 493, in _make_request
    conn.request(
  File "/home/arifin/envbot/lib/python3.12/site-packages/urllib3/connection.py", line 494, in request
    self.endheaders()
  File "/usr/lib/python3.12/http/client.py", line 1331, in endheaders
    self._send_output(message_body, encode_chunked=encode_chunked)
  File "/usr/lib/python3.12/http/client.py", line 1091, in _send_output
    self.send(msg)
  File "/usr/lib/python3.12/http/client.py", line 1035, in send
    self.connect()
  File "/home/arifin/envbot/lib/python3.12/site-packages/urllib3/connection.py", line 325, in connect
    self.sock = self._new_conn()
                ^^^^^^^^^^^^^^^^
  File "/home/arifin/envbot/lib/python3.12/site-packages/urllib3/connection.py", line 207, in _new_conn
    raise ConnectTimeoutError(
urllib3.exceptions.ConnectTimeoutError: (<urllib3.connection.HTTPConnection object at 0x7f6d510f8590>, 'Connection to api.isportsapi.com timed out. (connect timeout=None)')

The above exception was the direct cause of the following exception:

Traceback (most recent call last):
  File "/home/arifin/envbot/lib/python3.12/site-packages/requests/adapters.py", line 667, in send
    resp = conn.urlopen(
           ^^^^^^^^^^^^^
  File "/home/arifin/envbot/lib/python3.12/site-packages/urllib3/connectionpool.py", line 841, in urlopen
    retries = retries.increment(
              ^^^^^^^^^^^^^^^^^^
  File "/home/arifin/envbot/lib/python3.12/site-packages/urllib3/util/retry.py", line 519, in increment
    raise MaxRetryError(_pool, url, reason) from reason  # type: ignore[arg-type]
    ^^^^^^^^^^^^^^^^^^^^^^^^^^^^^^^^^^^^^^^^^^^^^^^^^^^
urllib3.exceptions.MaxRetryError: HTTPConnectionPool(host='api.isportsapi.com', port=80): Max retries exceeded with url: /sport/football/livescores?api_key=VEM3L91m7eguSCla (Caused by ConnectTimeoutError(<urllib3.connection.HTTPConnection object at 0x7f6d510f8590>, 'Connection to api.isportsapi.com timed out. (connect timeout=None)'))

During handling of the above exception, another exception occurred:

Traceback (most recent call last):
  File "/home/arifin/project/live_score/main.py", line 23, in <module>
    matches = fetch_matches()
              ^^^^^^^^^^^^^^^
  File "/home/arifin/project/live_score/main.py", line 17, in fetch_matches
    resp = requests.get(settings.NOWGOAL_API_URL, params=params)
           ^^^^^^^^^^^^^^^^^^^^^^^^^^^^^^^^^^^^^^^^^^^^^^^^^^^^^
  File "/home/arifin/envbot/lib/python3.12/site-packages/requests/api.py", line 73, in get
    return request("get", url, params=params, **kwargs)
           ^^^^^^^^^^^^^^^^^^^^^^^^^^^^^^^^^^^^^^^^^^^^
  File "/home/arifin/envbot/lib/python3.12/site-packages/requests/api.py", line 59, in request
    return session.request(method=method, url=url, **kwargs)
           ^^^^^^^^^^^^^^^^^^^^^^^^^^^^^^^^^^^^^^^^^^^^^^^^^
  File "/home/arifin/envbot/lib/python3.12/site-packages/requests/sessions.py", line 589, in request
    resp = self.send(prep, **send_kwargs)
           ^^^^^^^^^^^^^^^^^^^^^^^^^^^^^^
  File "/home/arifin/envbot/lib/python3.12/site-packages/requests/sessions.py", line 703, in send
    r = adapter.send(request, **kwargs)
        ^^^^^^^^^^^^^^^^^^^^^^^^^^^^^^^
  File "/home/arifin/envbot/lib/python3.12/site-packages/requests/adapters.py", line 688, in send
    raise ConnectTimeout(e, request=request)
requests.exceptions.ConnectTimeout: HTTPConnectionPool(host='api.isportsapi.com', port=80): Max retries exceeded with url: /sport/football/livescores?api_key=VEM3L91m7eguSCla (Caused by ConnectTimeoutError(<urllib3.connection.HTTPConnection object at 0x7f6d510f8590>, 'Connection to api.isportsapi.com timed out. (connect timeout=None)'))
Traceback (most recent call last):
  File "/home/arifin/envbot/lib/python3.12/site-packages/urllib3/connection.py", line 198, in _new_conn
    sock = connection.create_connection(
           ^^^^^^^^^^^^^^^^^^^^^^^^^^^^^
  File "/home/arifin/envbot/lib/python3.12/site-packages/urllib3/util/connection.py", line 60, in create_connection
    for res in socket.getaddrinfo(host, port, family, socket.SOCK_STREAM):
               ^^^^^^^^^^^^^^^^^^^^^^^^^^^^^^^^^^^^^^^^^^^^^^^^^^^^^^^^^^
  File "/usr/lib/python3.12/socket.py", line 963, in getaddrinfo
    for res in _socket.getaddrinfo(host, port, family, type, proto, flags):
               ^^^^^^^^^^^^^^^^^^^^^^^^^^^^^^^^^^^^^^^^^^^^^^^^^^^^^^^^^^^
socket.gaierror: [Errno -3] Temporary failure in name resolution

The above exception was the direct cause of the following exception:

Traceback (most recent call last):
  File "/home/arifin/envbot/lib/python3.12/site-packages/urllib3/connectionpool.py", line 787, in urlopen
    response = self._make_request(
               ^^^^^^^^^^^^^^^^^^^
  File "/home/arifin/envbot/lib/python3.12/site-packages/urllib3/connectionpool.py", line 493, in _make_request
    conn.request(
  File "/home/arifin/envbot/lib/python3.12/site-packages/urllib3/connection.py", line 494, in request
    self.endheaders()
  File "/usr/lib/python3.12/http/client.py", line 1331, in endheaders
    self._send_output(message_body, encode_chunked=encode_chunked)
  File "/usr/lib/python3.12/http/client.py", line 1091, in _send_output
    self.send(msg)
  File "/usr/lib/python3.12/http/client.py", line 1035, in send
    self.connect()
  File "/home/arifin/envbot/lib/python3.12/site-packages/urllib3/connection.py", line 325, in connect
    self.sock = self._new_conn()
                ^^^^^^^^^^^^^^^^
  File "/home/arifin/envbot/lib/python3.12/site-packages/urllib3/connection.py", line 205, in _new_conn
    raise NameResolutionError(self.host, self, e) from e
urllib3.exceptions.NameResolutionError: <urllib3.connection.HTTPConnection object at 0x78caf6a32e40>: Failed to resolve 'api.isportsapi.com' ([Errno -3] Temporary failure in name resolution)

The above exception was the direct cause of the following exception:

Traceback (most recent call last):
  File "/home/arifin/envbot/lib/python3.12/site-packages/requests/adapters.py", line 667, in send
    resp = conn.urlopen(
           ^^^^^^^^^^^^^
  File "/home/arifin/envbot/lib/python3.12/site-packages/urllib3/connectionpool.py", line 841, in urlopen
    retries = retries.increment(
              ^^^^^^^^^^^^^^^^^^
  File "/home/arifin/envbot/lib/python3.12/site-packages/urllib3/util/retry.py", line 519, in increment
    raise MaxRetryError(_pool, url, reason) from reason  # type: ignore[arg-type]
    ^^^^^^^^^^^^^^^^^^^^^^^^^^^^^^^^^^^^^^^^^^^^^^^^^^^
urllib3.exceptions.MaxRetryError: HTTPConnectionPool(host='api.isportsapi.com', port=80): Max retries exceeded with url: /sport/football/livescores?api_key=VEM3L91m7eguSCla (Caused by NameResolutionError("<urllib3.connection.HTTPConnection object at 0x78caf6a32e40>: Failed to resolve 'api.isportsapi.com' ([Errno -3] Temporary failure in name resolution)"))

During handling of the above exception, another exception occurred:

Traceback (most recent call last):
  File "/home/arifin/project/live_score/main.py", line 23, in <module>
    matches = fetch_matches()
              ^^^^^^^^^^^^^^^
  File "/home/arifin/project/live_score/main.py", line 17, in fetch_matches
    resp = requests.get(settings.NOWGOAL_API_URL, params=params)
           ^^^^^^^^^^^^^^^^^^^^^^^^^^^^^^^^^^^^^^^^^^^^^^^^^^^^^
  File "/home/arifin/envbot/lib/python3.12/site-packages/requests/api.py", line 73, in get
    return request("get", url, params=params, **kwargs)
           ^^^^^^^^^^^^^^^^^^^^^^^^^^^^^^^^^^^^^^^^^^^^
  File "/home/arifin/envbot/lib/python3.12/site-packages/requests/api.py", line 59, in request
    return session.request(method=method, url=url, **kwargs)
           ^^^^^^^^^^^^^^^^^^^^^^^^^^^^^^^^^^^^^^^^^^^^^^^^^
  File "/home/arifin/envbot/lib/python3.12/site-packages/requests/sessions.py", line 589, in request
    resp = self.send(prep, **send_kwargs)
           ^^^^^^^^^^^^^^^^^^^^^^^^^^^^^^
  File "/home/arifin/envbot/lib/python3.12/site-packages/requests/sessions.py", line 703, in send
    r = adapter.send(request, **kwargs)
        ^^^^^^^^^^^^^^^^^^^^^^^^^^^^^^^
  File "/home/arifin/envbot/lib/python3.12/site-packages/requests/adapters.py", line 700, in send
    raise ConnectionError(e, request=request)
requests.exceptions.ConnectionError: HTTPConnectionPool(host='api.isportsapi.com', port=80): Max retries exceeded with url: /sport/football/livescores?api_key=VEM3L91m7eguSCla (Caused by NameResolutionError("<urllib3.connection.HTTPConnection object at 0x78caf6a32e40>: Failed to resolve 'api.isportsapi.com' ([Errno -3] Temporary failure in name resolution)"))
ðŸ“Š Total pertandingan: 292
ðŸŽ¯ Yang memenuhi syarat: 6
Traceback (most recent call last):
  File "/home/arifin/envbot/lib/python3.12/site-packages/httpx/_transports/default.py", line 101, in map_httpcore_exceptions
    yield
  File "/home/arifin/envbot/lib/python3.12/site-packages/httpx/_transports/default.py", line 250, in handle_request
    resp = self._pool.handle_request(req)
           ^^^^^^^^^^^^^^^^^^^^^^^^^^^^^^
  File "/home/arifin/envbot/lib/python3.12/site-packages/httpcore/_sync/connection_pool.py", line 256, in handle_request
    raise exc from None
  File "/home/arifin/envbot/lib/python3.12/site-packages/httpcore/_sync/connection_pool.py", line 236, in handle_request
    response = connection.handle_request(
               ^^^^^^^^^^^^^^^^^^^^^^^^^^
  File "/home/arifin/envbot/lib/python3.12/site-packages/httpcore/_sync/connection.py", line 101, in handle_request
    raise exc
  File "/home/arifin/envbot/lib/python3.12/site-packages/httpcore/_sync/connection.py", line 78, in handle_request
    stream = self._connect(request)
             ^^^^^^^^^^^^^^^^^^^^^^
  File "/home/arifin/envbot/lib/python3.12/site-packages/httpcore/_sync/connection.py", line 156, in _connect
    stream = stream.start_tls(**kwargs)
             ^^^^^^^^^^^^^^^^^^^^^^^^^^
  File "/home/arifin/envbot/lib/python3.12/site-packages/httpcore/_backends/sync.py", line 154, in start_tls
    with map_exceptions(exc_map):
  File "/usr/lib/python3.12/contextlib.py", line 158, in __exit__
    self.gen.throw(value)
  File "/home/arifin/envbot/lib/python3.12/site-packages/httpcore/_exceptions.py", line 14, in map_exceptions
    raise to_exc(exc) from exc
httpcore.ConnectTimeout: _ssl.c:983: The handshake operation timed out

The above exception was the direct cause of the following exception:

Traceback (most recent call last):
  File "/home/arifin/project/live_score/main.py", line 30, in <module>
    notify(match, reason)
  File "/home/arifin/project/live_score/notifier.py", line 68, in notify
    httpx.post(f"{API_URL}/sendMessage", json={
  File "/home/arifin/envbot/lib/python3.12/site-packages/httpx/_api.py", line 304, in post
    return request(
           ^^^^^^^^
  File "/home/arifin/envbot/lib/python3.12/site-packages/httpx/_api.py", line 109, in request
    return client.request(
           ^^^^^^^^^^^^^^^
  File "/home/arifin/envbot/lib/python3.12/site-packages/httpx/_client.py", line 825, in request
    return self.send(request, auth=auth, follow_redirects=follow_redirects)
           ^^^^^^^^^^^^^^^^^^^^^^^^^^^^^^^^^^^^^^^^^^^^^^^^^^^^^^^^^^^^^^^^
  File "/home/arifin/envbot/lib/python3.12/site-packages/httpx/_client.py", line 914, in send
    response = self._send_handling_auth(
               ^^^^^^^^^^^^^^^^^^^^^^^^^
  File "/home/arifin/envbot/lib/python3.12/site-packages/httpx/_client.py", line 942, in _send_handling_auth
    response = self._send_handling_redirects(
               ^^^^^^^^^^^^^^^^^^^^^^^^^^^^^^
  File "/home/arifin/envbot/lib/python3.12/site-packages/httpx/_client.py", line 979, in _send_handling_redirects
    response = self._send_single_request(request)
               ^^^^^^^^^^^^^^^^^^^^^^^^^^^^^^^^^^
  File "/home/arifin/envbot/lib/python3.12/site-packages/httpx/_client.py", line 1014, in _send_single_request
    response = transport.handle_request(request)
               ^^^^^^^^^^^^^^^^^^^^^^^^^^^^^^^^^
  File "/home/arifin/envbot/lib/python3.12/site-packages/httpx/_transports/default.py", line 249, in handle_request
    with map_httpcore_exceptions():
  File "/usr/lib/python3.12/contextlib.py", line 158, in __exit__
    self.gen.throw(value)
  File "/home/arifin/envbot/lib/python3.12/site-packages/httpx/_transports/default.py", line 118, in map_httpcore_exceptions
    raise mapped_exc(message) from exc
httpx.ConnectTimeout: _ssl.c:983: The handshake operation timed out
Traceback (most recent call last):
  File "/home/arifin/envbot/lib/python3.12/site-packages/urllib3/connection.py", line 198, in _new_conn
    sock = connection.create_connection(
           ^^^^^^^^^^^^^^^^^^^^^^^^^^^^^
  File "/home/arifin/envbot/lib/python3.12/site-packages/urllib3/util/connection.py", line 85, in create_connection
    raise err
  File "/home/arifin/envbot/lib/python3.12/site-packages/urllib3/util/connection.py", line 73, in create_connection
    sock.connect(sa)
TimeoutError: [Errno 110] Connection timed out

The above exception was the direct cause of the following exception:

Traceback (most recent call last):
  File "/home/arifin/envbot/lib/python3.12/site-packages/urllib3/connectionpool.py", line 787, in urlopen
    response = self._make_request(
               ^^^^^^^^^^^^^^^^^^^
  File "/home/arifin/envbot/lib/python3.12/site-packages/urllib3/connectionpool.py", line 493, in _make_request
    conn.request(
  File "/home/arifin/envbot/lib/python3.12/site-packages/urllib3/connection.py", line 494, in request
    self.endheaders()
  File "/usr/lib/python3.12/http/client.py", line 1331, in endheaders
    self._send_output(message_body, encode_chunked=encode_chunked)
  File "/usr/lib/python3.12/http/client.py", line 1091, in _send_output
    self.send(msg)
  File "/usr/lib/python3.12/http/client.py", line 1035, in send
    self.connect()
  File "/home/arifin/envbot/lib/python3.12/site-packages/urllib3/connection.py", line 325, in connect
    self.sock = self._new_conn()
                ^^^^^^^^^^^^^^^^
  File "/home/arifin/envbot/lib/python3.12/site-packages/urllib3/connection.py", line 207, in _new_conn
    raise ConnectTimeoutError(
urllib3.exceptions.ConnectTimeoutError: (<urllib3.connection.HTTPConnection object at 0x71bf1049a900>, 'Connection to api.isportsapi.com timed out. (connect timeout=None)')

The above exception was the direct cause of the following exception:

Traceback (most recent call last):
  File "/home/arifin/envbot/lib/python3.12/site-packages/requests/adapters.py", line 667, in send
    resp = conn.urlopen(
           ^^^^^^^^^^^^^
  File "/home/arifin/envbot/lib/python3.12/site-packages/urllib3/connectionpool.py", line 841, in urlopen
    retries = retries.increment(
              ^^^^^^^^^^^^^^^^^^
  File "/home/arifin/envbot/lib/python3.12/site-packages/urllib3/util/retry.py", line 519, in increment
    raise MaxRetryError(_pool, url, reason) from reason  # type: ignore[arg-type]
    ^^^^^^^^^^^^^^^^^^^^^^^^^^^^^^^^^^^^^^^^^^^^^^^^^^^
urllib3.exceptions.MaxRetryError: HTTPConnectionPool(host='api.isportsapi.com', port=80): Max retries exceeded with url: /sport/football/livescores?api_key=VEM3L91m7eguSCla (Caused by ConnectTimeoutError(<urllib3.connection.HTTPConnection object at 0x71bf1049a900>, 'Connection to api.isportsapi.com timed out. (connect timeout=None)'))

During handling of the above exception, another exception occurred:

Traceback (most recent call last):
  File "/home/arifin/project/live_score/main.py", line 23, in <module>
    matches = fetch_matches()
              ^^^^^^^^^^^^^^^
  File "/home/arifin/project/live_score/main.py", line 17, in fetch_matches
    resp = requests.get(settings.NOWGOAL_API_URL, params=params)
           ^^^^^^^^^^^^^^^^^^^^^^^^^^^^^^^^^^^^^^^^^^^^^^^^^^^^^
  File "/home/arifin/envbot/lib/python3.12/site-packages/requests/api.py", line 73, in get
    return request("get", url, params=params, **kwargs)
           ^^^^^^^^^^^^^^^^^^^^^^^^^^^^^^^^^^^^^^^^^^^^
  File "/home/arifin/envbot/lib/python3.12/site-packages/requests/api.py", line 59, in request
    return session.request(method=method, url=url, **kwargs)
           ^^^^^^^^^^^^^^^^^^^^^^^^^^^^^^^^^^^^^^^^^^^^^^^^^
  File "/home/arifin/envbot/lib/python3.12/site-packages/requests/sessions.py", line 589, in request
    resp = self.send(prep, **send_kwargs)
           ^^^^^^^^^^^^^^^^^^^^^^^^^^^^^^
  File "/home/arifin/envbot/lib/python3.12/site-packages/requests/sessions.py", line 703, in send
    r = adapter.send(request, **kwargs)
        ^^^^^^^^^^^^^^^^^^^^^^^^^^^^^^^
  File "/home/arifin/envbot/lib/python3.12/site-packages/requests/adapters.py", line 688, in send
    raise ConnectTimeout(e, request=request)
requests.exceptions.ConnectTimeout: HTTPConnectionPool(host='api.isportsapi.com', port=80): Max retries exceeded with url: /sport/football/livescores?api_key=VEM3L91m7eguSCla (Caused by ConnectTimeoutError(<urllib3.connection.HTTPConnection object at 0x71bf1049a900>, 'Connection to api.isportsapi.com timed out. (connect timeout=None)'))
ðŸ“Š Total pertandingan: 292
ðŸŽ¯ Yang memenuhi syarat: 6
Traceback (most recent call last):
  File "/home/arifin/envbot/lib/python3.12/site-packages/httpx/_transports/default.py", line 101, in map_httpcore_exceptions
    yield
  File "/home/arifin/envbot/lib/python3.12/site-packages/httpx/_transports/default.py", line 250, in handle_request
    resp = self._pool.handle_request(req)
           ^^^^^^^^^^^^^^^^^^^^^^^^^^^^^^
  File "/home/arifin/envbot/lib/python3.12/site-packages/httpcore/_sync/connection_pool.py", line 256, in handle_request
    raise exc from None
  File "/home/arifin/envbot/lib/python3.12/site-packages/httpcore/_sync/connection_pool.py", line 236, in handle_request
    response = connection.handle_request(
               ^^^^^^^^^^^^^^^^^^^^^^^^^^
  File "/home/arifin/envbot/lib/python3.12/site-packages/httpcore/_sync/connection.py", line 103, in handle_request
    return self._connection.handle_request(request)
           ^^^^^^^^^^^^^^^^^^^^^^^^^^^^^^^^^^^^^^^^
  File "/home/arifin/envbot/lib/python3.12/site-packages/httpcore/_sync/http11.py", line 136, in handle_request
    raise exc
  File "/home/arifin/envbot/lib/python3.12/site-packages/httpcore/_sync/http11.py", line 106, in handle_request
    ) = self._receive_response_headers(**kwargs)
        ^^^^^^^^^^^^^^^^^^^^^^^^^^^^^^^^^^^^^^^^
  File "/home/arifin/envbot/lib/python3.12/site-packages/httpcore/_sync/http11.py", line 177, in _receive_response_headers
    event = self._receive_event(timeout=timeout)
            ^^^^^^^^^^^^^^^^^^^^^^^^^^^^^^^^^^^^
  File "/home/arifin/envbot/lib/python3.12/site-packages/httpcore/_sync/http11.py", line 231, in _receive_event
    raise RemoteProtocolError(msg)
httpcore.RemoteProtocolError: Server disconnected without sending a response.

The above exception was the direct cause of the following exception:

Traceback (most recent call last):
  File "/home/arifin/project/live_score/main.py", line 30, in <module>
    notify(match, reason)
  File "/home/arifin/project/live_score/notifier.py", line 68, in notify
    httpx.post(f"{API_URL}/sendMessage", json={
  File "/home/arifin/envbot/lib/python3.12/site-packages/httpx/_api.py", line 304, in post
    return request(
           ^^^^^^^^
  File "/home/arifin/envbot/lib/python3.12/site-packages/httpx/_api.py", line 109, in request
    return client.request(
           ^^^^^^^^^^^^^^^
  File "/home/arifin/envbot/lib/python3.12/site-packages/httpx/_client.py", line 825, in request
    return self.send(request, auth=auth, follow_redirects=follow_redirects)
           ^^^^^^^^^^^^^^^^^^^^^^^^^^^^^^^^^^^^^^^^^^^^^^^^^^^^^^^^^^^^^^^^
  File "/home/arifin/envbot/lib/python3.12/site-packages/httpx/_client.py", line 914, in send
    response = self._send_handling_auth(
               ^^^^^^^^^^^^^^^^^^^^^^^^^
  File "/home/arifin/envbot/lib/python3.12/site-packages/httpx/_client.py", line 942, in _send_handling_auth
    response = self._send_handling_redirects(
               ^^^^^^^^^^^^^^^^^^^^^^^^^^^^^^
  File "/home/arifin/envbot/lib/python3.12/site-packages/httpx/_client.py", line 979, in _send_handling_redirects
    response = self._send_single_request(request)
               ^^^^^^^^^^^^^^^^^^^^^^^^^^^^^^^^^^
  File "/home/arifin/envbot/lib/python3.12/site-packages/httpx/_client.py", line 1014, in _send_single_request
    response = transport.handle_request(request)
               ^^^^^^^^^^^^^^^^^^^^^^^^^^^^^^^^^
  File "/home/arifin/envbot/lib/python3.12/site-packages/httpx/_transports/default.py", line 249, in handle_request
    with map_httpcore_exceptions():
  File "/usr/lib/python3.12/contextlib.py", line 158, in __exit__
    self.gen.throw(value)
  File "/home/arifin/envbot/lib/python3.12/site-packages/httpx/_transports/default.py", line 118, in map_httpcore_exceptions
    raise mapped_exc(message) from exc
httpx.RemoteProtocolError: Server disconnected without sending a response.
ðŸ“Š Total pertandingan: 292
ðŸŽ¯ Yang memenuhi syarat: 6
Traceback (most recent call last):
  File "/home/arifin/envbot/lib/python3.12/site-packages/httpx/_transports/default.py", line 101, in map_httpcore_exceptions
    yield
  File "/home/arifin/envbot/lib/python3.12/site-packages/httpx/_transports/default.py", line 250, in handle_request
    resp = self._pool.handle_request(req)
           ^^^^^^^^^^^^^^^^^^^^^^^^^^^^^^
  File "/home/arifin/envbot/lib/python3.12/site-packages/httpcore/_sync/connection_pool.py", line 256, in handle_request
    raise exc from None
  File "/home/arifin/envbot/lib/python3.12/site-packages/httpcore/_sync/connection_pool.py", line 236, in handle_request
    response = connection.handle_request(
               ^^^^^^^^^^^^^^^^^^^^^^^^^^
  File "/home/arifin/envbot/lib/python3.12/site-packages/httpcore/_sync/connection.py", line 101, in handle_request
    raise exc
  File "/home/arifin/envbot/lib/python3.12/site-packages/httpcore/_sync/connection.py", line 78, in handle_request
    stream = self._connect(request)
             ^^^^^^^^^^^^^^^^^^^^^^
  File "/home/arifin/envbot/lib/python3.12/site-packages/httpcore/_sync/connection.py", line 124, in _connect
    stream = self._network_backend.connect_tcp(**kwargs)
             ^^^^^^^^^^^^^^^^^^^^^^^^^^^^^^^^^^^^^^^^^^^
  File "/home/arifin/envbot/lib/python3.12/site-packages/httpcore/_backends/sync.py", line 207, in connect_tcp
    with map_exceptions(exc_map):
  File "/usr/lib/python3.12/contextlib.py", line 158, in __exit__
    self.gen.throw(value)
  File "/home/arifin/envbot/lib/python3.12/site-packages/httpcore/_exceptions.py", line 14, in map_exceptions
    raise to_exc(exc) from exc
httpcore.ConnectError: [Errno -3] Temporary failure in name resolution

The above exception was the direct cause of the following exception:

Traceback (most recent call last):
  File "/home/arifin/project/live_score/main.py", line 30, in <module>
    notify(match, reason)
  File "/home/arifin/project/live_score/notifier.py", line 68, in notify
    httpx.post(f"{API_URL}/sendMessage", json={
  File "/home/arifin/envbot/lib/python3.12/site-packages/httpx/_api.py", line 304, in post
    return request(
           ^^^^^^^^
  File "/home/arifin/envbot/lib/python3.12/site-packages/httpx/_api.py", line 109, in request
    return client.request(
           ^^^^^^^^^^^^^^^
  File "/home/arifin/envbot/lib/python3.12/site-packages/httpx/_client.py", line 825, in request
    return self.send(request, auth=auth, follow_redirects=follow_redirects)
           ^^^^^^^^^^^^^^^^^^^^^^^^^^^^^^^^^^^^^^^^^^^^^^^^^^^^^^^^^^^^^^^^
  File "/home/arifin/envbot/lib/python3.12/site-packages/httpx/_client.py", line 914, in send
    response = self._send_handling_auth(
               ^^^^^^^^^^^^^^^^^^^^^^^^^
  File "/home/arifin/envbot/lib/python3.12/site-packages/httpx/_client.py", line 942, in _send_handling_auth
    response = self._send_handling_redirects(
               ^^^^^^^^^^^^^^^^^^^^^^^^^^^^^^
  File "/home/arifin/envbot/lib/python3.12/site-packages/httpx/_client.py", line 979, in _send_handling_redirects
    response = self._send_single_request(request)
               ^^^^^^^^^^^^^^^^^^^^^^^^^^^^^^^^^^
  File "/home/arifin/envbot/lib/python3.12/site-packages/httpx/_client.py", line 1014, in _send_single_request
    response = transport.handle_request(request)
               ^^^^^^^^^^^^^^^^^^^^^^^^^^^^^^^^^
  File "/home/arifin/envbot/lib/python3.12/site-packages/httpx/_transports/default.py", line 249, in handle_request
    with map_httpcore_exceptions():
  File "/usr/lib/python3.12/contextlib.py", line 158, in __exit__
    self.gen.throw(value)
  File "/home/arifin/envbot/lib/python3.12/site-packages/httpx/_transports/default.py", line 118, in map_httpcore_exceptions
    raise mapped_exc(message) from exc
httpx.ConnectError: [Errno -3] Temporary failure in name resolution
ðŸ“Š Total pertandingan: 292
ðŸŽ¯ Yang memenuhi syarat: 6
Traceback (most recent call last):
  File "/home/arifin/envbot/lib/python3.12/site-packages/httpx/_transports/default.py", line 101, in map_httpcore_exceptions
    yield
  File "/home/arifin/envbot/lib/python3.12/site-packages/httpx/_transports/default.py", line 250, in handle_request
    resp = self._pool.handle_request(req)
           ^^^^^^^^^^^^^^^^^^^^^^^^^^^^^^
  File "/home/arifin/envbot/lib/python3.12/site-packages/httpcore/_sync/connection_pool.py", line 256, in handle_request
    raise exc from None
  File "/home/arifin/envbot/lib/python3.12/site-packages/httpcore/_sync/connection_pool.py", line 236, in handle_request
    response = connection.handle_request(
               ^^^^^^^^^^^^^^^^^^^^^^^^^^
  File "/home/arifin/envbot/lib/python3.12/site-packages/httpcore/_sync/connection.py", line 101, in handle_request
    raise exc
  File "/home/arifin/envbot/lib/python3.12/site-packages/httpcore/_sync/connection.py", line 78, in handle_request
    stream = self._connect(request)
             ^^^^^^^^^^^^^^^^^^^^^^
  File "/home/arifin/envbot/lib/python3.12/site-packages/httpcore/_sync/connection.py", line 124, in _connect
    stream = self._network_backend.connect_tcp(**kwargs)
             ^^^^^^^^^^^^^^^^^^^^^^^^^^^^^^^^^^^^^^^^^^^
  File "/home/arifin/envbot/lib/python3.12/site-packages/httpcore/_backends/sync.py", line 207, in connect_tcp
    with map_exceptions(exc_map):
  File "/usr/lib/python3.12/contextlib.py", line 158, in __exit__
    self.gen.throw(value)
  File "/home/arifin/envbot/lib/python3.12/site-packages/httpcore/_exceptions.py", line 14, in map_exceptions
    raise to_exc(exc) from exc
httpcore.ConnectError: [Errno -3] Temporary failure in name resolution

The above exception was the direct cause of the following exception:

Traceback (most recent call last):
  File "/home/arifin/project/live_score/main.py", line 30, in <module>
    notify(match, reason)
  File "/home/arifin/project/live_score/notifier.py", line 68, in notify
    httpx.post(f"{API_URL}/sendMessage", json={
  File "/home/arifin/envbot/lib/python3.12/site-packages/httpx/_api.py", line 304, in post
    return request(
           ^^^^^^^^
  File "/home/arifin/envbot/lib/python3.12/site-packages/httpx/_api.py", line 109, in request
    return client.request(
           ^^^^^^^^^^^^^^^
  File "/home/arifin/envbot/lib/python3.12/site-packages/httpx/_client.py", line 825, in request
    return self.send(request, auth=auth, follow_redirects=follow_redirects)
           ^^^^^^^^^^^^^^^^^^^^^^^^^^^^^^^^^^^^^^^^^^^^^^^^^^^^^^^^^^^^^^^^
  File "/home/arifin/envbot/lib/python3.12/site-packages/httpx/_client.py", line 914, in send
    response = self._send_handling_auth(
               ^^^^^^^^^^^^^^^^^^^^^^^^^
  File "/home/arifin/envbot/lib/python3.12/site-packages/httpx/_client.py", line 942, in _send_handling_auth
    response = self._send_handling_redirects(
               ^^^^^^^^^^^^^^^^^^^^^^^^^^^^^^
  File "/home/arifin/envbot/lib/python3.12/site-packages/httpx/_client.py", line 979, in _send_handling_redirects
    response = self._send_single_request(request)
               ^^^^^^^^^^^^^^^^^^^^^^^^^^^^^^^^^^
  File "/home/arifin/envbot/lib/python3.12/site-packages/httpx/_client.py", line 1014, in _send_single_request
    response = transport.handle_request(request)
               ^^^^^^^^^^^^^^^^^^^^^^^^^^^^^^^^^
  File "/home/arifin/envbot/lib/python3.12/site-packages/httpx/_transports/default.py", line 249, in handle_request
    with map_httpcore_exceptions():
  File "/usr/lib/python3.12/contextlib.py", line 158, in __exit__
    self.gen.throw(value)
  File "/home/arifin/envbot/lib/python3.12/site-packages/httpx/_transports/default.py", line 118, in map_httpcore_exceptions
    raise mapped_exc(message) from exc
httpx.ConnectError: [Errno -3] Temporary failure in name resolution
ðŸ“Š Total pertandingan: 292
ðŸŽ¯ Yang memenuhi syarat: 6
Traceback (most recent call last):
  File "/home/arifin/envbot/lib/python3.12/site-packages/httpx/_transports/default.py", line 101, in map_httpcore_exceptions
    yield
  File "/home/arifin/envbot/lib/python3.12/site-packages/httpx/_transports/default.py", line 250, in handle_request
    resp = self._pool.handle_request(req)
           ^^^^^^^^^^^^^^^^^^^^^^^^^^^^^^
  File "/home/arifin/envbot/lib/python3.12/site-packages/httpcore/_sync/connection_pool.py", line 256, in handle_request
    raise exc from None
  File "/home/arifin/envbot/lib/python3.12/site-packages/httpcore/_sync/connection_pool.py", line 236, in handle_request
    response = connection.handle_request(
               ^^^^^^^^^^^^^^^^^^^^^^^^^^
  File "/home/arifin/envbot/lib/python3.12/site-packages/httpcore/_sync/connection.py", line 101, in handle_request
    raise exc
  File "/home/arifin/envbot/lib/python3.12/site-packages/httpcore/_sync/connection.py", line 78, in handle_request
    stream = self._connect(request)
             ^^^^^^^^^^^^^^^^^^^^^^
  File "/home/arifin/envbot/lib/python3.12/site-packages/httpcore/_sync/connection.py", line 124, in _connect
    stream = self._network_backend.connect_tcp(**kwargs)
             ^^^^^^^^^^^^^^^^^^^^^^^^^^^^^^^^^^^^^^^^^^^
  File "/home/arifin/envbot/lib/python3.12/site-packages/httpcore/_backends/sync.py", line 207, in connect_tcp
    with map_exceptions(exc_map):
  File "/usr/lib/python3.12/contextlib.py", line 158, in __exit__
    self.gen.throw(value)
  File "/home/arifin/envbot/lib/python3.12/site-packages/httpcore/_exceptions.py", line 14, in map_exceptions
    raise to_exc(exc) from exc
httpcore.ConnectError: [Errno -3] Temporary failure in name resolution

The above exception was the direct cause of the following exception:

Traceback (most recent call last):
  File "/home/arifin/project/live_score/main.py", line 30, in <module>
    notify(match, reason)
  File "/home/arifin/project/live_score/notifier.py", line 68, in notify
    httpx.post(f"{API_URL}/sendMessage", json={
  File "/home/arifin/envbot/lib/python3.12/site-packages/httpx/_api.py", line 304, in post
    return request(
           ^^^^^^^^
  File "/home/arifin/envbot/lib/python3.12/site-packages/httpx/_api.py", line 109, in request
    return client.request(
           ^^^^^^^^^^^^^^^
  File "/home/arifin/envbot/lib/python3.12/site-packages/httpx/_client.py", line 825, in request
    return self.send(request, auth=auth, follow_redirects=follow_redirects)
           ^^^^^^^^^^^^^^^^^^^^^^^^^^^^^^^^^^^^^^^^^^^^^^^^^^^^^^^^^^^^^^^^
  File "/home/arifin/envbot/lib/python3.12/site-packages/httpx/_client.py", line 914, in send
    response = self._send_handling_auth(
               ^^^^^^^^^^^^^^^^^^^^^^^^^
  File "/home/arifin/envbot/lib/python3.12/site-packages/httpx/_client.py", line 942, in _send_handling_auth
    response = self._send_handling_redirects(
               ^^^^^^^^^^^^^^^^^^^^^^^^^^^^^^
  File "/home/arifin/envbot/lib/python3.12/site-packages/httpx/_client.py", line 979, in _send_handling_redirects
    response = self._send_single_request(request)
               ^^^^^^^^^^^^^^^^^^^^^^^^^^^^^^^^^^
  File "/home/arifin/envbot/lib/python3.12/site-packages/httpx/_client.py", line 1014, in _send_single_request
    response = transport.handle_request(request)
               ^^^^^^^^^^^^^^^^^^^^^^^^^^^^^^^^^
  File "/home/arifin/envbot/lib/python3.12/site-packages/httpx/_transports/default.py", line 249, in handle_request
    with map_httpcore_exceptions():
  File "/usr/lib/python3.12/contextlib.py", line 158, in __exit__
    self.gen.throw(value)
  File "/home/arifin/envbot/lib/python3.12/site-packages/httpx/_transports/default.py", line 118, in map_httpcore_exceptions
    raise mapped_exc(message) from exc
httpx.ConnectError: [Errno -3] Temporary failure in name resolution
ðŸ“Š Total pertandingan: 293
ðŸŽ¯ Yang memenuhi syarat: 6
Traceback (most recent call last):
  File "/home/arifin/envbot/lib/python3.12/site-packages/httpx/_transports/default.py", line 101, in map_httpcore_exceptions
    yield
  File "/home/arifin/envbot/lib/python3.12/site-packages/httpx/_transports/default.py", line 250, in handle_request
    resp = self._pool.handle_request(req)
           ^^^^^^^^^^^^^^^^^^^^^^^^^^^^^^
  File "/home/arifin/envbot/lib/python3.12/site-packages/httpcore/_sync/connection_pool.py", line 256, in handle_request
    raise exc from None
  File "/home/arifin/envbot/lib/python3.12/site-packages/httpcore/_sync/connection_pool.py", line 236, in handle_request
    response = connection.handle_request(
               ^^^^^^^^^^^^^^^^^^^^^^^^^^
  File "/home/arifin/envbot/lib/python3.12/site-packages/httpcore/_sync/connection.py", line 101, in handle_request
    raise exc
  File "/home/arifin/envbot/lib/python3.12/site-packages/httpcore/_sync/connection.py", line 78, in handle_request
    stream = self._connect(request)
             ^^^^^^^^^^^^^^^^^^^^^^
  File "/home/arifin/envbot/lib/python3.12/site-packages/httpcore/_sync/connection.py", line 124, in _connect
    stream = self._network_backend.connect_tcp(**kwargs)
             ^^^^^^^^^^^^^^^^^^^^^^^^^^^^^^^^^^^^^^^^^^^
  File "/home/arifin/envbot/lib/python3.12/site-packages/httpcore/_backends/sync.py", line 207, in connect_tcp
    with map_exceptions(exc_map):
  File "/usr/lib/python3.12/contextlib.py", line 158, in __exit__
    self.gen.throw(value)
  File "/home/arifin/envbot/lib/python3.12/site-packages/httpcore/_exceptions.py", line 14, in map_exceptions
    raise to_exc(exc) from exc
httpcore.ConnectError: [Errno -3] Temporary failure in name resolution

The above exception was the direct cause of the following exception:

Traceback (most recent call last):
  File "/home/arifin/project/live_score/main.py", line 30, in <module>
    notify(match, reason)
  File "/home/arifin/project/live_score/notifier.py", line 68, in notify
    httpx.post(f"{API_URL}/sendMessage", json={
  File "/home/arifin/envbot/lib/python3.12/site-packages/httpx/_api.py", line 304, in post
    return request(
           ^^^^^^^^
  File "/home/arifin/envbot/lib/python3.12/site-packages/httpx/_api.py", line 109, in request
    return client.request(
           ^^^^^^^^^^^^^^^
  File "/home/arifin/envbot/lib/python3.12/site-packages/httpx/_client.py", line 825, in request
    return self.send(request, auth=auth, follow_redirects=follow_redirects)
           ^^^^^^^^^^^^^^^^^^^^^^^^^^^^^^^^^^^^^^^^^^^^^^^^^^^^^^^^^^^^^^^^
  File "/home/arifin/envbot/lib/python3.12/site-packages/httpx/_client.py", line 914, in send
    response = self._send_handling_auth(
               ^^^^^^^^^^^^^^^^^^^^^^^^^
  File "/home/arifin/envbot/lib/python3.12/site-packages/httpx/_client.py", line 942, in _send_handling_auth
    response = self._send_handling_redirects(
               ^^^^^^^^^^^^^^^^^^^^^^^^^^^^^^
  File "/home/arifin/envbot/lib/python3.12/site-packages/httpx/_client.py", line 979, in _send_handling_redirects
    response = self._send_single_request(request)
               ^^^^^^^^^^^^^^^^^^^^^^^^^^^^^^^^^^
  File "/home/arifin/envbot/lib/python3.12/site-packages/httpx/_client.py", line 1014, in _send_single_request
    response = transport.handle_request(request)
               ^^^^^^^^^^^^^^^^^^^^^^^^^^^^^^^^^
  File "/home/arifin/envbot/lib/python3.12/site-packages/httpx/_transports/default.py", line 249, in handle_request
    with map_httpcore_exceptions():
  File "/usr/lib/python3.12/contextlib.py", line 158, in __exit__
    self.gen.throw(value)
  File "/home/arifin/envbot/lib/python3.12/site-packages/httpx/_transports/default.py", line 118, in map_httpcore_exceptions
    raise mapped_exc(message) from exc
httpx.ConnectError: [Errno -3] Temporary failure in name resolution
Traceback (most recent call last):
  File "/home/arifin/envbot/lib/python3.12/site-packages/urllib3/connection.py", line 198, in _new_conn
    sock = connection.create_connection(
           ^^^^^^^^^^^^^^^^^^^^^^^^^^^^^
  File "/home/arifin/envbot/lib/python3.12/site-packages/urllib3/util/connection.py", line 60, in create_connection
    for res in socket.getaddrinfo(host, port, family, socket.SOCK_STREAM):
               ^^^^^^^^^^^^^^^^^^^^^^^^^^^^^^^^^^^^^^^^^^^^^^^^^^^^^^^^^^
  File "/usr/lib/python3.12/socket.py", line 963, in getaddrinfo
    for res in _socket.getaddrinfo(host, port, family, type, proto, flags):
               ^^^^^^^^^^^^^^^^^^^^^^^^^^^^^^^^^^^^^^^^^^^^^^^^^^^^^^^^^^^
socket.gaierror: [Errno -3] Temporary failure in name resolution

The above exception was the direct cause of the following exception:

Traceback (most recent call last):
  File "/home/arifin/envbot/lib/python3.12/site-packages/urllib3/connectionpool.py", line 787, in urlopen
    response = self._make_request(
               ^^^^^^^^^^^^^^^^^^^
  File "/home/arifin/envbot/lib/python3.12/site-packages/urllib3/connectionpool.py", line 493, in _make_request
    conn.request(
  File "/home/arifin/envbot/lib/python3.12/site-packages/urllib3/connection.py", line 494, in request
    self.endheaders()
  File "/usr/lib/python3.12/http/client.py", line 1331, in endheaders
    self._send_output(message_body, encode_chunked=encode_chunked)
  File "/usr/lib/python3.12/http/client.py", line 1091, in _send_output
    self.send(msg)
  File "/usr/lib/python3.12/http/client.py", line 1035, in send
    self.connect()
  File "/home/arifin/envbot/lib/python3.12/site-packages/urllib3/connection.py", line 325, in connect
    self.sock = self._new_conn()
                ^^^^^^^^^^^^^^^^
  File "/home/arifin/envbot/lib/python3.12/site-packages/urllib3/connection.py", line 205, in _new_conn
    raise NameResolutionError(self.host, self, e) from e
urllib3.exceptions.NameResolutionError: <urllib3.connection.HTTPConnection object at 0x745a50ed3800>: Failed to resolve 'api.isportsapi.com' ([Errno -3] Temporary failure in name resolution)

The above exception was the direct cause of the following exception:

Traceback (most recent call last):
  File "/home/arifin/envbot/lib/python3.12/site-packages/requests/adapters.py", line 667, in send
    resp = conn.urlopen(
           ^^^^^^^^^^^^^
  File "/home/arifin/envbot/lib/python3.12/site-packages/urllib3/connectionpool.py", line 841, in urlopen
    retries = retries.increment(
              ^^^^^^^^^^^^^^^^^^
  File "/home/arifin/envbot/lib/python3.12/site-packages/urllib3/util/retry.py", line 519, in increment
    raise MaxRetryError(_pool, url, reason) from reason  # type: ignore[arg-type]
    ^^^^^^^^^^^^^^^^^^^^^^^^^^^^^^^^^^^^^^^^^^^^^^^^^^^
urllib3.exceptions.MaxRetryError: HTTPConnectionPool(host='api.isportsapi.com', port=80): Max retries exceeded with url: /sport/football/livescores?api_key=VEM3L91m7eguSCla (Caused by NameResolutionError("<urllib3.connection.HTTPConnection object at 0x745a50ed3800>: Failed to resolve 'api.isportsapi.com' ([Errno -3] Temporary failure in name resolution)"))

During handling of the above exception, another exception occurred:

Traceback (most recent call last):
  File "/home/arifin/project/live_score/main.py", line 23, in <module>
    matches = fetch_matches()
              ^^^^^^^^^^^^^^^
  File "/home/arifin/project/live_score/main.py", line 17, in fetch_matches
    resp = requests.get(settings.NOWGOAL_API_URL, params=params)
           ^^^^^^^^^^^^^^^^^^^^^^^^^^^^^^^^^^^^^^^^^^^^^^^^^^^^^
  File "/home/arifin/envbot/lib/python3.12/site-packages/requests/api.py", line 73, in get
    return request("get", url, params=params, **kwargs)
           ^^^^^^^^^^^^^^^^^^^^^^^^^^^^^^^^^^^^^^^^^^^^
  File "/home/arifin/envbot/lib/python3.12/site-packages/requests/api.py", line 59, in request
    return session.request(method=method, url=url, **kwargs)
           ^^^^^^^^^^^^^^^^^^^^^^^^^^^^^^^^^^^^^^^^^^^^^^^^^
  File "/home/arifin/envbot/lib/python3.12/site-packages/requests/sessions.py", line 589, in request
    resp = self.send(prep, **send_kwargs)
           ^^^^^^^^^^^^^^^^^^^^^^^^^^^^^^
  File "/home/arifin/envbot/lib/python3.12/site-packages/requests/sessions.py", line 703, in send
    r = adapter.send(request, **kwargs)
        ^^^^^^^^^^^^^^^^^^^^^^^^^^^^^^^
  File "/home/arifin/envbot/lib/python3.12/site-packages/requests/adapters.py", line 700, in send
    raise ConnectionError(e, request=request)
requests.exceptions.ConnectionError: HTTPConnectionPool(host='api.isportsapi.com', port=80): Max retries exceeded with url: /sport/football/livescores?api_key=VEM3L91m7eguSCla (Caused by NameResolutionError("<urllib3.connection.HTTPConnection object at 0x745a50ed3800>: Failed to resolve 'api.isportsapi.com' ([Errno -3] Temporary failure in name resolution)"))
ðŸ“Š Total pertandingan: 293
ðŸŽ¯ Yang memenuhi syarat: 6
Traceback (most recent call last):
  File "/home/arifin/envbot/lib/python3.12/site-packages/httpx/_transports/default.py", line 101, in map_httpcore_exceptions
    yield
  File "/home/arifin/envbot/lib/python3.12/site-packages/httpx/_transports/default.py", line 250, in handle_request
    resp = self._pool.handle_request(req)
           ^^^^^^^^^^^^^^^^^^^^^^^^^^^^^^
  File "/home/arifin/envbot/lib/python3.12/site-packages/httpcore/_sync/connection_pool.py", line 256, in handle_request
    raise exc from None
  File "/home/arifin/envbot/lib/python3.12/site-packages/httpcore/_sync/connection_pool.py", line 236, in handle_request
    response = connection.handle_request(
               ^^^^^^^^^^^^^^^^^^^^^^^^^^
  File "/home/arifin/envbot/lib/python3.12/site-packages/httpcore/_sync/connection.py", line 101, in handle_request
    raise exc
  File "/home/arifin/envbot/lib/python3.12/site-packages/httpcore/_sync/connection.py", line 78, in handle_request
    stream = self._connect(request)
             ^^^^^^^^^^^^^^^^^^^^^^
  File "/home/arifin/envbot/lib/python3.12/site-packages/httpcore/_sync/connection.py", line 124, in _connect
    stream = self._network_backend.connect_tcp(**kwargs)
             ^^^^^^^^^^^^^^^^^^^^^^^^^^^^^^^^^^^^^^^^^^^
  File "/home/arifin/envbot/lib/python3.12/site-packages/httpcore/_backends/sync.py", line 207, in connect_tcp
    with map_exceptions(exc_map):
  File "/usr/lib/python3.12/contextlib.py", line 158, in __exit__
    self.gen.throw(value)
  File "/home/arifin/envbot/lib/python3.12/site-packages/httpcore/_exceptions.py", line 14, in map_exceptions
    raise to_exc(exc) from exc
httpcore.ConnectError: [Errno -3] Temporary failure in name resolution

The above exception was the direct cause of the following exception:

Traceback (most recent call last):
  File "/home/arifin/project/live_score/main.py", line 30, in <module>
    notify(match, reason)
  File "/home/arifin/project/live_score/notifier.py", line 68, in notify
    httpx.post(f"{API_URL}/sendMessage", json={
  File "/home/arifin/envbot/lib/python3.12/site-packages/httpx/_api.py", line 304, in post
    return request(
           ^^^^^^^^
  File "/home/arifin/envbot/lib/python3.12/site-packages/httpx/_api.py", line 109, in request
    return client.request(
           ^^^^^^^^^^^^^^^
  File "/home/arifin/envbot/lib/python3.12/site-packages/httpx/_client.py", line 825, in request
    return self.send(request, auth=auth, follow_redirects=follow_redirects)
           ^^^^^^^^^^^^^^^^^^^^^^^^^^^^^^^^^^^^^^^^^^^^^^^^^^^^^^^^^^^^^^^^
  File "/home/arifin/envbot/lib/python3.12/site-packages/httpx/_client.py", line 914, in send
    response = self._send_handling_auth(
               ^^^^^^^^^^^^^^^^^^^^^^^^^
  File "/home/arifin/envbot/lib/python3.12/site-packages/httpx/_client.py", line 942, in _send_handling_auth
    response = self._send_handling_redirects(
               ^^^^^^^^^^^^^^^^^^^^^^^^^^^^^^
  File "/home/arifin/envbot/lib/python3.12/site-packages/httpx/_client.py", line 979, in _send_handling_redirects
    response = self._send_single_request(request)
               ^^^^^^^^^^^^^^^^^^^^^^^^^^^^^^^^^^
  File "/home/arifin/envbot/lib/python3.12/site-packages/httpx/_client.py", line 1014, in _send_single_request
    response = transport.handle_request(request)
               ^^^^^^^^^^^^^^^^^^^^^^^^^^^^^^^^^
  File "/home/arifin/envbot/lib/python3.12/site-packages/httpx/_transports/default.py", line 249, in handle_request
    with map_httpcore_exceptions():
  File "/usr/lib/python3.12/contextlib.py", line 158, in __exit__
    self.gen.throw(value)
  File "/home/arifin/envbot/lib/python3.12/site-packages/httpx/_transports/default.py", line 118, in map_httpcore_exceptions
    raise mapped_exc(message) from exc
httpx.ConnectError: [Errno -3] Temporary failure in name resolution
ðŸ“Š Total pertandingan: 293
ðŸŽ¯ Yang memenuhi syarat: 6
Traceback (most recent call last):
  File "/home/arifin/envbot/lib/python3.12/site-packages/httpx/_transports/default.py", line 101, in map_httpcore_exceptions
    yield
  File "/home/arifin/envbot/lib/python3.12/site-packages/httpx/_transports/default.py", line 250, in handle_request
    resp = self._pool.handle_request(req)
           ^^^^^^^^^^^^^^^^^^^^^^^^^^^^^^
  File "/home/arifin/envbot/lib/python3.12/site-packages/httpcore/_sync/connection_pool.py", line 256, in handle_request
    raise exc from None
  File "/home/arifin/envbot/lib/python3.12/site-packages/httpcore/_sync/connection_pool.py", line 236, in handle_request
    response = connection.handle_request(
               ^^^^^^^^^^^^^^^^^^^^^^^^^^
  File "/home/arifin/envbot/lib/python3.12/site-packages/httpcore/_sync/connection.py", line 101, in handle_request
    raise exc
  File "/home/arifin/envbot/lib/python3.12/site-packages/httpcore/_sync/connection.py", line 78, in handle_request
    stream = self._connect(request)
             ^^^^^^^^^^^^^^^^^^^^^^
  File "/home/arifin/envbot/lib/python3.12/site-packages/httpcore/_sync/connection.py", line 124, in _connect
    stream = self._network_backend.connect_tcp(**kwargs)
             ^^^^^^^^^^^^^^^^^^^^^^^^^^^^^^^^^^^^^^^^^^^
  File "/home/arifin/envbot/lib/python3.12/site-packages/httpcore/_backends/sync.py", line 207, in connect_tcp
    with map_exceptions(exc_map):
  File "/usr/lib/python3.12/contextlib.py", line 158, in __exit__
    self.gen.throw(value)
  File "/home/arifin/envbot/lib/python3.12/site-packages/httpcore/_exceptions.py", line 14, in map_exceptions
    raise to_exc(exc) from exc
httpcore.ConnectError: [Errno -3] Temporary failure in name resolution

The above exception was the direct cause of the following exception:

Traceback (most recent call last):
  File "/home/arifin/project/live_score/main.py", line 30, in <module>
    notify(match, reason)
  File "/home/arifin/project/live_score/notifier.py", line 68, in notify
    httpx.post(f"{API_URL}/sendMessage", json={
  File "/home/arifin/envbot/lib/python3.12/site-packages/httpx/_api.py", line 304, in post
    return request(
           ^^^^^^^^
  File "/home/arifin/envbot/lib/python3.12/site-packages/httpx/_api.py", line 109, in request
    return client.request(
           ^^^^^^^^^^^^^^^
  File "/home/arifin/envbot/lib/python3.12/site-packages/httpx/_client.py", line 825, in request
    return self.send(request, auth=auth, follow_redirects=follow_redirects)
           ^^^^^^^^^^^^^^^^^^^^^^^^^^^^^^^^^^^^^^^^^^^^^^^^^^^^^^^^^^^^^^^^
  File "/home/arifin/envbot/lib/python3.12/site-packages/httpx/_client.py", line 914, in send
    response = self._send_handling_auth(
               ^^^^^^^^^^^^^^^^^^^^^^^^^
  File "/home/arifin/envbot/lib/python3.12/site-packages/httpx/_client.py", line 942, in _send_handling_auth
    response = self._send_handling_redirects(
               ^^^^^^^^^^^^^^^^^^^^^^^^^^^^^^
  File "/home/arifin/envbot/lib/python3.12/site-packages/httpx/_client.py", line 979, in _send_handling_redirects
    response = self._send_single_request(request)
               ^^^^^^^^^^^^^^^^^^^^^^^^^^^^^^^^^^
  File "/home/arifin/envbot/lib/python3.12/site-packages/httpx/_client.py", line 1014, in _send_single_request
    response = transport.handle_request(request)
               ^^^^^^^^^^^^^^^^^^^^^^^^^^^^^^^^^
  File "/home/arifin/envbot/lib/python3.12/site-packages/httpx/_transports/default.py", line 249, in handle_request
    with map_httpcore_exceptions():
  File "/usr/lib/python3.12/contextlib.py", line 158, in __exit__
    self.gen.throw(value)
  File "/home/arifin/envbot/lib/python3.12/site-packages/httpx/_transports/default.py", line 118, in map_httpcore_exceptions
    raise mapped_exc(message) from exc
httpx.ConnectError: [Errno -3] Temporary failure in name resolution
ðŸ“Š Total pertandingan: 293
ðŸŽ¯ Yang memenuhi syarat: 6
Traceback (most recent call last):
  File "/home/arifin/envbot/lib/python3.12/site-packages/httpx/_transports/default.py", line 101, in map_httpcore_exceptions
    yield
  File "/home/arifin/envbot/lib/python3.12/site-packages/httpx/_transports/default.py", line 250, in handle_request
    resp = self._pool.handle_request(req)
           ^^^^^^^^^^^^^^^^^^^^^^^^^^^^^^
  File "/home/arifin/envbot/lib/python3.12/site-packages/httpcore/_sync/connection_pool.py", line 256, in handle_request
    raise exc from None
  File "/home/arifin/envbot/lib/python3.12/site-packages/httpcore/_sync/connection_pool.py", line 236, in handle_request
    response = connection.handle_request(
               ^^^^^^^^^^^^^^^^^^^^^^^^^^
  File "/home/arifin/envbot/lib/python3.12/site-packages/httpcore/_sync/connection.py", line 101, in handle_request
    raise exc
  File "/home/arifin/envbot/lib/python3.12/site-packages/httpcore/_sync/connection.py", line 78, in handle_request
    stream = self._connect(request)
             ^^^^^^^^^^^^^^^^^^^^^^
  File "/home/arifin/envbot/lib/python3.12/site-packages/httpcore/_sync/connection.py", line 124, in _connect
    stream = self._network_backend.connect_tcp(**kwargs)
             ^^^^^^^^^^^^^^^^^^^^^^^^^^^^^^^^^^^^^^^^^^^
  File "/home/arifin/envbot/lib/python3.12/site-packages/httpcore/_backends/sync.py", line 207, in connect_tcp
    with map_exceptions(exc_map):
  File "/usr/lib/python3.12/contextlib.py", line 158, in __exit__
    self.gen.throw(value)
  File "/home/arifin/envbot/lib/python3.12/site-packages/httpcore/_exceptions.py", line 14, in map_exceptions
    raise to_exc(exc) from exc
httpcore.ConnectError: [Errno -3] Temporary failure in name resolution

The above exception was the direct cause of the following exception:

Traceback (most recent call last):
  File "/home/arifin/project/live_score/main.py", line 30, in <module>
    notify(match, reason)
  File "/home/arifin/project/live_score/notifier.py", line 68, in notify
    httpx.post(f"{API_URL}/sendMessage", json={
  File "/home/arifin/envbot/lib/python3.12/site-packages/httpx/_api.py", line 304, in post
    return request(
           ^^^^^^^^
  File "/home/arifin/envbot/lib/python3.12/site-packages/httpx/_api.py", line 109, in request
    return client.request(
           ^^^^^^^^^^^^^^^
  File "/home/arifin/envbot/lib/python3.12/site-packages/httpx/_client.py", line 825, in request
    return self.send(request, auth=auth, follow_redirects=follow_redirects)
           ^^^^^^^^^^^^^^^^^^^^^^^^^^^^^^^^^^^^^^^^^^^^^^^^^^^^^^^^^^^^^^^^
  File "/home/arifin/envbot/lib/python3.12/site-packages/httpx/_client.py", line 914, in send
    response = self._send_handling_auth(
               ^^^^^^^^^^^^^^^^^^^^^^^^^
  File "/home/arifin/envbot/lib/python3.12/site-packages/httpx/_client.py", line 942, in _send_handling_auth
    response = self._send_handling_redirects(
               ^^^^^^^^^^^^^^^^^^^^^^^^^^^^^^
  File "/home/arifin/envbot/lib/python3.12/site-packages/httpx/_client.py", line 979, in _send_handling_redirects
    response = self._send_single_request(request)
               ^^^^^^^^^^^^^^^^^^^^^^^^^^^^^^^^^^
  File "/home/arifin/envbot/lib/python3.12/site-packages/httpx/_client.py", line 1014, in _send_single_request
    response = transport.handle_request(request)
               ^^^^^^^^^^^^^^^^^^^^^^^^^^^^^^^^^
  File "/home/arifin/envbot/lib/python3.12/site-packages/httpx/_transports/default.py", line 249, in handle_request
    with map_httpcore_exceptions():
  File "/usr/lib/python3.12/contextlib.py", line 158, in __exit__
    self.gen.throw(value)
  File "/home/arifin/envbot/lib/python3.12/site-packages/httpx/_transports/default.py", line 118, in map_httpcore_exceptions
    raise mapped_exc(message) from exc
httpx.ConnectError: [Errno -3] Temporary failure in name resolution
ðŸ“Š Total pertandingan: 293
ðŸŽ¯ Yang memenuhi syarat: 6
Traceback (most recent call last):
  File "/home/arifin/envbot/lib/python3.12/site-packages/httpx/_transports/default.py", line 101, in map_httpcore_exceptions
    yield
  File "/home/arifin/envbot/lib/python3.12/site-packages/httpx/_transports/default.py", line 250, in handle_request
    resp = self._pool.handle_request(req)
           ^^^^^^^^^^^^^^^^^^^^^^^^^^^^^^
  File "/home/arifin/envbot/lib/python3.12/site-packages/httpcore/_sync/connection_pool.py", line 256, in handle_request
    raise exc from None
  File "/home/arifin/envbot/lib/python3.12/site-packages/httpcore/_sync/connection_pool.py", line 236, in handle_request
    response = connection.handle_request(
               ^^^^^^^^^^^^^^^^^^^^^^^^^^
  File "/home/arifin/envbot/lib/python3.12/site-packages/httpcore/_sync/connection.py", line 101, in handle_request
    raise exc
  File "/home/arifin/envbot/lib/python3.12/site-packages/httpcore/_sync/connection.py", line 78, in handle_request
    stream = self._connect(request)
             ^^^^^^^^^^^^^^^^^^^^^^
  File "/home/arifin/envbot/lib/python3.12/site-packages/httpcore/_sync/connection.py", line 124, in _connect
    stream = self._network_backend.connect_tcp(**kwargs)
             ^^^^^^^^^^^^^^^^^^^^^^^^^^^^^^^^^^^^^^^^^^^
  File "/home/arifin/envbot/lib/python3.12/site-packages/httpcore/_backends/sync.py", line 207, in connect_tcp
    with map_exceptions(exc_map):
  File "/usr/lib/python3.12/contextlib.py", line 158, in __exit__
    self.gen.throw(value)
  File "/home/arifin/envbot/lib/python3.12/site-packages/httpcore/_exceptions.py", line 14, in map_exceptions
    raise to_exc(exc) from exc
httpcore.ConnectError: [Errno -3] Temporary failure in name resolution

The above exception was the direct cause of the following exception:

Traceback (most recent call last):
  File "/home/arifin/project/live_score/main.py", line 30, in <module>
    notify(match, reason)
  File "/home/arifin/project/live_score/notifier.py", line 68, in notify
    httpx.post(f"{API_URL}/sendMessage", json={
  File "/home/arifin/envbot/lib/python3.12/site-packages/httpx/_api.py", line 304, in post
    return request(
           ^^^^^^^^
  File "/home/arifin/envbot/lib/python3.12/site-packages/httpx/_api.py", line 109, in request
    return client.request(
           ^^^^^^^^^^^^^^^
  File "/home/arifin/envbot/lib/python3.12/site-packages/httpx/_client.py", line 825, in request
    return self.send(request, auth=auth, follow_redirects=follow_redirects)
           ^^^^^^^^^^^^^^^^^^^^^^^^^^^^^^^^^^^^^^^^^^^^^^^^^^^^^^^^^^^^^^^^
  File "/home/arifin/envbot/lib/python3.12/site-packages/httpx/_client.py", line 914, in send
    response = self._send_handling_auth(
               ^^^^^^^^^^^^^^^^^^^^^^^^^
  File "/home/arifin/envbot/lib/python3.12/site-packages/httpx/_client.py", line 942, in _send_handling_auth
    response = self._send_handling_redirects(
               ^^^^^^^^^^^^^^^^^^^^^^^^^^^^^^
  File "/home/arifin/envbot/lib/python3.12/site-packages/httpx/_client.py", line 979, in _send_handling_redirects
    response = self._send_single_request(request)
               ^^^^^^^^^^^^^^^^^^^^^^^^^^^^^^^^^^
  File "/home/arifin/envbot/lib/python3.12/site-packages/httpx/_client.py", line 1014, in _send_single_request
    response = transport.handle_request(request)
               ^^^^^^^^^^^^^^^^^^^^^^^^^^^^^^^^^
  File "/home/arifin/envbot/lib/python3.12/site-packages/httpx/_transports/default.py", line 249, in handle_request
    with map_httpcore_exceptions():
  File "/usr/lib/python3.12/contextlib.py", line 158, in __exit__
    self.gen.throw(value)
  File "/home/arifin/envbot/lib/python3.12/site-packages/httpx/_transports/default.py", line 118, in map_httpcore_exceptions
    raise mapped_exc(message) from exc
httpx.ConnectError: [Errno -3] Temporary failure in name resolution
ðŸ“Š Total pertandingan: 293
ðŸŽ¯ Yang memenuhi syarat: 6
Traceback (most recent call last):
  File "/home/arifin/envbot/lib/python3.12/site-packages/httpx/_transports/default.py", line 101, in map_httpcore_exceptions
    yield
  File "/home/arifin/envbot/lib/python3.12/site-packages/httpx/_transports/default.py", line 250, in handle_request
    resp = self._pool.handle_request(req)
           ^^^^^^^^^^^^^^^^^^^^^^^^^^^^^^
  File "/home/arifin/envbot/lib/python3.12/site-packages/httpcore/_sync/connection_pool.py", line 256, in handle_request
    raise exc from None
  File "/home/arifin/envbot/lib/python3.12/site-packages/httpcore/_sync/connection_pool.py", line 236, in handle_request
    response = connection.handle_request(
               ^^^^^^^^^^^^^^^^^^^^^^^^^^
  File "/home/arifin/envbot/lib/python3.12/site-packages/httpcore/_sync/connection.py", line 101, in handle_request
    raise exc
  File "/home/arifin/envbot/lib/python3.12/site-packages/httpcore/_sync/connection.py", line 78, in handle_request
    stream = self._connect(request)
             ^^^^^^^^^^^^^^^^^^^^^^
  File "/home/arifin/envbot/lib/python3.12/site-packages/httpcore/_sync/connection.py", line 124, in _connect
    stream = self._network_backend.connect_tcp(**kwargs)
             ^^^^^^^^^^^^^^^^^^^^^^^^^^^^^^^^^^^^^^^^^^^
  File "/home/arifin/envbot/lib/python3.12/site-packages/httpcore/_backends/sync.py", line 207, in connect_tcp
    with map_exceptions(exc_map):
  File "/usr/lib/python3.12/contextlib.py", line 158, in __exit__
    self.gen.throw(value)
  File "/home/arifin/envbot/lib/python3.12/site-packages/httpcore/_exceptions.py", line 14, in map_exceptions
    raise to_exc(exc) from exc
httpcore.ConnectError: [Errno -3] Temporary failure in name resolution

The above exception was the direct cause of the following exception:

Traceback (most recent call last):
  File "/home/arifin/project/live_score/main.py", line 30, in <module>
    notify(match, reason)
  File "/home/arifin/project/live_score/notifier.py", line 68, in notify
    httpx.post(f"{API_URL}/sendMessage", json={
  File "/home/arifin/envbot/lib/python3.12/site-packages/httpx/_api.py", line 304, in post
    return request(
           ^^^^^^^^
  File "/home/arifin/envbot/lib/python3.12/site-packages/httpx/_api.py", line 109, in request
    return client.request(
           ^^^^^^^^^^^^^^^
  File "/home/arifin/envbot/lib/python3.12/site-packages/httpx/_client.py", line 825, in request
    return self.send(request, auth=auth, follow_redirects=follow_redirects)
           ^^^^^^^^^^^^^^^^^^^^^^^^^^^^^^^^^^^^^^^^^^^^^^^^^^^^^^^^^^^^^^^^
  File "/home/arifin/envbot/lib/python3.12/site-packages/httpx/_client.py", line 914, in send
    response = self._send_handling_auth(
               ^^^^^^^^^^^^^^^^^^^^^^^^^
  File "/home/arifin/envbot/lib/python3.12/site-packages/httpx/_client.py", line 942, in _send_handling_auth
    response = self._send_handling_redirects(
               ^^^^^^^^^^^^^^^^^^^^^^^^^^^^^^
  File "/home/arifin/envbot/lib/python3.12/site-packages/httpx/_client.py", line 979, in _send_handling_redirects
    response = self._send_single_request(request)
               ^^^^^^^^^^^^^^^^^^^^^^^^^^^^^^^^^^
  File "/home/arifin/envbot/lib/python3.12/site-packages/httpx/_client.py", line 1014, in _send_single_request
    response = transport.handle_request(request)
               ^^^^^^^^^^^^^^^^^^^^^^^^^^^^^^^^^
  File "/home/arifin/envbot/lib/python3.12/site-packages/httpx/_transports/default.py", line 249, in handle_request
    with map_httpcore_exceptions():
  File "/usr/lib/python3.12/contextlib.py", line 158, in __exit__
    self.gen.throw(value)
  File "/home/arifin/envbot/lib/python3.12/site-packages/httpx/_transports/default.py", line 118, in map_httpcore_exceptions
    raise mapped_exc(message) from exc
httpx.ConnectError: [Errno -3] Temporary failure in name resolution
ðŸ“Š Total pertandingan: 293
ðŸŽ¯ Yang memenuhi syarat: 6
Traceback (most recent call last):
  File "/home/arifin/envbot/lib/python3.12/site-packages/httpx/_transports/default.py", line 101, in map_httpcore_exceptions
    yield
  File "/home/arifin/envbot/lib/python3.12/site-packages/httpx/_transports/default.py", line 250, in handle_request
    resp = self._pool.handle_request(req)
           ^^^^^^^^^^^^^^^^^^^^^^^^^^^^^^
  File "/home/arifin/envbot/lib/python3.12/site-packages/httpcore/_sync/connection_pool.py", line 256, in handle_request
    raise exc from None
  File "/home/arifin/envbot/lib/python3.12/site-packages/httpcore/_sync/connection_pool.py", line 236, in handle_request
    response = connection.handle_request(
               ^^^^^^^^^^^^^^^^^^^^^^^^^^
  File "/home/arifin/envbot/lib/python3.12/site-packages/httpcore/_sync/connection.py", line 101, in handle_request
    raise exc
  File "/home/arifin/envbot/lib/python3.12/site-packages/httpcore/_sync/connection.py", line 78, in handle_request
    stream = self._connect(request)
             ^^^^^^^^^^^^^^^^^^^^^^
  File "/home/arifin/envbot/lib/python3.12/site-packages/httpcore/_sync/connection.py", line 124, in _connect
    stream = self._network_backend.connect_tcp(**kwargs)
             ^^^^^^^^^^^^^^^^^^^^^^^^^^^^^^^^^^^^^^^^^^^
  File "/home/arifin/envbot/lib/python3.12/site-packages/httpcore/_backends/sync.py", line 207, in connect_tcp
    with map_exceptions(exc_map):
  File "/usr/lib/python3.12/contextlib.py", line 158, in __exit__
    self.gen.throw(value)
  File "/home/arifin/envbot/lib/python3.12/site-packages/httpcore/_exceptions.py", line 14, in map_exceptions
    raise to_exc(exc) from exc
httpcore.ConnectError: [Errno -3] Temporary failure in name resolution

The above exception was the direct cause of the following exception:

Traceback (most recent call last):
  File "/home/arifin/project/live_score/main.py", line 30, in <module>
    notify(match, reason)
  File "/home/arifin/project/live_score/notifier.py", line 68, in notify
    httpx.post(f"{API_URL}/sendMessage", json={
  File "/home/arifin/envbot/lib/python3.12/site-packages/httpx/_api.py", line 304, in post
    return request(
           ^^^^^^^^
  File "/home/arifin/envbot/lib/python3.12/site-packages/httpx/_api.py", line 109, in request
    return client.request(
           ^^^^^^^^^^^^^^^
  File "/home/arifin/envbot/lib/python3.12/site-packages/httpx/_client.py", line 825, in request
    return self.send(request, auth=auth, follow_redirects=follow_redirects)
           ^^^^^^^^^^^^^^^^^^^^^^^^^^^^^^^^^^^^^^^^^^^^^^^^^^^^^^^^^^^^^^^^
  File "/home/arifin/envbot/lib/python3.12/site-packages/httpx/_client.py", line 914, in send
    response = self._send_handling_auth(
               ^^^^^^^^^^^^^^^^^^^^^^^^^
  File "/home/arifin/envbot/lib/python3.12/site-packages/httpx/_client.py", line 942, in _send_handling_auth
    response = self._send_handling_redirects(
               ^^^^^^^^^^^^^^^^^^^^^^^^^^^^^^
  File "/home/arifin/envbot/lib/python3.12/site-packages/httpx/_client.py", line 979, in _send_handling_redirects
    response = self._send_single_request(request)
               ^^^^^^^^^^^^^^^^^^^^^^^^^^^^^^^^^^
  File "/home/arifin/envbot/lib/python3.12/site-packages/httpx/_client.py", line 1014, in _send_single_request
    response = transport.handle_request(request)
               ^^^^^^^^^^^^^^^^^^^^^^^^^^^^^^^^^
  File "/home/arifin/envbot/lib/python3.12/site-packages/httpx/_transports/default.py", line 249, in handle_request
    with map_httpcore_exceptions():
  File "/usr/lib/python3.12/contextlib.py", line 158, in __exit__
    self.gen.throw(value)
  File "/home/arifin/envbot/lib/python3.12/site-packages/httpx/_transports/default.py", line 118, in map_httpcore_exceptions
    raise mapped_exc(message) from exc
httpx.ConnectError: [Errno -3] Temporary failure in name resolution
ðŸ“Š Total pertandingan: 293
ðŸŽ¯ Yang memenuhi syarat: 6
Traceback (most recent call last):
  File "/home/arifin/envbot/lib/python3.12/site-packages/httpx/_transports/default.py", line 101, in map_httpcore_exceptions
    yield
  File "/home/arifin/envbot/lib/python3.12/site-packages/httpx/_transports/default.py", line 250, in handle_request
    resp = self._pool.handle_request(req)
           ^^^^^^^^^^^^^^^^^^^^^^^^^^^^^^
  File "/home/arifin/envbot/lib/python3.12/site-packages/httpcore/_sync/connection_pool.py", line 256, in handle_request
    raise exc from None
  File "/home/arifin/envbot/lib/python3.12/site-packages/httpcore/_sync/connection_pool.py", line 236, in handle_request
    response = connection.handle_request(
               ^^^^^^^^^^^^^^^^^^^^^^^^^^
  File "/home/arifin/envbot/lib/python3.12/site-packages/httpcore/_sync/connection.py", line 101, in handle_request
    raise exc
  File "/home/arifin/envbot/lib/python3.12/site-packages/httpcore/_sync/connection.py", line 78, in handle_request
    stream = self._connect(request)
             ^^^^^^^^^^^^^^^^^^^^^^
  File "/home/arifin/envbot/lib/python3.12/site-packages/httpcore/_sync/connection.py", line 124, in _connect
    stream = self._network_backend.connect_tcp(**kwargs)
             ^^^^^^^^^^^^^^^^^^^^^^^^^^^^^^^^^^^^^^^^^^^
  File "/home/arifin/envbot/lib/python3.12/site-packages/httpcore/_backends/sync.py", line 207, in connect_tcp
    with map_exceptions(exc_map):
  File "/usr/lib/python3.12/contextlib.py", line 158, in __exit__
    self.gen.throw(value)
  File "/home/arifin/envbot/lib/python3.12/site-packages/httpcore/_exceptions.py", line 14, in map_exceptions
    raise to_exc(exc) from exc
httpcore.ConnectError: [Errno -3] Temporary failure in name resolution

The above exception was the direct cause of the following exception:

Traceback (most recent call last):
  File "/home/arifin/project/live_score/main.py", line 30, in <module>
    notify(match, reason)
  File "/home/arifin/project/live_score/notifier.py", line 68, in notify
    httpx.post(f"{API_URL}/sendMessage", json={
  File "/home/arifin/envbot/lib/python3.12/site-packages/httpx/_api.py", line 304, in post
    return request(
           ^^^^^^^^
  File "/home/arifin/envbot/lib/python3.12/site-packages/httpx/_api.py", line 109, in request
    return client.request(
           ^^^^^^^^^^^^^^^
  File "/home/arifin/envbot/lib/python3.12/site-packages/httpx/_client.py", line 825, in request
    return self.send(request, auth=auth, follow_redirects=follow_redirects)
           ^^^^^^^^^^^^^^^^^^^^^^^^^^^^^^^^^^^^^^^^^^^^^^^^^^^^^^^^^^^^^^^^
  File "/home/arifin/envbot/lib/python3.12/site-packages/httpx/_client.py", line 914, in send
    response = self._send_handling_auth(
               ^^^^^^^^^^^^^^^^^^^^^^^^^
  File "/home/arifin/envbot/lib/python3.12/site-packages/httpx/_client.py", line 942, in _send_handling_auth
    response = self._send_handling_redirects(
               ^^^^^^^^^^^^^^^^^^^^^^^^^^^^^^
  File "/home/arifin/envbot/lib/python3.12/site-packages/httpx/_client.py", line 979, in _send_handling_redirects
    response = self._send_single_request(request)
               ^^^^^^^^^^^^^^^^^^^^^^^^^^^^^^^^^^
  File "/home/arifin/envbot/lib/python3.12/site-packages/httpx/_client.py", line 1014, in _send_single_request
    response = transport.handle_request(request)
               ^^^^^^^^^^^^^^^^^^^^^^^^^^^^^^^^^
  File "/home/arifin/envbot/lib/python3.12/site-packages/httpx/_transports/default.py", line 249, in handle_request
    with map_httpcore_exceptions():
  File "/usr/lib/python3.12/contextlib.py", line 158, in __exit__
    self.gen.throw(value)
  File "/home/arifin/envbot/lib/python3.12/site-packages/httpx/_transports/default.py", line 118, in map_httpcore_exceptions
    raise mapped_exc(message) from exc
httpx.ConnectError: [Errno -3] Temporary failure in name resolution
ðŸ“Š Total pertandingan: 293
ðŸŽ¯ Yang memenuhi syarat: 6
Traceback (most recent call last):
  File "/home/arifin/envbot/lib/python3.12/site-packages/httpx/_transports/default.py", line 101, in map_httpcore_exceptions
    yield
  File "/home/arifin/envbot/lib/python3.12/site-packages/httpx/_transports/default.py", line 250, in handle_request
    resp = self._pool.handle_request(req)
           ^^^^^^^^^^^^^^^^^^^^^^^^^^^^^^
  File "/home/arifin/envbot/lib/python3.12/site-packages/httpcore/_sync/connection_pool.py", line 256, in handle_request
    raise exc from None
  File "/home/arifin/envbot/lib/python3.12/site-packages/httpcore/_sync/connection_pool.py", line 236, in handle_request
    response = connection.handle_request(
               ^^^^^^^^^^^^^^^^^^^^^^^^^^
  File "/home/arifin/envbot/lib/python3.12/site-packages/httpcore/_sync/connection.py", line 101, in handle_request
    raise exc
  File "/home/arifin/envbot/lib/python3.12/site-packages/httpcore/_sync/connection.py", line 78, in handle_request
    stream = self._connect(request)
             ^^^^^^^^^^^^^^^^^^^^^^
  File "/home/arifin/envbot/lib/python3.12/site-packages/httpcore/_sync/connection.py", line 124, in _connect
    stream = self._network_backend.connect_tcp(**kwargs)
             ^^^^^^^^^^^^^^^^^^^^^^^^^^^^^^^^^^^^^^^^^^^
  File "/home/arifin/envbot/lib/python3.12/site-packages/httpcore/_backends/sync.py", line 207, in connect_tcp
    with map_exceptions(exc_map):
  File "/usr/lib/python3.12/contextlib.py", line 158, in __exit__
    self.gen.throw(value)
  File "/home/arifin/envbot/lib/python3.12/site-packages/httpcore/_exceptions.py", line 14, in map_exceptions
    raise to_exc(exc) from exc
httpcore.ConnectError: [Errno -3] Temporary failure in name resolution

The above exception was the direct cause of the following exception:

Traceback (most recent call last):
  File "/home/arifin/project/live_score/main.py", line 30, in <module>
    notify(match, reason)
  File "/home/arifin/project/live_score/notifier.py", line 68, in notify
    httpx.post(f"{API_URL}/sendMessage", json={
  File "/home/arifin/envbot/lib/python3.12/site-packages/httpx/_api.py", line 304, in post
    return request(
           ^^^^^^^^
  File "/home/arifin/envbot/lib/python3.12/site-packages/httpx/_api.py", line 109, in request
    return client.request(
           ^^^^^^^^^^^^^^^
  File "/home/arifin/envbot/lib/python3.12/site-packages/httpx/_client.py", line 825, in request
    return self.send(request, auth=auth, follow_redirects=follow_redirects)
           ^^^^^^^^^^^^^^^^^^^^^^^^^^^^^^^^^^^^^^^^^^^^^^^^^^^^^^^^^^^^^^^^
  File "/home/arifin/envbot/lib/python3.12/site-packages/httpx/_client.py", line 914, in send
    response = self._send_handling_auth(
               ^^^^^^^^^^^^^^^^^^^^^^^^^
  File "/home/arifin/envbot/lib/python3.12/site-packages/httpx/_client.py", line 942, in _send_handling_auth
    response = self._send_handling_redirects(
               ^^^^^^^^^^^^^^^^^^^^^^^^^^^^^^
  File "/home/arifin/envbot/lib/python3.12/site-packages/httpx/_client.py", line 979, in _send_handling_redirects
    response = self._send_single_request(request)
               ^^^^^^^^^^^^^^^^^^^^^^^^^^^^^^^^^^
  File "/home/arifin/envbot/lib/python3.12/site-packages/httpx/_client.py", line 1014, in _send_single_request
    response = transport.handle_request(request)
               ^^^^^^^^^^^^^^^^^^^^^^^^^^^^^^^^^
  File "/home/arifin/envbot/lib/python3.12/site-packages/httpx/_transports/default.py", line 249, in handle_request
    with map_httpcore_exceptions():
  File "/usr/lib/python3.12/contextlib.py", line 158, in __exit__
    self.gen.throw(value)
  File "/home/arifin/envbot/lib/python3.12/site-packages/httpx/_transports/default.py", line 118, in map_httpcore_exceptions
    raise mapped_exc(message) from exc
httpx.ConnectError: [Errno -3] Temporary failure in name resolution
ðŸ“Š Total pertandingan: 293
ðŸŽ¯ Yang memenuhi syarat: 6
Traceback (most recent call last):
  File "/home/arifin/envbot/lib/python3.12/site-packages/httpx/_transports/default.py", line 101, in map_httpcore_exceptions
    yield
  File "/home/arifin/envbot/lib/python3.12/site-packages/httpx/_transports/default.py", line 250, in handle_request
    resp = self._pool.handle_request(req)
           ^^^^^^^^^^^^^^^^^^^^^^^^^^^^^^
  File "/home/arifin/envbot/lib/python3.12/site-packages/httpcore/_sync/connection_pool.py", line 256, in handle_request
    raise exc from None
  File "/home/arifin/envbot/lib/python3.12/site-packages/httpcore/_sync/connection_pool.py", line 236, in handle_request
    response = connection.handle_request(
               ^^^^^^^^^^^^^^^^^^^^^^^^^^
  File "/home/arifin/envbot/lib/python3.12/site-packages/httpcore/_sync/connection.py", line 101, in handle_request
    raise exc
  File "/home/arifin/envbot/lib/python3.12/site-packages/httpcore/_sync/connection.py", line 78, in handle_request
    stream = self._connect(request)
             ^^^^^^^^^^^^^^^^^^^^^^
  File "/home/arifin/envbot/lib/python3.12/site-packages/httpcore/_sync/connection.py", line 124, in _connect
    stream = self._network_backend.connect_tcp(**kwargs)
             ^^^^^^^^^^^^^^^^^^^^^^^^^^^^^^^^^^^^^^^^^^^
  File "/home/arifin/envbot/lib/python3.12/site-packages/httpcore/_backends/sync.py", line 207, in connect_tcp
    with map_exceptions(exc_map):
  File "/usr/lib/python3.12/contextlib.py", line 158, in __exit__
    self.gen.throw(value)
  File "/home/arifin/envbot/lib/python3.12/site-packages/httpcore/_exceptions.py", line 14, in map_exceptions
    raise to_exc(exc) from exc
httpcore.ConnectError: [Errno -3] Temporary failure in name resolution

The above exception was the direct cause of the following exception:

Traceback (most recent call last):
  File "/home/arifin/project/live_score/main.py", line 30, in <module>
    notify(match, reason)
  File "/home/arifin/project/live_score/notifier.py", line 68, in notify
    httpx.post(f"{API_URL}/sendMessage", json={
  File "/home/arifin/envbot/lib/python3.12/site-packages/httpx/_api.py", line 304, in post
    return request(
           ^^^^^^^^
  File "/home/arifin/envbot/lib/python3.12/site-packages/httpx/_api.py", line 109, in request
    return client.request(
           ^^^^^^^^^^^^^^^
  File "/home/arifin/envbot/lib/python3.12/site-packages/httpx/_client.py", line 825, in request
    return self.send(request, auth=auth, follow_redirects=follow_redirects)
           ^^^^^^^^^^^^^^^^^^^^^^^^^^^^^^^^^^^^^^^^^^^^^^^^^^^^^^^^^^^^^^^^
  File "/home/arifin/envbot/lib/python3.12/site-packages/httpx/_client.py", line 914, in send
    response = self._send_handling_auth(
               ^^^^^^^^^^^^^^^^^^^^^^^^^
  File "/home/arifin/envbot/lib/python3.12/site-packages/httpx/_client.py", line 942, in _send_handling_auth
    response = self._send_handling_redirects(
               ^^^^^^^^^^^^^^^^^^^^^^^^^^^^^^
  File "/home/arifin/envbot/lib/python3.12/site-packages/httpx/_client.py", line 979, in _send_handling_redirects
    response = self._send_single_request(request)
               ^^^^^^^^^^^^^^^^^^^^^^^^^^^^^^^^^^
  File "/home/arifin/envbot/lib/python3.12/site-packages/httpx/_client.py", line 1014, in _send_single_request
    response = transport.handle_request(request)
               ^^^^^^^^^^^^^^^^^^^^^^^^^^^^^^^^^
  File "/home/arifin/envbot/lib/python3.12/site-packages/httpx/_transports/default.py", line 249, in handle_request
    with map_httpcore_exceptions():
  File "/usr/lib/python3.12/contextlib.py", line 158, in __exit__
    self.gen.throw(value)
  File "/home/arifin/envbot/lib/python3.12/site-packages/httpx/_transports/default.py", line 118, in map_httpcore_exceptions
    raise mapped_exc(message) from exc
httpx.ConnectError: [Errno -3] Temporary failure in name resolution
ðŸ“Š Total pertandingan: 293
ðŸŽ¯ Yang memenuhi syarat: 6
Traceback (most recent call last):
  File "/home/arifin/envbot/lib/python3.12/site-packages/httpx/_transports/default.py", line 101, in map_httpcore_exceptions
    yield
  File "/home/arifin/envbot/lib/python3.12/site-packages/httpx/_transports/default.py", line 250, in handle_request
    resp = self._pool.handle_request(req)
           ^^^^^^^^^^^^^^^^^^^^^^^^^^^^^^
  File "/home/arifin/envbot/lib/python3.12/site-packages/httpcore/_sync/connection_pool.py", line 256, in handle_request
    raise exc from None
  File "/home/arifin/envbot/lib/python3.12/site-packages/httpcore/_sync/connection_pool.py", line 236, in handle_request
    response = connection.handle_request(
               ^^^^^^^^^^^^^^^^^^^^^^^^^^
  File "/home/arifin/envbot/lib/python3.12/site-packages/httpcore/_sync/connection.py", line 101, in handle_request
    raise exc
  File "/home/arifin/envbot/lib/python3.12/site-packages/httpcore/_sync/connection.py", line 78, in handle_request
    stream = self._connect(request)
             ^^^^^^^^^^^^^^^^^^^^^^
  File "/home/arifin/envbot/lib/python3.12/site-packages/httpcore/_sync/connection.py", line 124, in _connect
    stream = self._network_backend.connect_tcp(**kwargs)
             ^^^^^^^^^^^^^^^^^^^^^^^^^^^^^^^^^^^^^^^^^^^
  File "/home/arifin/envbot/lib/python3.12/site-packages/httpcore/_backends/sync.py", line 207, in connect_tcp
    with map_exceptions(exc_map):
  File "/usr/lib/python3.12/contextlib.py", line 158, in __exit__
    self.gen.throw(value)
  File "/home/arifin/envbot/lib/python3.12/site-packages/httpcore/_exceptions.py", line 14, in map_exceptions
    raise to_exc(exc) from exc
httpcore.ConnectError: [Errno -3] Temporary failure in name resolution

The above exception was the direct cause of the following exception:

Traceback (most recent call last):
  File "/home/arifin/project/live_score/main.py", line 30, in <module>
    notify(match, reason)
  File "/home/arifin/project/live_score/notifier.py", line 68, in notify
    httpx.post(f"{API_URL}/sendMessage", json={
  File "/home/arifin/envbot/lib/python3.12/site-packages/httpx/_api.py", line 304, in post
    return request(
           ^^^^^^^^
  File "/home/arifin/envbot/lib/python3.12/site-packages/httpx/_api.py", line 109, in request
    return client.request(
           ^^^^^^^^^^^^^^^
  File "/home/arifin/envbot/lib/python3.12/site-packages/httpx/_client.py", line 825, in request
    return self.send(request, auth=auth, follow_redirects=follow_redirects)
           ^^^^^^^^^^^^^^^^^^^^^^^^^^^^^^^^^^^^^^^^^^^^^^^^^^^^^^^^^^^^^^^^
  File "/home/arifin/envbot/lib/python3.12/site-packages/httpx/_client.py", line 914, in send
    response = self._send_handling_auth(
               ^^^^^^^^^^^^^^^^^^^^^^^^^
  File "/home/arifin/envbot/lib/python3.12/site-packages/httpx/_client.py", line 942, in _send_handling_auth
    response = self._send_handling_redirects(
               ^^^^^^^^^^^^^^^^^^^^^^^^^^^^^^
  File "/home/arifin/envbot/lib/python3.12/site-packages/httpx/_client.py", line 979, in _send_handling_redirects
    response = self._send_single_request(request)
               ^^^^^^^^^^^^^^^^^^^^^^^^^^^^^^^^^^
  File "/home/arifin/envbot/lib/python3.12/site-packages/httpx/_client.py", line 1014, in _send_single_request
    response = transport.handle_request(request)
               ^^^^^^^^^^^^^^^^^^^^^^^^^^^^^^^^^
  File "/home/arifin/envbot/lib/python3.12/site-packages/httpx/_transports/default.py", line 249, in handle_request
    with map_httpcore_exceptions():
  File "/usr/lib/python3.12/contextlib.py", line 158, in __exit__
    self.gen.throw(value)
  File "/home/arifin/envbot/lib/python3.12/site-packages/httpx/_transports/default.py", line 118, in map_httpcore_exceptions
    raise mapped_exc(message) from exc
httpx.ConnectError: [Errno -3] Temporary failure in name resolution
Traceback (most recent call last):
  File "/home/arifin/envbot/lib/python3.12/site-packages/urllib3/connection.py", line 198, in _new_conn
    sock = connection.create_connection(
           ^^^^^^^^^^^^^^^^^^^^^^^^^^^^^
  File "/home/arifin/envbot/lib/python3.12/site-packages/urllib3/util/connection.py", line 60, in create_connection
    for res in socket.getaddrinfo(host, port, family, socket.SOCK_STREAM):
               ^^^^^^^^^^^^^^^^^^^^^^^^^^^^^^^^^^^^^^^^^^^^^^^^^^^^^^^^^^
  File "/usr/lib/python3.12/socket.py", line 963, in getaddrinfo
    for res in _socket.getaddrinfo(host, port, family, type, proto, flags):
               ^^^^^^^^^^^^^^^^^^^^^^^^^^^^^^^^^^^^^^^^^^^^^^^^^^^^^^^^^^^
socket.gaierror: [Errno -3] Temporary failure in name resolution

The above exception was the direct cause of the following exception:

Traceback (most recent call last):
  File "/home/arifin/envbot/lib/python3.12/site-packages/urllib3/connectionpool.py", line 787, in urlopen
    response = self._make_request(
               ^^^^^^^^^^^^^^^^^^^
  File "/home/arifin/envbot/lib/python3.12/site-packages/urllib3/connectionpool.py", line 493, in _make_request
    conn.request(
  File "/home/arifin/envbot/lib/python3.12/site-packages/urllib3/connection.py", line 494, in request
    self.endheaders()
  File "/usr/lib/python3.12/http/client.py", line 1331, in endheaders
    self._send_output(message_body, encode_chunked=encode_chunked)
  File "/usr/lib/python3.12/http/client.py", line 1091, in _send_output
    self.send(msg)
  File "/usr/lib/python3.12/http/client.py", line 1035, in send
    self.connect()
  File "/home/arifin/envbot/lib/python3.12/site-packages/urllib3/connection.py", line 325, in connect
    self.sock = self._new_conn()
                ^^^^^^^^^^^^^^^^
  File "/home/arifin/envbot/lib/python3.12/site-packages/urllib3/connection.py", line 205, in _new_conn
    raise NameResolutionError(self.host, self, e) from e
urllib3.exceptions.NameResolutionError: <urllib3.connection.HTTPConnection object at 0x72140022eba0>: Failed to resolve 'api.isportsapi.com' ([Errno -3] Temporary failure in name resolution)

The above exception was the direct cause of the following exception:

Traceback (most recent call last):
  File "/home/arifin/envbot/lib/python3.12/site-packages/requests/adapters.py", line 667, in send
    resp = conn.urlopen(
           ^^^^^^^^^^^^^
  File "/home/arifin/envbot/lib/python3.12/site-packages/urllib3/connectionpool.py", line 841, in urlopen
    retries = retries.increment(
              ^^^^^^^^^^^^^^^^^^
  File "/home/arifin/envbot/lib/python3.12/site-packages/urllib3/util/retry.py", line 519, in increment
    raise MaxRetryError(_pool, url, reason) from reason  # type: ignore[arg-type]
    ^^^^^^^^^^^^^^^^^^^^^^^^^^^^^^^^^^^^^^^^^^^^^^^^^^^
urllib3.exceptions.MaxRetryError: HTTPConnectionPool(host='api.isportsapi.com', port=80): Max retries exceeded with url: /sport/football/livescores?api_key=VEM3L91m7eguSCla (Caused by NameResolutionError("<urllib3.connection.HTTPConnection object at 0x72140022eba0>: Failed to resolve 'api.isportsapi.com' ([Errno -3] Temporary failure in name resolution)"))

During handling of the above exception, another exception occurred:

Traceback (most recent call last):
  File "/home/arifin/project/live_score/main.py", line 23, in <module>
    matches = fetch_matches()
              ^^^^^^^^^^^^^^^
  File "/home/arifin/project/live_score/main.py", line 17, in fetch_matches
    resp = requests.get(settings.NOWGOAL_API_URL, params=params)
           ^^^^^^^^^^^^^^^^^^^^^^^^^^^^^^^^^^^^^^^^^^^^^^^^^^^^^
  File "/home/arifin/envbot/lib/python3.12/site-packages/requests/api.py", line 73, in get
    return request("get", url, params=params, **kwargs)
           ^^^^^^^^^^^^^^^^^^^^^^^^^^^^^^^^^^^^^^^^^^^^
  File "/home/arifin/envbot/lib/python3.12/site-packages/requests/api.py", line 59, in request
    return session.request(method=method, url=url, **kwargs)
           ^^^^^^^^^^^^^^^^^^^^^^^^^^^^^^^^^^^^^^^^^^^^^^^^^
  File "/home/arifin/envbot/lib/python3.12/site-packages/requests/sessions.py", line 589, in request
    resp = self.send(prep, **send_kwargs)
           ^^^^^^^^^^^^^^^^^^^^^^^^^^^^^^
  File "/home/arifin/envbot/lib/python3.12/site-packages/requests/sessions.py", line 703, in send
    r = adapter.send(request, **kwargs)
        ^^^^^^^^^^^^^^^^^^^^^^^^^^^^^^^
  File "/home/arifin/envbot/lib/python3.12/site-packages/requests/adapters.py", line 700, in send
    raise ConnectionError(e, request=request)
requests.exceptions.ConnectionError: HTTPConnectionPool(host='api.isportsapi.com', port=80): Max retries exceeded with url: /sport/football/livescores?api_key=VEM3L91m7eguSCla (Caused by NameResolutionError("<urllib3.connection.HTTPConnection object at 0x72140022eba0>: Failed to resolve 'api.isportsapi.com' ([Errno -3] Temporary failure in name resolution)"))
Traceback (most recent call last):
  File "/home/arifin/envbot/lib/python3.12/site-packages/urllib3/connection.py", line 198, in _new_conn
    sock = connection.create_connection(
           ^^^^^^^^^^^^^^^^^^^^^^^^^^^^^
  File "/home/arifin/envbot/lib/python3.12/site-packages/urllib3/util/connection.py", line 60, in create_connection
    for res in socket.getaddrinfo(host, port, family, socket.SOCK_STREAM):
               ^^^^^^^^^^^^^^^^^^^^^^^^^^^^^^^^^^^^^^^^^^^^^^^^^^^^^^^^^^
  File "/usr/lib/python3.12/socket.py", line 963, in getaddrinfo
    for res in _socket.getaddrinfo(host, port, family, type, proto, flags):
               ^^^^^^^^^^^^^^^^^^^^^^^^^^^^^^^^^^^^^^^^^^^^^^^^^^^^^^^^^^^
socket.gaierror: [Errno -3] Temporary failure in name resolution

The above exception was the direct cause of the following exception:

Traceback (most recent call last):
  File "/home/arifin/envbot/lib/python3.12/site-packages/urllib3/connectionpool.py", line 787, in urlopen
    response = self._make_request(
               ^^^^^^^^^^^^^^^^^^^
  File "/home/arifin/envbot/lib/python3.12/site-packages/urllib3/connectionpool.py", line 493, in _make_request
    conn.request(
  File "/home/arifin/envbot/lib/python3.12/site-packages/urllib3/connection.py", line 494, in request
    self.endheaders()
  File "/usr/lib/python3.12/http/client.py", line 1331, in endheaders
    self._send_output(message_body, encode_chunked=encode_chunked)
  File "/usr/lib/python3.12/http/client.py", line 1091, in _send_output
    self.send(msg)
  File "/usr/lib/python3.12/http/client.py", line 1035, in send
    self.connect()
  File "/home/arifin/envbot/lib/python3.12/site-packages/urllib3/connection.py", line 325, in connect
    self.sock = self._new_conn()
                ^^^^^^^^^^^^^^^^
  File "/home/arifin/envbot/lib/python3.12/site-packages/urllib3/connection.py", line 205, in _new_conn
    raise NameResolutionError(self.host, self, e) from e
urllib3.exceptions.NameResolutionError: <urllib3.connection.HTTPConnection object at 0x7161720d3800>: Failed to resolve 'api.isportsapi.com' ([Errno -3] Temporary failure in name resolution)

The above exception was the direct cause of the following exception:

Traceback (most recent call last):
  File "/home/arifin/envbot/lib/python3.12/site-packages/requests/adapters.py", line 667, in send
    resp = conn.urlopen(
           ^^^^^^^^^^^^^
  File "/home/arifin/envbot/lib/python3.12/site-packages/urllib3/connectionpool.py", line 841, in urlopen
    retries = retries.increment(
              ^^^^^^^^^^^^^^^^^^
  File "/home/arifin/envbot/lib/python3.12/site-packages/urllib3/util/retry.py", line 519, in increment
    raise MaxRetryError(_pool, url, reason) from reason  # type: ignore[arg-type]
    ^^^^^^^^^^^^^^^^^^^^^^^^^^^^^^^^^^^^^^^^^^^^^^^^^^^
urllib3.exceptions.MaxRetryError: HTTPConnectionPool(host='api.isportsapi.com', port=80): Max retries exceeded with url: /sport/football/livescores?api_key=VEM3L91m7eguSCla (Caused by NameResolutionError("<urllib3.connection.HTTPConnection object at 0x7161720d3800>: Failed to resolve 'api.isportsapi.com' ([Errno -3] Temporary failure in name resolution)"))

During handling of the above exception, another exception occurred:

Traceback (most recent call last):
  File "/home/arifin/project/live_score/main.py", line 23, in <module>
    matches = fetch_matches()
              ^^^^^^^^^^^^^^^
  File "/home/arifin/project/live_score/main.py", line 17, in fetch_matches
    resp = requests.get(settings.NOWGOAL_API_URL, params=params)
           ^^^^^^^^^^^^^^^^^^^^^^^^^^^^^^^^^^^^^^^^^^^^^^^^^^^^^
  File "/home/arifin/envbot/lib/python3.12/site-packages/requests/api.py", line 73, in get
    return request("get", url, params=params, **kwargs)
           ^^^^^^^^^^^^^^^^^^^^^^^^^^^^^^^^^^^^^^^^^^^^
  File "/home/arifin/envbot/lib/python3.12/site-packages/requests/api.py", line 59, in request
    return session.request(method=method, url=url, **kwargs)
           ^^^^^^^^^^^^^^^^^^^^^^^^^^^^^^^^^^^^^^^^^^^^^^^^^
  File "/home/arifin/envbot/lib/python3.12/site-packages/requests/sessions.py", line 589, in request
    resp = self.send(prep, **send_kwargs)
           ^^^^^^^^^^^^^^^^^^^^^^^^^^^^^^
  File "/home/arifin/envbot/lib/python3.12/site-packages/requests/sessions.py", line 703, in send
    r = adapter.send(request, **kwargs)
        ^^^^^^^^^^^^^^^^^^^^^^^^^^^^^^^
  File "/home/arifin/envbot/lib/python3.12/site-packages/requests/adapters.py", line 700, in send
    raise ConnectionError(e, request=request)
requests.exceptions.ConnectionError: HTTPConnectionPool(host='api.isportsapi.com', port=80): Max retries exceeded with url: /sport/football/livescores?api_key=VEM3L91m7eguSCla (Caused by NameResolutionError("<urllib3.connection.HTTPConnection object at 0x7161720d3800>: Failed to resolve 'api.isportsapi.com' ([Errno -3] Temporary failure in name resolution)"))
Traceback (most recent call last):
  File "/home/arifin/envbot/lib/python3.12/site-packages/urllib3/connection.py", line 198, in _new_conn
    sock = connection.create_connection(
           ^^^^^^^^^^^^^^^^^^^^^^^^^^^^^
  File "/home/arifin/envbot/lib/python3.12/site-packages/urllib3/util/connection.py", line 60, in create_connection
    for res in socket.getaddrinfo(host, port, family, socket.SOCK_STREAM):
               ^^^^^^^^^^^^^^^^^^^^^^^^^^^^^^^^^^^^^^^^^^^^^^^^^^^^^^^^^^
  File "/usr/lib/python3.12/socket.py", line 963, in getaddrinfo
    for res in _socket.getaddrinfo(host, port, family, type, proto, flags):
               ^^^^^^^^^^^^^^^^^^^^^^^^^^^^^^^^^^^^^^^^^^^^^^^^^^^^^^^^^^^
socket.gaierror: [Errno -3] Temporary failure in name resolution

The above exception was the direct cause of the following exception:

Traceback (most recent call last):
  File "/home/arifin/envbot/lib/python3.12/site-packages/urllib3/connectionpool.py", line 787, in urlopen
    response = self._make_request(
               ^^^^^^^^^^^^^^^^^^^
  File "/home/arifin/envbot/lib/python3.12/site-packages/urllib3/connectionpool.py", line 493, in _make_request
    conn.request(
  File "/home/arifin/envbot/lib/python3.12/site-packages/urllib3/connection.py", line 494, in request
    self.endheaders()
  File "/usr/lib/python3.12/http/client.py", line 1331, in endheaders
    self._send_output(message_body, encode_chunked=encode_chunked)
  File "/usr/lib/python3.12/http/client.py", line 1091, in _send_output
    self.send(msg)
  File "/usr/lib/python3.12/http/client.py", line 1035, in send
    self.connect()
  File "/home/arifin/envbot/lib/python3.12/site-packages/urllib3/connection.py", line 325, in connect
    self.sock = self._new_conn()
                ^^^^^^^^^^^^^^^^
  File "/home/arifin/envbot/lib/python3.12/site-packages/urllib3/connection.py", line 205, in _new_conn
    raise NameResolutionError(self.host, self, e) from e
urllib3.exceptions.NameResolutionError: <urllib3.connection.HTTPConnection object at 0x79e8f83a8a40>: Failed to resolve 'api.isportsapi.com' ([Errno -3] Temporary failure in name resolution)

The above exception was the direct cause of the following exception:

Traceback (most recent call last):
  File "/home/arifin/envbot/lib/python3.12/site-packages/requests/adapters.py", line 667, in send
    resp = conn.urlopen(
           ^^^^^^^^^^^^^
  File "/home/arifin/envbot/lib/python3.12/site-packages/urllib3/connectionpool.py", line 841, in urlopen
    retries = retries.increment(
              ^^^^^^^^^^^^^^^^^^
  File "/home/arifin/envbot/lib/python3.12/site-packages/urllib3/util/retry.py", line 519, in increment
    raise MaxRetryError(_pool, url, reason) from reason  # type: ignore[arg-type]
    ^^^^^^^^^^^^^^^^^^^^^^^^^^^^^^^^^^^^^^^^^^^^^^^^^^^
urllib3.exceptions.MaxRetryError: HTTPConnectionPool(host='api.isportsapi.com', port=80): Max retries exceeded with url: /sport/football/livescores?api_key=VEM3L91m7eguSCla (Caused by NameResolutionError("<urllib3.connection.HTTPConnection object at 0x79e8f83a8a40>: Failed to resolve 'api.isportsapi.com' ([Errno -3] Temporary failure in name resolution)"))

During handling of the above exception, another exception occurred:

Traceback (most recent call last):
  File "/home/arifin/project/live_score/main.py", line 23, in <module>
    matches = fetch_matches()
              ^^^^^^^^^^^^^^^
  File "/home/arifin/project/live_score/main.py", line 17, in fetch_matches
    resp = requests.get(settings.NOWGOAL_API_URL, params=params)
           ^^^^^^^^^^^^^^^^^^^^^^^^^^^^^^^^^^^^^^^^^^^^^^^^^^^^^
  File "/home/arifin/envbot/lib/python3.12/site-packages/requests/api.py", line 73, in get
    return request("get", url, params=params, **kwargs)
           ^^^^^^^^^^^^^^^^^^^^^^^^^^^^^^^^^^^^^^^^^^^^
  File "/home/arifin/envbot/lib/python3.12/site-packages/requests/api.py", line 59, in request
    return session.request(method=method, url=url, **kwargs)
           ^^^^^^^^^^^^^^^^^^^^^^^^^^^^^^^^^^^^^^^^^^^^^^^^^
  File "/home/arifin/envbot/lib/python3.12/site-packages/requests/sessions.py", line 589, in request
    resp = self.send(prep, **send_kwargs)
           ^^^^^^^^^^^^^^^^^^^^^^^^^^^^^^
  File "/home/arifin/envbot/lib/python3.12/site-packages/requests/sessions.py", line 703, in send
    r = adapter.send(request, **kwargs)
        ^^^^^^^^^^^^^^^^^^^^^^^^^^^^^^^
  File "/home/arifin/envbot/lib/python3.12/site-packages/requests/adapters.py", line 700, in send
    raise ConnectionError(e, request=request)
requests.exceptions.ConnectionError: HTTPConnectionPool(host='api.isportsapi.com', port=80): Max retries exceeded with url: /sport/football/livescores?api_key=VEM3L91m7eguSCla (Caused by NameResolutionError("<urllib3.connection.HTTPConnection object at 0x79e8f83a8a40>: Failed to resolve 'api.isportsapi.com' ([Errno -3] Temporary failure in name resolution)"))
Traceback (most recent call last):
  File "/home/arifin/envbot/lib/python3.12/site-packages/urllib3/connection.py", line 198, in _new_conn
    sock = connection.create_connection(
           ^^^^^^^^^^^^^^^^^^^^^^^^^^^^^
  File "/home/arifin/envbot/lib/python3.12/site-packages/urllib3/util/connection.py", line 60, in create_connection
    for res in socket.getaddrinfo(host, port, family, socket.SOCK_STREAM):
               ^^^^^^^^^^^^^^^^^^^^^^^^^^^^^^^^^^^^^^^^^^^^^^^^^^^^^^^^^^
  File "/usr/lib/python3.12/socket.py", line 963, in getaddrinfo
    for res in _socket.getaddrinfo(host, port, family, type, proto, flags):
               ^^^^^^^^^^^^^^^^^^^^^^^^^^^^^^^^^^^^^^^^^^^^^^^^^^^^^^^^^^^
socket.gaierror: [Errno -3] Temporary failure in name resolution

The above exception was the direct cause of the following exception:

Traceback (most recent call last):
  File "/home/arifin/envbot/lib/python3.12/site-packages/urllib3/connectionpool.py", line 787, in urlopen
    response = self._make_request(
               ^^^^^^^^^^^^^^^^^^^
  File "/home/arifin/envbot/lib/python3.12/site-packages/urllib3/connectionpool.py", line 493, in _make_request
    conn.request(
  File "/home/arifin/envbot/lib/python3.12/site-packages/urllib3/connection.py", line 494, in request
    self.endheaders()
  File "/usr/lib/python3.12/http/client.py", line 1331, in endheaders
    self._send_output(message_body, encode_chunked=encode_chunked)
  File "/usr/lib/python3.12/http/client.py", line 1091, in _send_output
    self.send(msg)
  File "/usr/lib/python3.12/http/client.py", line 1035, in send
    self.connect()
  File "/home/arifin/envbot/lib/python3.12/site-packages/urllib3/connection.py", line 325, in connect
    self.sock = self._new_conn()
                ^^^^^^^^^^^^^^^^
  File "/home/arifin/envbot/lib/python3.12/site-packages/urllib3/connection.py", line 205, in _new_conn
    raise NameResolutionError(self.host, self, e) from e
urllib3.exceptions.NameResolutionError: <urllib3.connection.HTTPConnection object at 0x7b76cb2bcc80>: Failed to resolve 'api.isportsapi.com' ([Errno -3] Temporary failure in name resolution)

The above exception was the direct cause of the following exception:

Traceback (most recent call last):
  File "/home/arifin/envbot/lib/python3.12/site-packages/requests/adapters.py", line 667, in send
    resp = conn.urlopen(
           ^^^^^^^^^^^^^
  File "/home/arifin/envbot/lib/python3.12/site-packages/urllib3/connectionpool.py", line 841, in urlopen
    retries = retries.increment(
              ^^^^^^^^^^^^^^^^^^
  File "/home/arifin/envbot/lib/python3.12/site-packages/urllib3/util/retry.py", line 519, in increment
    raise MaxRetryError(_pool, url, reason) from reason  # type: ignore[arg-type]
    ^^^^^^^^^^^^^^^^^^^^^^^^^^^^^^^^^^^^^^^^^^^^^^^^^^^
urllib3.exceptions.MaxRetryError: HTTPConnectionPool(host='api.isportsapi.com', port=80): Max retries exceeded with url: /sport/football/livescores?api_key=VEM3L91m7eguSCla (Caused by NameResolutionError("<urllib3.connection.HTTPConnection object at 0x7b76cb2bcc80>: Failed to resolve 'api.isportsapi.com' ([Errno -3] Temporary failure in name resolution)"))

During handling of the above exception, another exception occurred:

Traceback (most recent call last):
  File "/home/arifin/project/live_score/main.py", line 23, in <module>
    matches = fetch_matches()
              ^^^^^^^^^^^^^^^
  File "/home/arifin/project/live_score/main.py", line 17, in fetch_matches
    resp = requests.get(settings.NOWGOAL_API_URL, params=params)
           ^^^^^^^^^^^^^^^^^^^^^^^^^^^^^^^^^^^^^^^^^^^^^^^^^^^^^
  File "/home/arifin/envbot/lib/python3.12/site-packages/requests/api.py", line 73, in get
    return request("get", url, params=params, **kwargs)
           ^^^^^^^^^^^^^^^^^^^^^^^^^^^^^^^^^^^^^^^^^^^^
  File "/home/arifin/envbot/lib/python3.12/site-packages/requests/api.py", line 59, in request
    return session.request(method=method, url=url, **kwargs)
           ^^^^^^^^^^^^^^^^^^^^^^^^^^^^^^^^^^^^^^^^^^^^^^^^^
  File "/home/arifin/envbot/lib/python3.12/site-packages/requests/sessions.py", line 589, in request
    resp = self.send(prep, **send_kwargs)
           ^^^^^^^^^^^^^^^^^^^^^^^^^^^^^^
  File "/home/arifin/envbot/lib/python3.12/site-packages/requests/sessions.py", line 703, in send
    r = adapter.send(request, **kwargs)
        ^^^^^^^^^^^^^^^^^^^^^^^^^^^^^^^
  File "/home/arifin/envbot/lib/python3.12/site-packages/requests/adapters.py", line 700, in send
    raise ConnectionError(e, request=request)
requests.exceptions.ConnectionError: HTTPConnectionPool(host='api.isportsapi.com', port=80): Max retries exceeded with url: /sport/football/livescores?api_key=VEM3L91m7eguSCla (Caused by NameResolutionError("<urllib3.connection.HTTPConnection object at 0x7b76cb2bcc80>: Failed to resolve 'api.isportsapi.com' ([Errno -3] Temporary failure in name resolution)"))
Traceback (most recent call last):
  File "/home/arifin/envbot/lib/python3.12/site-packages/urllib3/connection.py", line 198, in _new_conn
    sock = connection.create_connection(
           ^^^^^^^^^^^^^^^^^^^^^^^^^^^^^
  File "/home/arifin/envbot/lib/python3.12/site-packages/urllib3/util/connection.py", line 60, in create_connection
    for res in socket.getaddrinfo(host, port, family, socket.SOCK_STREAM):
               ^^^^^^^^^^^^^^^^^^^^^^^^^^^^^^^^^^^^^^^^^^^^^^^^^^^^^^^^^^
  File "/usr/lib/python3.12/socket.py", line 963, in getaddrinfo
    for res in _socket.getaddrinfo(host, port, family, type, proto, flags):
               ^^^^^^^^^^^^^^^^^^^^^^^^^^^^^^^^^^^^^^^^^^^^^^^^^^^^^^^^^^^
socket.gaierror: [Errno -3] Temporary failure in name resolution

The above exception was the direct cause of the following exception:

Traceback (most recent call last):
  File "/home/arifin/envbot/lib/python3.12/site-packages/urllib3/connectionpool.py", line 787, in urlopen
    response = self._make_request(
               ^^^^^^^^^^^^^^^^^^^
  File "/home/arifin/envbot/lib/python3.12/site-packages/urllib3/connectionpool.py", line 493, in _make_request
    conn.request(
  File "/home/arifin/envbot/lib/python3.12/site-packages/urllib3/connection.py", line 494, in request
    self.endheaders()
  File "/usr/lib/python3.12/http/client.py", line 1331, in endheaders
    self._send_output(message_body, encode_chunked=encode_chunked)
  File "/usr/lib/python3.12/http/client.py", line 1091, in _send_output
    self.send(msg)
  File "/usr/lib/python3.12/http/client.py", line 1035, in send
    self.connect()
  File "/home/arifin/envbot/lib/python3.12/site-packages/urllib3/connection.py", line 325, in connect
    self.sock = self._new_conn()
                ^^^^^^^^^^^^^^^^
  File "/home/arifin/envbot/lib/python3.12/site-packages/urllib3/connection.py", line 205, in _new_conn
    raise NameResolutionError(self.host, self, e) from e
urllib3.exceptions.NameResolutionError: <urllib3.connection.HTTPConnection object at 0x79cddb6d6e40>: Failed to resolve 'api.isportsapi.com' ([Errno -3] Temporary failure in name resolution)

The above exception was the direct cause of the following exception:

Traceback (most recent call last):
  File "/home/arifin/envbot/lib/python3.12/site-packages/requests/adapters.py", line 667, in send
    resp = conn.urlopen(
           ^^^^^^^^^^^^^
  File "/home/arifin/envbot/lib/python3.12/site-packages/urllib3/connectionpool.py", line 841, in urlopen
    retries = retries.increment(
              ^^^^^^^^^^^^^^^^^^
  File "/home/arifin/envbot/lib/python3.12/site-packages/urllib3/util/retry.py", line 519, in increment
    raise MaxRetryError(_pool, url, reason) from reason  # type: ignore[arg-type]
    ^^^^^^^^^^^^^^^^^^^^^^^^^^^^^^^^^^^^^^^^^^^^^^^^^^^
urllib3.exceptions.MaxRetryError: HTTPConnectionPool(host='api.isportsapi.com', port=80): Max retries exceeded with url: /sport/football/livescores?api_key=VEM3L91m7eguSCla (Caused by NameResolutionError("<urllib3.connection.HTTPConnection object at 0x79cddb6d6e40>: Failed to resolve 'api.isportsapi.com' ([Errno -3] Temporary failure in name resolution)"))

During handling of the above exception, another exception occurred:

Traceback (most recent call last):
  File "/home/arifin/project/live_score/main.py", line 23, in <module>
    matches = fetch_matches()
              ^^^^^^^^^^^^^^^
  File "/home/arifin/project/live_score/main.py", line 17, in fetch_matches
    resp = requests.get(settings.NOWGOAL_API_URL, params=params)
           ^^^^^^^^^^^^^^^^^^^^^^^^^^^^^^^^^^^^^^^^^^^^^^^^^^^^^
  File "/home/arifin/envbot/lib/python3.12/site-packages/requests/api.py", line 73, in get
    return request("get", url, params=params, **kwargs)
           ^^^^^^^^^^^^^^^^^^^^^^^^^^^^^^^^^^^^^^^^^^^^
  File "/home/arifin/envbot/lib/python3.12/site-packages/requests/api.py", line 59, in request
    return session.request(method=method, url=url, **kwargs)
           ^^^^^^^^^^^^^^^^^^^^^^^^^^^^^^^^^^^^^^^^^^^^^^^^^
  File "/home/arifin/envbot/lib/python3.12/site-packages/requests/sessions.py", line 589, in request
    resp = self.send(prep, **send_kwargs)
           ^^^^^^^^^^^^^^^^^^^^^^^^^^^^^^
  File "/home/arifin/envbot/lib/python3.12/site-packages/requests/sessions.py", line 703, in send
    r = adapter.send(request, **kwargs)
        ^^^^^^^^^^^^^^^^^^^^^^^^^^^^^^^
  File "/home/arifin/envbot/lib/python3.12/site-packages/requests/adapters.py", line 700, in send
    raise ConnectionError(e, request=request)
requests.exceptions.ConnectionError: HTTPConnectionPool(host='api.isportsapi.com', port=80): Max retries exceeded with url: /sport/football/livescores?api_key=VEM3L91m7eguSCla (Caused by NameResolutionError("<urllib3.connection.HTTPConnection object at 0x79cddb6d6e40>: Failed to resolve 'api.isportsapi.com' ([Errno -3] Temporary failure in name resolution)"))
Traceback (most recent call last):
  File "/home/arifin/envbot/lib/python3.12/site-packages/urllib3/connection.py", line 198, in _new_conn
    sock = connection.create_connection(
           ^^^^^^^^^^^^^^^^^^^^^^^^^^^^^
  File "/home/arifin/envbot/lib/python3.12/site-packages/urllib3/util/connection.py", line 60, in create_connection
    for res in socket.getaddrinfo(host, port, family, socket.SOCK_STREAM):
               ^^^^^^^^^^^^^^^^^^^^^^^^^^^^^^^^^^^^^^^^^^^^^^^^^^^^^^^^^^
  File "/usr/lib/python3.12/socket.py", line 963, in getaddrinfo
    for res in _socket.getaddrinfo(host, port, family, type, proto, flags):
               ^^^^^^^^^^^^^^^^^^^^^^^^^^^^^^^^^^^^^^^^^^^^^^^^^^^^^^^^^^^
socket.gaierror: [Errno -3] Temporary failure in name resolution

The above exception was the direct cause of the following exception:

Traceback (most recent call last):
  File "/home/arifin/envbot/lib/python3.12/site-packages/urllib3/connectionpool.py", line 787, in urlopen
    response = self._make_request(
               ^^^^^^^^^^^^^^^^^^^
  File "/home/arifin/envbot/lib/python3.12/site-packages/urllib3/connectionpool.py", line 493, in _make_request
    conn.request(
  File "/home/arifin/envbot/lib/python3.12/site-packages/urllib3/connection.py", line 494, in request
    self.endheaders()
  File "/usr/lib/python3.12/http/client.py", line 1331, in endheaders
    self._send_output(message_body, encode_chunked=encode_chunked)
  File "/usr/lib/python3.12/http/client.py", line 1091, in _send_output
    self.send(msg)
  File "/usr/lib/python3.12/http/client.py", line 1035, in send
    self.connect()
  File "/home/arifin/envbot/lib/python3.12/site-packages/urllib3/connection.py", line 325, in connect
    self.sock = self._new_conn()
                ^^^^^^^^^^^^^^^^
  File "/home/arifin/envbot/lib/python3.12/site-packages/urllib3/connection.py", line 205, in _new_conn
    raise NameResolutionError(self.host, self, e) from e
urllib3.exceptions.NameResolutionError: <urllib3.connection.HTTPConnection object at 0x7bb643302a20>: Failed to resolve 'api.isportsapi.com' ([Errno -3] Temporary failure in name resolution)

The above exception was the direct cause of the following exception:

Traceback (most recent call last):
  File "/home/arifin/envbot/lib/python3.12/site-packages/requests/adapters.py", line 667, in send
    resp = conn.urlopen(
           ^^^^^^^^^^^^^
  File "/home/arifin/envbot/lib/python3.12/site-packages/urllib3/connectionpool.py", line 841, in urlopen
    retries = retries.increment(
              ^^^^^^^^^^^^^^^^^^
  File "/home/arifin/envbot/lib/python3.12/site-packages/urllib3/util/retry.py", line 519, in increment
    raise MaxRetryError(_pool, url, reason) from reason  # type: ignore[arg-type]
    ^^^^^^^^^^^^^^^^^^^^^^^^^^^^^^^^^^^^^^^^^^^^^^^^^^^
urllib3.exceptions.MaxRetryError: HTTPConnectionPool(host='api.isportsapi.com', port=80): Max retries exceeded with url: /sport/football/livescores?api_key=VEM3L91m7eguSCla (Caused by NameResolutionError("<urllib3.connection.HTTPConnection object at 0x7bb643302a20>: Failed to resolve 'api.isportsapi.com' ([Errno -3] Temporary failure in name resolution)"))

During handling of the above exception, another exception occurred:

Traceback (most recent call last):
  File "/home/arifin/project/live_score/main.py", line 23, in <module>
    matches = fetch_matches()
              ^^^^^^^^^^^^^^^
  File "/home/arifin/project/live_score/main.py", line 17, in fetch_matches
    resp = requests.get(settings.NOWGOAL_API_URL, params=params)
           ^^^^^^^^^^^^^^^^^^^^^^^^^^^^^^^^^^^^^^^^^^^^^^^^^^^^^
  File "/home/arifin/envbot/lib/python3.12/site-packages/requests/api.py", line 73, in get
    return request("get", url, params=params, **kwargs)
           ^^^^^^^^^^^^^^^^^^^^^^^^^^^^^^^^^^^^^^^^^^^^
  File "/home/arifin/envbot/lib/python3.12/site-packages/requests/api.py", line 59, in request
    return session.request(method=method, url=url, **kwargs)
           ^^^^^^^^^^^^^^^^^^^^^^^^^^^^^^^^^^^^^^^^^^^^^^^^^
  File "/home/arifin/envbot/lib/python3.12/site-packages/requests/sessions.py", line 589, in request
    resp = self.send(prep, **send_kwargs)
           ^^^^^^^^^^^^^^^^^^^^^^^^^^^^^^
  File "/home/arifin/envbot/lib/python3.12/site-packages/requests/sessions.py", line 703, in send
    r = adapter.send(request, **kwargs)
        ^^^^^^^^^^^^^^^^^^^^^^^^^^^^^^^
  File "/home/arifin/envbot/lib/python3.12/site-packages/requests/adapters.py", line 700, in send
    raise ConnectionError(e, request=request)
requests.exceptions.ConnectionError: HTTPConnectionPool(host='api.isportsapi.com', port=80): Max retries exceeded with url: /sport/football/livescores?api_key=VEM3L91m7eguSCla (Caused by NameResolutionError("<urllib3.connection.HTTPConnection object at 0x7bb643302a20>: Failed to resolve 'api.isportsapi.com' ([Errno -3] Temporary failure in name resolution)"))
Traceback (most recent call last):
  File "/home/arifin/envbot/lib/python3.12/site-packages/urllib3/connection.py", line 198, in _new_conn
    sock = connection.create_connection(
           ^^^^^^^^^^^^^^^^^^^^^^^^^^^^^
  File "/home/arifin/envbot/lib/python3.12/site-packages/urllib3/util/connection.py", line 60, in create_connection
    for res in socket.getaddrinfo(host, port, family, socket.SOCK_STREAM):
               ^^^^^^^^^^^^^^^^^^^^^^^^^^^^^^^^^^^^^^^^^^^^^^^^^^^^^^^^^^
  File "/usr/lib/python3.12/socket.py", line 963, in getaddrinfo
    for res in _socket.getaddrinfo(host, port, family, type, proto, flags):
               ^^^^^^^^^^^^^^^^^^^^^^^^^^^^^^^^^^^^^^^^^^^^^^^^^^^^^^^^^^^
socket.gaierror: [Errno -3] Temporary failure in name resolution

The above exception was the direct cause of the following exception:

Traceback (most recent call last):
  File "/home/arifin/envbot/lib/python3.12/site-packages/urllib3/connectionpool.py", line 787, in urlopen
    response = self._make_request(
               ^^^^^^^^^^^^^^^^^^^
  File "/home/arifin/envbot/lib/python3.12/site-packages/urllib3/connectionpool.py", line 493, in _make_request
    conn.request(
  File "/home/arifin/envbot/lib/python3.12/site-packages/urllib3/connection.py", line 494, in request
    self.endheaders()
  File "/usr/lib/python3.12/http/client.py", line 1331, in endheaders
    self._send_output(message_body, encode_chunked=encode_chunked)
  File "/usr/lib/python3.12/http/client.py", line 1091, in _send_output
    self.send(msg)
  File "/usr/lib/python3.12/http/client.py", line 1035, in send
    self.connect()
  File "/home/arifin/envbot/lib/python3.12/site-packages/urllib3/connection.py", line 325, in connect
    self.sock = self._new_conn()
                ^^^^^^^^^^^^^^^^
  File "/home/arifin/envbot/lib/python3.12/site-packages/urllib3/connection.py", line 205, in _new_conn
    raise NameResolutionError(self.host, self, e) from e
urllib3.exceptions.NameResolutionError: <urllib3.connection.HTTPConnection object at 0x7cf72ad3cbf0>: Failed to resolve 'api.isportsapi.com' ([Errno -3] Temporary failure in name resolution)

The above exception was the direct cause of the following exception:

Traceback (most recent call last):
  File "/home/arifin/envbot/lib/python3.12/site-packages/requests/adapters.py", line 667, in send
    resp = conn.urlopen(
           ^^^^^^^^^^^^^
  File "/home/arifin/envbot/lib/python3.12/site-packages/urllib3/connectionpool.py", line 841, in urlopen
    retries = retries.increment(
              ^^^^^^^^^^^^^^^^^^
  File "/home/arifin/envbot/lib/python3.12/site-packages/urllib3/util/retry.py", line 519, in increment
    raise MaxRetryError(_pool, url, reason) from reason  # type: ignore[arg-type]
    ^^^^^^^^^^^^^^^^^^^^^^^^^^^^^^^^^^^^^^^^^^^^^^^^^^^
urllib3.exceptions.MaxRetryError: HTTPConnectionPool(host='api.isportsapi.com', port=80): Max retries exceeded with url: /sport/football/livescores?api_key=VEM3L91m7eguSCla (Caused by NameResolutionError("<urllib3.connection.HTTPConnection object at 0x7cf72ad3cbf0>: Failed to resolve 'api.isportsapi.com' ([Errno -3] Temporary failure in name resolution)"))

During handling of the above exception, another exception occurred:

Traceback (most recent call last):
  File "/home/arifin/project/live_score/main.py", line 23, in <module>
    matches = fetch_matches()
              ^^^^^^^^^^^^^^^
  File "/home/arifin/project/live_score/main.py", line 17, in fetch_matches
    resp = requests.get(settings.NOWGOAL_API_URL, params=params)
           ^^^^^^^^^^^^^^^^^^^^^^^^^^^^^^^^^^^^^^^^^^^^^^^^^^^^^
  File "/home/arifin/envbot/lib/python3.12/site-packages/requests/api.py", line 73, in get
    return request("get", url, params=params, **kwargs)
           ^^^^^^^^^^^^^^^^^^^^^^^^^^^^^^^^^^^^^^^^^^^^
  File "/home/arifin/envbot/lib/python3.12/site-packages/requests/api.py", line 59, in request
    return session.request(method=method, url=url, **kwargs)
           ^^^^^^^^^^^^^^^^^^^^^^^^^^^^^^^^^^^^^^^^^^^^^^^^^
  File "/home/arifin/envbot/lib/python3.12/site-packages/requests/sessions.py", line 589, in request
    resp = self.send(prep, **send_kwargs)
           ^^^^^^^^^^^^^^^^^^^^^^^^^^^^^^
  File "/home/arifin/envbot/lib/python3.12/site-packages/requests/sessions.py", line 703, in send
    r = adapter.send(request, **kwargs)
        ^^^^^^^^^^^^^^^^^^^^^^^^^^^^^^^
  File "/home/arifin/envbot/lib/python3.12/site-packages/requests/adapters.py", line 700, in send
    raise ConnectionError(e, request=request)
requests.exceptions.ConnectionError: HTTPConnectionPool(host='api.isportsapi.com', port=80): Max retries exceeded with url: /sport/football/livescores?api_key=VEM3L91m7eguSCla (Caused by NameResolutionError("<urllib3.connection.HTTPConnection object at 0x7cf72ad3cbf0>: Failed to resolve 'api.isportsapi.com' ([Errno -3] Temporary failure in name resolution)"))
Traceback (most recent call last):
  File "/home/arifin/envbot/lib/python3.12/site-packages/urllib3/connection.py", line 198, in _new_conn
    sock = connection.create_connection(
           ^^^^^^^^^^^^^^^^^^^^^^^^^^^^^
  File "/home/arifin/envbot/lib/python3.12/site-packages/urllib3/util/connection.py", line 60, in create_connection
    for res in socket.getaddrinfo(host, port, family, socket.SOCK_STREAM):
               ^^^^^^^^^^^^^^^^^^^^^^^^^^^^^^^^^^^^^^^^^^^^^^^^^^^^^^^^^^
  File "/usr/lib/python3.12/socket.py", line 963, in getaddrinfo
    for res in _socket.getaddrinfo(host, port, family, type, proto, flags):
               ^^^^^^^^^^^^^^^^^^^^^^^^^^^^^^^^^^^^^^^^^^^^^^^^^^^^^^^^^^^
socket.gaierror: [Errno -3] Temporary failure in name resolution

The above exception was the direct cause of the following exception:

Traceback (most recent call last):
  File "/home/arifin/envbot/lib/python3.12/site-packages/urllib3/connectionpool.py", line 787, in urlopen
    response = self._make_request(
               ^^^^^^^^^^^^^^^^^^^
  File "/home/arifin/envbot/lib/python3.12/site-packages/urllib3/connectionpool.py", line 493, in _make_request
    conn.request(
  File "/home/arifin/envbot/lib/python3.12/site-packages/urllib3/connection.py", line 494, in request
    self.endheaders()
  File "/usr/lib/python3.12/http/client.py", line 1331, in endheaders
    self._send_output(message_body, encode_chunked=encode_chunked)
  File "/usr/lib/python3.12/http/client.py", line 1091, in _send_output
    self.send(msg)
  File "/usr/lib/python3.12/http/client.py", line 1035, in send
    self.connect()
  File "/home/arifin/envbot/lib/python3.12/site-packages/urllib3/connection.py", line 325, in connect
    self.sock = self._new_conn()
                ^^^^^^^^^^^^^^^^
  File "/home/arifin/envbot/lib/python3.12/site-packages/urllib3/connection.py", line 205, in _new_conn
    raise NameResolutionError(self.host, self, e) from e
urllib3.exceptions.NameResolutionError: <urllib3.connection.HTTPConnection object at 0x7d54328b0b00>: Failed to resolve 'api.isportsapi.com' ([Errno -3] Temporary failure in name resolution)

The above exception was the direct cause of the following exception:

Traceback (most recent call last):
  File "/home/arifin/envbot/lib/python3.12/site-packages/requests/adapters.py", line 667, in send
    resp = conn.urlopen(
           ^^^^^^^^^^^^^
  File "/home/arifin/envbot/lib/python3.12/site-packages/urllib3/connectionpool.py", line 841, in urlopen
    retries = retries.increment(
              ^^^^^^^^^^^^^^^^^^
  File "/home/arifin/envbot/lib/python3.12/site-packages/urllib3/util/retry.py", line 519, in increment
    raise MaxRetryError(_pool, url, reason) from reason  # type: ignore[arg-type]
    ^^^^^^^^^^^^^^^^^^^^^^^^^^^^^^^^^^^^^^^^^^^^^^^^^^^
urllib3.exceptions.MaxRetryError: HTTPConnectionPool(host='api.isportsapi.com', port=80): Max retries exceeded with url: /sport/football/livescores?api_key=VEM3L91m7eguSCla (Caused by NameResolutionError("<urllib3.connection.HTTPConnection object at 0x7d54328b0b00>: Failed to resolve 'api.isportsapi.com' ([Errno -3] Temporary failure in name resolution)"))

During handling of the above exception, another exception occurred:

Traceback (most recent call last):
  File "/home/arifin/project/live_score/main.py", line 23, in <module>
    matches = fetch_matches()
              ^^^^^^^^^^^^^^^
  File "/home/arifin/project/live_score/main.py", line 17, in fetch_matches
    resp = requests.get(settings.NOWGOAL_API_URL, params=params)
           ^^^^^^^^^^^^^^^^^^^^^^^^^^^^^^^^^^^^^^^^^^^^^^^^^^^^^
  File "/home/arifin/envbot/lib/python3.12/site-packages/requests/api.py", line 73, in get
    return request("get", url, params=params, **kwargs)
           ^^^^^^^^^^^^^^^^^^^^^^^^^^^^^^^^^^^^^^^^^^^^
  File "/home/arifin/envbot/lib/python3.12/site-packages/requests/api.py", line 59, in request
    return session.request(method=method, url=url, **kwargs)
           ^^^^^^^^^^^^^^^^^^^^^^^^^^^^^^^^^^^^^^^^^^^^^^^^^
  File "/home/arifin/envbot/lib/python3.12/site-packages/requests/sessions.py", line 589, in request
    resp = self.send(prep, **send_kwargs)
           ^^^^^^^^^^^^^^^^^^^^^^^^^^^^^^
  File "/home/arifin/envbot/lib/python3.12/site-packages/requests/sessions.py", line 703, in send
    r = adapter.send(request, **kwargs)
        ^^^^^^^^^^^^^^^^^^^^^^^^^^^^^^^
  File "/home/arifin/envbot/lib/python3.12/site-packages/requests/adapters.py", line 700, in send
    raise ConnectionError(e, request=request)
requests.exceptions.ConnectionError: HTTPConnectionPool(host='api.isportsapi.com', port=80): Max retries exceeded with url: /sport/football/livescores?api_key=VEM3L91m7eguSCla (Caused by NameResolutionError("<urllib3.connection.HTTPConnection object at 0x7d54328b0b00>: Failed to resolve 'api.isportsapi.com' ([Errno -3] Temporary failure in name resolution)"))
ðŸ“Š Total pertandingan: 296
ðŸŽ¯ Yang memenuhi syarat: 9
ðŸ“Š Total pertandingan: 296
ðŸŽ¯ Yang memenuhi syarat: 9
ðŸ“Š Total pertandingan: 296
ðŸŽ¯ Yang memenuhi syarat: 9
Traceback (most recent call last):
  File "/home/arifin/envbot/lib/python3.12/site-packages/httpx/_transports/default.py", line 101, in map_httpcore_exceptions
    yield
  File "/home/arifin/envbot/lib/python3.12/site-packages/httpx/_transports/default.py", line 250, in handle_request
    resp = self._pool.handle_request(req)
           ^^^^^^^^^^^^^^^^^^^^^^^^^^^^^^
  File "/home/arifin/envbot/lib/python3.12/site-packages/httpcore/_sync/connection_pool.py", line 256, in handle_request
    raise exc from None
  File "/home/arifin/envbot/lib/python3.12/site-packages/httpcore/_sync/connection_pool.py", line 236, in handle_request
    response = connection.handle_request(
               ^^^^^^^^^^^^^^^^^^^^^^^^^^
  File "/home/arifin/envbot/lib/python3.12/site-packages/httpcore/_sync/connection.py", line 101, in handle_request
    raise exc
  File "/home/arifin/envbot/lib/python3.12/site-packages/httpcore/_sync/connection.py", line 78, in handle_request
    stream = self._connect(request)
             ^^^^^^^^^^^^^^^^^^^^^^
  File "/home/arifin/envbot/lib/python3.12/site-packages/httpcore/_sync/connection.py", line 156, in _connect
    stream = stream.start_tls(**kwargs)
             ^^^^^^^^^^^^^^^^^^^^^^^^^^
  File "/home/arifin/envbot/lib/python3.12/site-packages/httpcore/_backends/sync.py", line 154, in start_tls
    with map_exceptions(exc_map):
  File "/usr/lib/python3.12/contextlib.py", line 158, in __exit__
    self.gen.throw(value)
  File "/home/arifin/envbot/lib/python3.12/site-packages/httpcore/_exceptions.py", line 14, in map_exceptions
    raise to_exc(exc) from exc
httpcore.ConnectTimeout: _ssl.c:983: The handshake operation timed out

The above exception was the direct cause of the following exception:

Traceback (most recent call last):
  File "/home/arifin/project/live_score/main.py", line 30, in <module>
    notify(match, reason)
  File "/home/arifin/project/live_score/notifier.py", line 68, in notify
    httpx.post(f"{API_URL}/sendMessage", json={
  File "/home/arifin/envbot/lib/python3.12/site-packages/httpx/_api.py", line 304, in post
    return request(
           ^^^^^^^^
  File "/home/arifin/envbot/lib/python3.12/site-packages/httpx/_api.py", line 109, in request
    return client.request(
           ^^^^^^^^^^^^^^^
  File "/home/arifin/envbot/lib/python3.12/site-packages/httpx/_client.py", line 825, in request
    return self.send(request, auth=auth, follow_redirects=follow_redirects)
           ^^^^^^^^^^^^^^^^^^^^^^^^^^^^^^^^^^^^^^^^^^^^^^^^^^^^^^^^^^^^^^^^
  File "/home/arifin/envbot/lib/python3.12/site-packages/httpx/_client.py", line 914, in send
    response = self._send_handling_auth(
               ^^^^^^^^^^^^^^^^^^^^^^^^^
  File "/home/arifin/envbot/lib/python3.12/site-packages/httpx/_client.py", line 942, in _send_handling_auth
    response = self._send_handling_redirects(
               ^^^^^^^^^^^^^^^^^^^^^^^^^^^^^^
  File "/home/arifin/envbot/lib/python3.12/site-packages/httpx/_client.py", line 979, in _send_handling_redirects
    response = self._send_single_request(request)
               ^^^^^^^^^^^^^^^^^^^^^^^^^^^^^^^^^^
  File "/home/arifin/envbot/lib/python3.12/site-packages/httpx/_client.py", line 1014, in _send_single_request
    response = transport.handle_request(request)
               ^^^^^^^^^^^^^^^^^^^^^^^^^^^^^^^^^
  File "/home/arifin/envbot/lib/python3.12/site-packages/httpx/_transports/default.py", line 249, in handle_request
    with map_httpcore_exceptions():
  File "/usr/lib/python3.12/contextlib.py", line 158, in __exit__
    self.gen.throw(value)
  File "/home/arifin/envbot/lib/python3.12/site-packages/httpx/_transports/default.py", line 118, in map_httpcore_exceptions
    raise mapped_exc(message) from exc
httpx.ConnectTimeout: _ssl.c:983: The handshake operation timed out
ðŸ“Š Total pertandingan: 296
ðŸŽ¯ Yang memenuhi syarat: 10
Traceback (most recent call last):
  File "/home/arifin/envbot/lib/python3.12/site-packages/httpx/_transports/default.py", line 101, in map_httpcore_exceptions
    yield
  File "/home/arifin/envbot/lib/python3.12/site-packages/httpx/_transports/default.py", line 250, in handle_request
    resp = self._pool.handle_request(req)
           ^^^^^^^^^^^^^^^^^^^^^^^^^^^^^^
  File "/home/arifin/envbot/lib/python3.12/site-packages/httpcore/_sync/connection_pool.py", line 256, in handle_request
    raise exc from None
  File "/home/arifin/envbot/lib/python3.12/site-packages/httpcore/_sync/connection_pool.py", line 236, in handle_request
    response = connection.handle_request(
               ^^^^^^^^^^^^^^^^^^^^^^^^^^
  File "/home/arifin/envbot/lib/python3.12/site-packages/httpcore/_sync/connection.py", line 101, in handle_request
    raise exc
  File "/home/arifin/envbot/lib/python3.12/site-packages/httpcore/_sync/connection.py", line 78, in handle_request
    stream = self._connect(request)
             ^^^^^^^^^^^^^^^^^^^^^^
  File "/home/arifin/envbot/lib/python3.12/site-packages/httpcore/_sync/connection.py", line 156, in _connect
    stream = stream.start_tls(**kwargs)
             ^^^^^^^^^^^^^^^^^^^^^^^^^^
  File "/home/arifin/envbot/lib/python3.12/site-packages/httpcore/_backends/sync.py", line 154, in start_tls
    with map_exceptions(exc_map):
  File "/usr/lib/python3.12/contextlib.py", line 158, in __exit__
    self.gen.throw(value)
  File "/home/arifin/envbot/lib/python3.12/site-packages/httpcore/_exceptions.py", line 14, in map_exceptions
    raise to_exc(exc) from exc
httpcore.ConnectTimeout: _ssl.c:983: The handshake operation timed out

The above exception was the direct cause of the following exception:

Traceback (most recent call last):
  File "/home/arifin/project/live_score/main.py", line 30, in <module>
    notify(match, reason)
  File "/home/arifin/project/live_score/notifier.py", line 68, in notify
    httpx.post(f"{API_URL}/sendMessage", json={
  File "/home/arifin/envbot/lib/python3.12/site-packages/httpx/_api.py", line 304, in post
    return request(
           ^^^^^^^^
  File "/home/arifin/envbot/lib/python3.12/site-packages/httpx/_api.py", line 109, in request
    return client.request(
           ^^^^^^^^^^^^^^^
  File "/home/arifin/envbot/lib/python3.12/site-packages/httpx/_client.py", line 825, in request
    return self.send(request, auth=auth, follow_redirects=follow_redirects)
           ^^^^^^^^^^^^^^^^^^^^^^^^^^^^^^^^^^^^^^^^^^^^^^^^^^^^^^^^^^^^^^^^
  File "/home/arifin/envbot/lib/python3.12/site-packages/httpx/_client.py", line 914, in send
    response = self._send_handling_auth(
               ^^^^^^^^^^^^^^^^^^^^^^^^^
  File "/home/arifin/envbot/lib/python3.12/site-packages/httpx/_client.py", line 942, in _send_handling_auth
    response = self._send_handling_redirects(
               ^^^^^^^^^^^^^^^^^^^^^^^^^^^^^^
  File "/home/arifin/envbot/lib/python3.12/site-packages/httpx/_client.py", line 979, in _send_handling_redirects
    response = self._send_single_request(request)
               ^^^^^^^^^^^^^^^^^^^^^^^^^^^^^^^^^^
  File "/home/arifin/envbot/lib/python3.12/site-packages/httpx/_client.py", line 1014, in _send_single_request
    response = transport.handle_request(request)
               ^^^^^^^^^^^^^^^^^^^^^^^^^^^^^^^^^
  File "/home/arifin/envbot/lib/python3.12/site-packages/httpx/_transports/default.py", line 249, in handle_request
    with map_httpcore_exceptions():
  File "/usr/lib/python3.12/contextlib.py", line 158, in __exit__
    self.gen.throw(value)
  File "/home/arifin/envbot/lib/python3.12/site-packages/httpx/_transports/default.py", line 118, in map_httpcore_exceptions
    raise mapped_exc(message) from exc
httpx.ConnectTimeout: _ssl.c:983: The handshake operation timed out
